[17/Mar/2018 21:24:16] "GET /kk/category/3 HTTP/1.1" 200 6020
[17/Mar/2018 21:24:18] "GET /kk/category/1 HTTP/1.1" 200 6634
[17/Mar/2018 21:24:19] "GET /kk/category/2 HTTP/1.1" 200 6015
[17/Mar/2018 21:24:20] "GET /kk/category/2 HTTP/1.1" 200 6015
[17/Mar/2018 21:24:21] "GET /kk/category/1 HTTP/1.1" 200 6634
[17/Mar/2018 21:24:22] "GET /kk/post/1 HTTP/1.1" 200 8030
[17/Mar/2018 21:24:23] "GET /self/blog_admin/selfblog/post/1/change/ HTTP/1.1" 200 10373
[17/Mar/2018 21:24:24] "GET /self/blog_admin/jsi18n/ HTTP/1.1" 200 7758
[17/Mar/2018 21:24:25] "GET /self/blog_admin/selfblog/ HTTP/1.1" 200 3161
[17/Mar/2018 21:24:29] "GET /self/blog_admin/selfblog/post/ HTTP/1.1" 200 7551
[17/Mar/2018 21:24:29] "GET /self/blog_admin/jsi18n/ HTTP/1.1" 200 7758
[17/Mar/2018 21:24:31] "GET /self/blog_admin/selfblog/post/ HTTP/1.1" 200 7551
[17/Mar/2018 21:24:31] "GET /self/blog_admin/jsi18n/ HTTP/1.1" 200 7758
Traceback (most recent call last):
  File "/usr/lib/python2.7/SocketServer.py", line 596, in process_request_thread
    self.finish_request(request, client_address)
  File "/usr/lib/python2.7/SocketServer.py", line 331, in finish_request
    self.RequestHandlerClass(request, client_address, self)
  File "/usr/lib/python2.7/SocketServer.py", line 652, in __init__
    self.handle()
  File "/home/kk/.virtualenvs/blog-env/local/lib/python2.7/site-packages/django/core/servers/basehttp.py", line 140, in handle
    self.raw_requestline = self.rfile.readline(65537)
  File "/usr/lib/python2.7/socket.py", line 480, in readline
    data = self._sock.recv(self._rbufsize)
error: [Errno 104] Connection reset by peer
Traceback (most recent call last):
  File "/usr/lib/python2.7/SocketServer.py", line 596, in process_request_thread
    self.finish_request(request, client_address)
  File "/usr/lib/python2.7/SocketServer.py", line 331, in finish_request
    self.RequestHandlerClass(request, client_address, self)
  File "/usr/lib/python2.7/SocketServer.py", line 652, in __init__
    self.handle()
  File "/home/kk/.virtualenvs/blog-env/local/lib/python2.7/site-packages/django/core/servers/basehttp.py", line 140, in handle
    self.raw_requestline = self.rfile.readline(65537)
  File "/usr/lib/python2.7/socket.py", line 480, in readline
    data = self._sock.recv(self._rbufsize)
error: [Errno 104] Connection reset by peer
Traceback (most recent call last):
  File "/usr/lib/python2.7/SocketServer.py", line 596, in process_request_thread
    self.finish_request(request, client_address)
  File "/usr/lib/python2.7/SocketServer.py", line 331, in finish_request
    self.RequestHandlerClass(request, client_address, self)
  File "/usr/lib/python2.7/SocketServer.py", line 652, in __init__
    self.handle()
  File "/home/kk/.virtualenvs/blog-env/local/lib/python2.7/site-packages/django/core/servers/basehttp.py", line 140, in handle
    self.raw_requestline = self.rfile.readline(65537)
  File "/usr/lib/python2.7/socket.py", line 480, in readline
    data = self._sock.recv(self._rbufsize)
error: [Errno 104] Connection reset by peer
Traceback (most recent call last):
  File "/usr/lib/python2.7/SocketServer.py", line 596, in process_request_thread
    self.finish_request(request, client_address)
  File "/usr/lib/python2.7/SocketServer.py", line 331, in finish_request
    self.RequestHandlerClass(request, client_address, self)
  File "/usr/lib/python2.7/SocketServer.py", line 652, in __init__
    self.handle()
  File "/home/kk/.virtualenvs/blog-env/local/lib/python2.7/site-packages/django/core/servers/basehttp.py", line 140, in handle
    self.raw_requestline = self.rfile.readline(65537)
  File "/usr/lib/python2.7/socket.py", line 480, in readline
    data = self._sock.recv(self._rbufsize)
error: [Errno 104] Connection reset by peer
[17/Mar/2018 21:27:13] "GET /kk/post/1 HTTP/1.1" 200 8030
Not Found: /favicon.ico
[17/Mar/2018 21:27:13] "GET /favicon.ico HTTP/1.1" 404 3007
[17/Mar/2018 21:27:30] "GET /kk/post/1 HTTP/1.1" 200 8030
[17/Mar/2018 21:27:30] "GET /static/css/base.css HTTP/1.1" 304 0
[17/Mar/2018 21:27:54] "GET /self/blog_admin HTTP/1.1" 301 0
[17/Mar/2018 21:27:55] "GET /self/blog_admin/ HTTP/1.1" 302 0
[17/Mar/2018 21:27:55] "GET /self/blog_admin/login/?next=/self/blog_admin/ HTTP/1.1" 200 1681
[17/Mar/2018 21:27:55] "GET /static/admin/css/base.css HTTP/1.1" 200 16066
[17/Mar/2018 21:27:55] "GET /static/admin/css/login.css HTTP/1.1" 200 1203
[17/Mar/2018 21:27:55] "GET /static/admin/css/fonts.css HTTP/1.1" 200 423
[17/Mar/2018 21:27:55] "GET /static/admin/fonts/Roboto-Regular-webfont.woff HTTP/1.1" 200 80304
[17/Mar/2018 21:27:55] "GET /static/admin/fonts/Roboto-Light-webfont.woff HTTP/1.1" 200 81348
Not Found: /favicon.ico
[17/Mar/2018 21:27:55] "GET /favicon.ico HTTP/1.1" 404 3007
[17/Mar/2018 21:28:06] "POST /self/blog_admin/login/?next=/self/blog_admin/ HTTP/1.1" 302 0
[17/Mar/2018 21:28:06] "GET /self/blog_admin/ HTTP/1.1" 200 7413
[17/Mar/2018 21:28:06] "GET /static/admin/css/dashboard.css HTTP/1.1" 200 412
[17/Mar/2018 21:28:06] "GET /static/admin/fonts/Roboto-Bold-webfont.woff HTTP/1.1" 200 82564
[17/Mar/2018 21:28:06] "GET /static/admin/img/icon-changelink.svg HTTP/1.1" 200 380
[17/Mar/2018 21:28:06] "GET /static/admin/img/icon-addlink.svg HTTP/1.1" 200 331
[17/Mar/2018 21:28:09] "GET /self/blog_admin/selfblog/post/ HTTP/1.1" 200 7551
[17/Mar/2018 21:28:09] "GET /static/admin/css/changelists.css HTTP/1.1" 200 6170
[17/Mar/2018 21:28:09] "GET /static/admin/js/core.js HTTP/1.1" 200 7976
[17/Mar/2018 21:28:09] "GET /static/admin/js/jquery.init.js HTTP/1.1" 200 363
[17/Mar/2018 21:28:09] "GET /self/blog_admin/jsi18n/ HTTP/1.1" 200 7758
[17/Mar/2018 21:28:09] "GET /static/admin/js/admin/RelatedObjectLookups.js HTTP/1.1" 200 6591
[17/Mar/2018 21:28:09] "GET /static/admin/js/actions.js HTTP/1.1" 200 6501
[17/Mar/2018 21:28:09] "GET /static/admin/js/urlify.js HTTP/1.1" 200 8186
[17/Mar/2018 21:28:09] "GET /static/admin/js/prepopulate.js HTTP/1.1" 200 1538
[17/Mar/2018 21:28:10] "GET /static/admin/js/vendor/xregexp/xregexp.js HTTP/1.1" 200 128820
[17/Mar/2018 21:28:10] "GET /static/admin/js/vendor/jquery/jquery.js HTTP/1.1" 200 258648
[17/Mar/2018 21:28:10] "GET /static/admin/img/icon-no.svg HTTP/1.1" 200 560
[17/Mar/2018 21:28:11] "GET /static/admin/img/tooltag-add.svg HTTP/1.1" 200 331
[17/Mar/2018 21:28:20] "GET /self/blog_admin/selfblog/ HTTP/1.1" 200 3161
[17/Mar/2018 21:28:22] "GET /self/blog_admin/selfblog/post/ HTTP/1.1" 200 7551
[17/Mar/2018 21:43:41] "GET /self/blog_admin/selfblog/post/ HTTP/1.1" 302 0
[17/Mar/2018 21:43:41] "GET /self/blog_admin/login/?next=/self/blog_admin/selfblog/post/ HTTP/1.1" 200 1709
Not Found: /favicon.ico
[17/Mar/2018 21:43:42] "GET /favicon.ico HTTP/1.1" 404 3007
[17/Mar/2018 23:37:37] "GET /kk/category/1 HTTP/1.1" 200 6634
[17/Mar/2018 23:37:37] "GET /kk/category/1 HTTP/1.1" 200 6634
[17/Mar/2018 23:37:37] "GET /static/css/base.css HTTP/1.1" 200 128
[18/Mar/2018 08:41:24] "GET /kk HTTP/1.1" 200 6625
[18/Mar/2018 08:41:24] "GET /static/css/base.css HTTP/1.1" 304 0
Not Found: /favicon.ico
[18/Mar/2018 08:41:25] "GET /favicon.ico HTTP/1.1" 404 3007
[18/Mar/2018 08:42:43] "GET /kk HTTP/1.1" 200 6625
[18/Mar/2018 08:43:47] "GET /self/admin HTTP/1.1" 301 0
[18/Mar/2018 08:43:47] "GET /self/admin/ HTTP/1.1" 302 0
[18/Mar/2018 08:43:48] "GET /self/admin/login/?next=/self/admin/ HTTP/1.1" 200 1672
[18/Mar/2018 08:43:48] "GET /static/admin/css/base.css HTTP/1.1" 200 16066
[18/Mar/2018 08:43:48] "GET /static/admin/css/login.css HTTP/1.1" 200 1203
[18/Mar/2018 08:43:48] "GET /static/admin/css/fonts.css HTTP/1.1" 200 423
[18/Mar/2018 08:43:48] "GET /static/admin/fonts/Roboto-Light-webfont.woff HTTP/1.1" 200 81348
[18/Mar/2018 08:43:48] "GET /static/admin/fonts/Roboto-Regular-webfont.woff HTTP/1.1" 200 80304
[18/Mar/2018 08:43:54] "POST /self/admin/login/?next=/self/admin/ HTTP/1.1" 302 0
[18/Mar/2018 08:43:54] "GET /self/admin/ HTTP/1.1" 200 5090
[18/Mar/2018 08:43:55] "GET /static/admin/css/dashboard.css HTTP/1.1" 200 412
[18/Mar/2018 08:43:55] "GET /static/admin/img/icon-addlink.svg HTTP/1.1" 200 331
[18/Mar/2018 08:43:55] "GET /static/admin/img/icon-changelink.svg HTTP/1.1" 200 380
[18/Mar/2018 08:43:55] "GET /static/admin/fonts/Roboto-Bold-webfont.woff HTTP/1.1" 200 82564
[18/Mar/2018 08:43:58] "GET /self/admin/auth/user/add/ HTTP/1.1" 200 5520
[18/Mar/2018 08:43:58] "GET /static/admin/css/forms.css HTTP/1.1" 200 8173
[18/Mar/2018 08:43:58] "GET /static/admin/js/core.js HTTP/1.1" 200 7976
[18/Mar/2018 08:43:58] "GET /self/admin/jsi18n/ HTTP/1.1" 200 7758
[18/Mar/2018 08:43:58] "GET /static/admin/js/jquery.init.js HTTP/1.1" 200 363
[18/Mar/2018 08:43:58] "GET /static/admin/js/admin/RelatedObjectLookups.js HTTP/1.1" 200 6591
[18/Mar/2018 08:43:58] "GET /static/admin/js/actions.js HTTP/1.1" 200 6501
[18/Mar/2018 08:43:58] "GET /static/admin/js/vendor/jquery/jquery.js HTTP/1.1" 200 258648
[18/Mar/2018 08:43:58] "GET /static/admin/css/widgets.css HTTP/1.1" 200 10340
[18/Mar/2018 08:43:58] "GET /static/admin/js/urlify.js HTTP/1.1" 200 8186
[18/Mar/2018 08:43:58] "GET /static/admin/js/prepopulate.js HTTP/1.1" 200 1538
[18/Mar/2018 08:43:58] "GET /static/admin/js/change_form.js HTTP/1.1" 200 712
[18/Mar/2018 08:43:58] "GET /static/admin/js/prepopulate_init.js HTTP/1.1" 200 495
[18/Mar/2018 08:43:59] "GET /static/admin/js/vendor/xregexp/xregexp.js HTTP/1.1" 200 128820
[18/Mar/2018 08:44:12] "POST /self/admin/auth/user/add/ HTTP/1.1" 302 0
[18/Mar/2018 08:44:12] "GET /self/admin/auth/user/3/change/ HTTP/1.1" 200 14741
[18/Mar/2018 08:44:12] "GET /static/admin/js/SelectBox.js HTTP/1.1" 200 5755
[18/Mar/2018 08:44:12] "GET /static/admin/js/SelectFilter2.js HTTP/1.1" 200 12389
[18/Mar/2018 08:44:12] "GET /static/admin/js/calendar.js HTTP/1.1" 200 7790
[18/Mar/2018 08:44:12] "GET /self/admin/jsi18n/ HTTP/1.1" 200 7758
[18/Mar/2018 08:44:12] "GET /static/admin/js/admin/DateTimeShortcuts.js HTTP/1.1" 200 20529
[18/Mar/2018 08:44:12] "GET /static/admin/img/icon-yes.svg HTTP/1.1" 200 436
[18/Mar/2018 08:44:12] "GET /static/admin/img/icon-unknown.svg HTTP/1.1" 200 655
[18/Mar/2018 08:44:12] "GET /static/admin/img/search.svg HTTP/1.1" 200 458
[18/Mar/2018 08:44:12] "GET /static/admin/img/selector-icons.svg HTTP/1.1" 200 3291
[18/Mar/2018 08:44:12] "GET /static/admin/img/icon-unknown-alt.svg HTTP/1.1" 200 655
[18/Mar/2018 08:44:13] "GET /static/admin/img/icon-clock.svg HTTP/1.1" 200 677
[18/Mar/2018 08:44:13] "GET /static/admin/img/icon-calendar.svg HTTP/1.1" 200 1086
[18/Mar/2018 08:44:56] "POST /self/admin/auth/user/3/change/ HTTP/1.1" 302 0
[18/Mar/2018 08:44:56] "GET /self/admin/auth/user/ HTTP/1.1" 200 7527
[18/Mar/2018 08:44:56] "GET /static/admin/css/changelists.css HTTP/1.1" 200 6170
[18/Mar/2018 08:44:56] "GET /self/admin/jsi18n/ HTTP/1.1" 200 7758
[18/Mar/2018 08:44:56] "GET /static/admin/img/icon-no.svg HTTP/1.1" 200 560
[18/Mar/2018 08:44:57] "GET /static/admin/img/tooltag-add.svg HTTP/1.1" 200 331
[18/Mar/2018 08:44:57] "GET /static/admin/img/sorting-icons.svg HTTP/1.1" 200 1097
[18/Mar/2018 08:45:02] "GET /self/admin/auth/user/3/change/ HTTP/1.1" 200 14693
[18/Mar/2018 08:45:02] "GET /self/admin/jsi18n/ HTTP/1.1" 200 7758
[18/Mar/2018 08:45:04] "GET /self/admin/auth/user/ HTTP/1.1" 200 7361
[18/Mar/2018 08:45:04] "GET /self/admin/auth/user/3/change/ HTTP/1.1" 200 14693
[18/Mar/2018 08:45:06] "GET /self/admin/auth/user/add/ HTTP/1.1" 200 5520
[18/Mar/2018 08:45:11] "GET /self/blog_admin HTTP/1.1" 301 0
[18/Mar/2018 08:45:11] "GET /self/blog_admin/ HTTP/1.1" 200 7698
[18/Mar/2018 08:45:15] "GET /self/blog_admin/config/sidebar/add/ HTTP/1.1" 200 6318
[18/Mar/2018 08:45:15] "GET /self/blog_admin/jsi18n/ HTTP/1.1" 200 7758
[18/Mar/2018 08:45:40] "GET /self/blog_admin HTTP/1.1" 301 0
[18/Mar/2018 08:45:40] "GET /self/blog_admin/ HTTP/1.1" 302 0
[18/Mar/2018 08:45:40] "GET /self/blog_admin/login/?next=/self/blog_admin/ HTTP/1.1" 200 1681
[18/Mar/2018 08:45:52] "GET /self/blog_admin HTTP/1.1" 301 0
[18/Mar/2018 08:45:52] "GET /self/blog_admin/ HTTP/1.1" 302 0
[18/Mar/2018 08:45:52] "GET /self/blog_admin/login/?next=/self/blog_admin/ HTTP/1.1" 200 1681
[18/Mar/2018 08:45:52] "GET /static/admin/css/base.css HTTP/1.1" 200 16066
[18/Mar/2018 08:45:52] "GET /static/admin/css/login.css HTTP/1.1" 200 1203
[18/Mar/2018 08:45:52] "GET /static/admin/css/fonts.css HTTP/1.1" 200 423
[18/Mar/2018 08:45:52] "GET /static/admin/fonts/Roboto-Regular-webfont.woff HTTP/1.1" 200 80304
[18/Mar/2018 08:45:52] "GET /static/admin/fonts/Roboto-Light-webfont.woff HTTP/1.1" 200 81348
[18/Mar/2018 08:45:52] "GET /static/admin/fonts/Roboto-Bold-webfont.woff HTTP/1.1" 200 82564
[18/Mar/2018 08:46:03] "GET /self/blog_admin/config/sidebar/add HTTP/1.1" 301 0
[18/Mar/2018 08:46:03] "GET /self/blog_admin/config/sidebar/add/ HTTP/1.1" 302 0
[18/Mar/2018 08:46:03] "GET /self/blog_admin/login/?next=/self/blog_admin/config/sidebar/add/ HTTP/1.1" 200 1719
[18/Mar/2018 08:46:25] "GET /self/blog_admin/config/sidebar/add HTTP/1.1" 301 0
[18/Mar/2018 08:46:25] "GET /self/blog_admin/config/sidebar/add/ HTTP/1.1" 302 0
[18/Mar/2018 08:46:25] "GET /self/blog_admin/login/?next=/self/blog_admin/config/sidebar/add/ HTTP/1.1" 200 1719
[18/Mar/2018 08:46:25] "GET /static/admin/css/base.css HTTP/1.1" 200 16066
[18/Mar/2018 08:46:25] "GET /static/admin/css/login.css HTTP/1.1" 200 1203
[18/Mar/2018 08:46:25] "GET /static/admin/css/fonts.css HTTP/1.1" 200 423
[18/Mar/2018 08:46:25] "GET /static/admin/fonts/Roboto-Regular-webfont.woff HTTP/1.1" 200 80304
[18/Mar/2018 08:46:25] "GET /static/admin/fonts/Roboto-Light-webfont.woff HTTP/1.1" 200 81348
[18/Mar/2018 08:46:25] "GET /static/admin/fonts/Roboto-Bold-webfont.woff HTTP/1.1" 200 82564
[18/Mar/2018 08:46:41] "POST /self/blog_admin/config/sidebar/add/ HTTP/1.1" 302 0
[18/Mar/2018 08:46:41] "GET /self/blog_admin/config/sidebar/ HTTP/1.1" 200 4932
[18/Mar/2018 08:46:41] "GET /self/blog_admin/jsi18n/ HTTP/1.1" 200 7758
[18/Mar/2018 08:46:44] "GET /self/blog_admin/config/sidebar/add/ HTTP/1.1" 200 6318
[18/Mar/2018 08:46:44] "GET /self/blog_admin/jsi18n/ HTTP/1.1" 200 7758
[18/Mar/2018 08:46:59] "POST /self/blog_admin/config/sidebar/add/ HTTP/1.1" 302 0
[18/Mar/2018 08:46:59] "GET /self/blog_admin/config/sidebar/add/ HTTP/1.1" 200 6559
[18/Mar/2018 08:46:59] "GET /self/blog_admin/jsi18n/ HTTP/1.1" 200 7758
[18/Mar/2018 08:47:20] "GET /self/blog_admin/config/sidebar HTTP/1.1" 301 0
[18/Mar/2018 08:47:20] "GET /self/blog_admin/config/sidebar/ HTTP/1.1" 302 0
[18/Mar/2018 08:47:20] "GET /self/blog_admin/login/?next=/self/blog_admin/config/sidebar/ HTTP/1.1" 200 1711
[18/Mar/2018 08:47:35] "GET /self/blog_admin/config/sidebar HTTP/1.1" 301 0
[18/Mar/2018 08:47:35] "GET /self/blog_admin/config/sidebar/ HTTP/1.1" 302 0
[18/Mar/2018 08:47:35] "GET /self/blog_admin/login/?next=/self/blog_admin/config/sidebar/ HTTP/1.1" 200 1711
[18/Mar/2018 08:47:35] "GET /static/admin/css/login.css HTTP/1.1" 200 1203
[18/Mar/2018 08:47:35] "GET /static/admin/css/base.css HTTP/1.1" 200 16066
[18/Mar/2018 08:47:35] "GET /static/admin/css/fonts.css HTTP/1.1" 200 423
[18/Mar/2018 08:47:35] "GET /static/admin/fonts/Roboto-Light-webfont.woff HTTP/1.1" 200 81348
[18/Mar/2018 08:47:35] "GET /static/admin/fonts/Roboto-Regular-webfont.woff HTTP/1.1" 200 80304
[18/Mar/2018 08:47:35] "GET /static/admin/fonts/Roboto-Bold-webfont.woff HTTP/1.1" 200 82564
[18/Mar/2018 08:49:24] "GET /self/blog_admin/ HTTP/1.1" 200 7669
[18/Mar/2018 08:49:30] "GET /self/blog_admin/config/link/add/ HTTP/1.1" 200 6050
[18/Mar/2018 08:49:30] "GET /self/blog_admin/jsi18n/ HTTP/1.1" 200 7758
[18/Mar/2018 08:49:40] "GET /kk HTTP/1.1" 200 6625
[18/Mar/2018 08:49:45] "GET /kylin HTTP/1.1" 200 5856
[18/Mar/2018 08:49:45] "GET /static/img/header.jpg HTTP/1.1" 200 7014
[18/Mar/2018 08:50:36] "POST /self/blog_admin/config/link/add/ HTTP/1.1" 302 0
[18/Mar/2018 08:50:36] "GET /self/blog_admin/config/link/add/ HTTP/1.1" 200 6279
[18/Mar/2018 08:50:37] "GET /self/blog_admin/jsi18n/ HTTP/1.1" 200 7758
[18/Mar/2018 08:50:41] "GET /self/blog_admin/logout/ HTTP/1.1" 200 1030
[18/Mar/2018 08:50:42] "GET /self/blog_admin/ HTTP/1.1" 302 0
[18/Mar/2018 08:50:42] "GET /self/blog_admin/login/?next=/self/blog_admin/ HTTP/1.1" 200 1681
[18/Mar/2018 08:50:47] "POST /self/blog_admin/login/?next=/self/blog_admin/ HTTP/1.1" 200 1813
[18/Mar/2018 08:50:52] "POST /self/blog_admin/login/?next=/self/blog_admin/ HTTP/1.1" 200 1813
[18/Mar/2018 08:51:01] "POST /self/blog_admin/login/?next=/self/blog_admin/ HTTP/1.1" 200 1813
[18/Mar/2018 08:51:12] "POST /self/blog_admin/login/?next=/self/blog_admin/ HTTP/1.1" 200 1813
[18/Mar/2018 08:51:21] "GET /self/admin HTTP/1.1" 301 0
[18/Mar/2018 08:51:21] "GET /self/admin/ HTTP/1.1" 302 0
[18/Mar/2018 08:51:22] "GET /self/admin/login/?next=/self/admin/ HTTP/1.1" 200 1672
[18/Mar/2018 08:51:23] "POST /self/admin/login/?next=/self/admin/ HTTP/1.1" 302 0
[18/Mar/2018 08:51:24] "GET /self/admin/ HTTP/1.1" 200 5350
[18/Mar/2018 08:51:25] "GET /self/admin/auth/user/ HTTP/1.1" 200 7361
[18/Mar/2018 08:51:25] "GET /self/admin/jsi18n/ HTTP/1.1" 200 7758
[18/Mar/2018 08:51:28] "GET /self/admin/auth/user/3/change/ HTTP/1.1" 200 14693
[18/Mar/2018 08:51:28] "GET /self/admin/jsi18n/ HTTP/1.1" 200 7758
[18/Mar/2018 08:52:07] "POST /self/admin/auth/user/3/change/ HTTP/1.1" 302 0
[18/Mar/2018 08:52:07] "GET /self/admin/auth/user/ HTTP/1.1" 200 7527
[18/Mar/2018 08:52:07] "GET /self/admin/jsi18n/ HTTP/1.1" 200 7758
[18/Mar/2018 08:52:13] "GET /self/blog_admin HTTP/1.1" 301 0
[18/Mar/2018 08:52:14] "GET /self/blog_admin/ HTTP/1.1" 200 7715
[18/Mar/2018 08:52:16] "GET /self/blog_admin/logout/ HTTP/1.1" 200 1030
[18/Mar/2018 08:52:18] "GET /self/blog_admin/ HTTP/1.1" 302 0
[18/Mar/2018 08:52:18] "GET /self/blog_admin/login/?next=/self/blog_admin/ HTTP/1.1" 200 1681
[18/Mar/2018 08:52:22] "POST /self/blog_admin/login/?next=/self/blog_admin/ HTTP/1.1" 302 0
[18/Mar/2018 08:52:22] "GET /self/blog_admin/ HTTP/1.1" 200 5112
[18/Mar/2018 08:52:27] "GET /self/blog_admin/config/link/ HTTP/1.1" 200 5088
[18/Mar/2018 08:52:27] "GET /self/blog_admin/jsi18n/ HTTP/1.1" 200 7758
[18/Mar/2018 08:52:30] "GET /self/blog_admin/config/link/add/ HTTP/1.1" 200 6053
[18/Mar/2018 08:52:30] "GET /self/blog_admin/jsi18n/ HTTP/1.1" 200 7758
[18/Mar/2018 08:52:55] "POST /self/blog_admin/config/link/add/ HTTP/1.1" 302 0
[18/Mar/2018 08:52:55] "GET /self/blog_admin/config/link/ HTTP/1.1" 200 5674
[18/Mar/2018 08:52:55] "GET /self/blog_admin/jsi18n/ HTTP/1.1" 200 7758
[18/Mar/2018 08:52:58] "GET /self/blog_admin/config/ HTTP/1.1" 200 2721
[18/Mar/2018 08:53:00] "GET /self/blog_admin/config/sidebar/ HTTP/1.1" 200 5097
[18/Mar/2018 08:53:00] "GET /self/blog_admin/jsi18n/ HTTP/1.1" 200 7758
[18/Mar/2018 08:53:02] "GET /self/blog_admin/ HTTP/1.1" 200 5392
[18/Mar/2018 08:53:05] "GET /self/blog_admin/selfblog/tag/ HTTP/1.1" 200 3124
[18/Mar/2018 08:53:05] "GET /self/blog_admin/jsi18n/ HTTP/1.1" 200 7758
[18/Mar/2018 08:53:06] "GET /self/blog_admin/selfblog/tag/add/ HTTP/1.1" 200 4423
[18/Mar/2018 08:53:06] "GET /self/blog_admin/jsi18n/ HTTP/1.1" 200 7758
[18/Mar/2018 08:53:18] "POST /self/blog_admin/selfblog/tag/add/ HTTP/1.1" 302 0
[18/Mar/2018 08:53:18] "GET /self/blog_admin/selfblog/tag/add/ HTTP/1.1" 200 4657
[18/Mar/2018 08:53:18] "GET /self/blog_admin/jsi18n/ HTTP/1.1" 200 7758
[18/Mar/2018 08:53:39] "POST /self/blog_admin/selfblog/tag/add/ HTTP/1.1" 302 0
[18/Mar/2018 08:53:39] "GET /self/blog_admin/selfblog/tag/add/ HTTP/1.1" 200 4657
[18/Mar/2018 08:53:39] "GET /self/blog_admin/jsi18n/ HTTP/1.1" 200 7758
[18/Mar/2018 08:53:45] "POST /self/blog_admin/selfblog/tag/add/ HTTP/1.1" 302 0
[18/Mar/2018 08:53:46] "GET /self/blog_admin/selfblog/tag/add/ HTTP/1.1" 200 4647
[18/Mar/2018 08:53:46] "GET /self/blog_admin/jsi18n/ HTTP/1.1" 200 7758
[18/Mar/2018 08:53:49] "POST /self/blog_admin/selfblog/tag/add/ HTTP/1.1" 302 0
[18/Mar/2018 08:53:50] "GET /self/blog_admin/selfblog/tag/add/ HTTP/1.1" 200 4649
[18/Mar/2018 08:53:50] "GET /self/blog_admin/jsi18n/ HTTP/1.1" 200 7758
[18/Mar/2018 08:53:53] "POST /self/blog_admin/selfblog/tag/add/ HTTP/1.1" 302 0
[18/Mar/2018 08:53:53] "GET /self/blog_admin/selfblog/tag/add/ HTTP/1.1" 200 4648
[18/Mar/2018 08:53:54] "GET /self/blog_admin/jsi18n/ HTTP/1.1" 200 7758
[18/Mar/2018 08:53:57] "POST /self/blog_admin/selfblog/tag/add/ HTTP/1.1" 302 0
[18/Mar/2018 08:53:57] "GET /self/blog_admin/selfblog/tag/add/ HTTP/1.1" 200 4648
[18/Mar/2018 08:53:57] "GET /self/blog_admin/jsi18n/ HTTP/1.1" 200 7758
[18/Mar/2018 08:54:01] "POST /self/blog_admin/selfblog/tag/add/ HTTP/1.1" 302 0
[18/Mar/2018 08:54:01] "GET /self/blog_admin/selfblog/tag/add/ HTTP/1.1" 200 4655
[18/Mar/2018 08:54:01] "GET /self/blog_admin/jsi18n/ HTTP/1.1" 200 7758
[18/Mar/2018 08:54:05] "POST /self/blog_admin/selfblog/tag/add/ HTTP/1.1" 302 0
[18/Mar/2018 08:54:05] "GET /self/blog_admin/selfblog/tag/add/ HTTP/1.1" 200 4655
[18/Mar/2018 08:54:05] "GET /self/blog_admin/jsi18n/ HTTP/1.1" 200 7758
[18/Mar/2018 08:54:07] "GET /self/blog_admin/ HTTP/1.1" 200 7342
[18/Mar/2018 08:54:12] "GET /self/blog_admin/selfblog/category/add/ HTTP/1.1" 200 4844
[18/Mar/2018 08:54:12] "GET /self/blog_admin/jsi18n/ HTTP/1.1" 200 7758
[18/Mar/2018 08:54:19] "POST /self/blog_admin/selfblog/category/add/ HTTP/1.1" 302 0
[18/Mar/2018 08:54:19] "GET /self/blog_admin/selfblog/category/add/ HTTP/1.1" 200 5080
[18/Mar/2018 08:54:19] "GET /self/blog_admin/jsi18n/ HTTP/1.1" 200 7758
[18/Mar/2018 08:54:25] "POST /self/blog_admin/selfblog/category/add/ HTTP/1.1" 302 0
[18/Mar/2018 08:54:25] "GET /self/blog_admin/selfblog/category/add/ HTTP/1.1" 200 5080
[18/Mar/2018 08:54:25] "GET /self/blog_admin/jsi18n/ HTTP/1.1" 200 7758
[18/Mar/2018 08:54:33] "POST /self/blog_admin/selfblog/category/add/ HTTP/1.1" 302 0
[18/Mar/2018 08:54:33] "GET /self/blog_admin/selfblog/category/add/ HTTP/1.1" 200 5080
[18/Mar/2018 08:54:33] "GET /self/blog_admin/jsi18n/ HTTP/1.1" 200 7758
[18/Mar/2018 08:54:37] "POST /self/blog_admin/selfblog/category/add/ HTTP/1.1" 302 0
[18/Mar/2018 08:54:38] "GET /self/blog_admin/selfblog/category/add/ HTTP/1.1" 200 5080
[18/Mar/2018 08:54:38] "GET /self/blog_admin/jsi18n/ HTTP/1.1" 200 7758
[18/Mar/2018 08:54:45] "POST /self/blog_admin/selfblog/category/add/ HTTP/1.1" 302 0
[18/Mar/2018 08:54:45] "GET /self/blog_admin/selfblog/category/add/ HTTP/1.1" 200 5083
[18/Mar/2018 08:54:46] "GET /self/blog_admin/jsi18n/ HTTP/1.1" 200 7758
[18/Mar/2018 08:54:48] "GET /kylin HTTP/1.1" 200 7760
[18/Mar/2018 08:54:48] "GET /static/css/base.css HTTP/1.1" 304 0
[18/Mar/2018 08:54:48] "GET /static/img/header.jpg HTTP/1.1" 304 0
[18/Mar/2018 08:55:00] "GET /self/blog_admin/selfblog/category/ HTTP/1.1" 200 6669
[18/Mar/2018 08:55:00] "GET /self/blog_admin/jsi18n/ HTTP/1.1" 200 7758
[18/Mar/2018 08:55:05] "GET /self/blog_admin/selfblog/category/5/change/ HTTP/1.1" 200 5108
[18/Mar/2018 08:55:05] "GET /self/blog_admin/jsi18n/ HTTP/1.1" 200 7758
[18/Mar/2018 08:55:07] "POST /self/blog_admin/selfblog/category/5/change/ HTTP/1.1" 302 0
[18/Mar/2018 08:55:07] "GET /self/blog_admin/selfblog/category/ HTTP/1.1" 200 6855
[18/Mar/2018 08:55:07] "GET /self/blog_admin/jsi18n/ HTTP/1.1" 200 7758
[18/Mar/2018 08:55:10] "GET /self/blog_admin/selfblog/category/6/change/ HTTP/1.1" 200 5108
[18/Mar/2018 08:55:10] "GET /self/blog_admin/jsi18n/ HTTP/1.1" 200 7758
[18/Mar/2018 08:55:12] "POST /self/blog_admin/selfblog/category/6/change/ HTTP/1.1" 302 0
[18/Mar/2018 08:55:12] "GET /self/blog_admin/selfblog/category/ HTTP/1.1" 200 6855
[18/Mar/2018 08:55:12] "GET /self/blog_admin/jsi18n/ HTTP/1.1" 200 7758
[18/Mar/2018 08:55:14] "GET /kylin HTTP/1.1" 200 7958
[18/Mar/2018 08:55:14] "GET /static/img/header.jpg HTTP/1.1" 304 0
[18/Mar/2018 08:55:14] "GET /static/css/base.css HTTP/1.1" 304 0
[18/Mar/2018 08:55:33] "GET /kylin HTTP/1.1" 200 7958
[18/Mar/2018 08:55:35] "GET /kylin/category/4 HTTP/1.1" 200 7973
[18/Mar/2018 08:55:36] "GET /kylin/category/5 HTTP/1.1" 200 7973
[18/Mar/2018 08:55:36] "GET /kylin/category/6 HTTP/1.1" 200 7973
[18/Mar/2018 08:55:37] "GET /kylin/category/8 HTTP/1.1" 200 7976
[18/Mar/2018 08:55:37] "GET /kylin/category/5 HTTP/1.1" 200 7973
[18/Mar/2018 08:55:38] "GET /kylin/category/4 HTTP/1.1" 200 7973
[18/Mar/2018 08:55:47] "GET /self/blog_admin/ HTTP/1.1" 200 7610
Internal Server Error: /self/blog_admin/selfblog/post/
Traceback (most recent call last):
  File "/home/kk/.virtualenvs/blog-env/local/lib/python2.7/site-packages/django/core/handlers/exception.py", line 41, in inner
    response = get_response(request)
  File "/home/kk/.virtualenvs/blog-env/local/lib/python2.7/site-packages/django/core/handlers/base.py", line 187, in _get_response
    response = self.process_exception_by_middleware(e, request)
  File "/home/kk/.virtualenvs/blog-env/local/lib/python2.7/site-packages/django/core/handlers/base.py", line 185, in _get_response
    response = wrapped_callback(request, *callback_args, **callback_kwargs)
  File "/home/kk/.virtualenvs/blog-env/local/lib/python2.7/site-packages/django/contrib/admin/options.py", line 551, in wrapper
    return self.admin_site.admin_view(view)(*args, **kwargs)
  File "/home/kk/.virtualenvs/blog-env/local/lib/python2.7/site-packages/django/utils/decorators.py", line 149, in _wrapped_view
    response = view_func(request, *args, **kwargs)
  File "/home/kk/.virtualenvs/blog-env/local/lib/python2.7/site-packages/django/views/decorators/cache.py", line 57, in _wrapped_view_func
    response = view_func(request, *args, **kwargs)
  File "/home/kk/.virtualenvs/blog-env/local/lib/python2.7/site-packages/django/contrib/admin/sites.py", line 224, in inner
    return view(request, *args, **kwargs)
  File "/home/kk/.virtualenvs/blog-env/local/lib/python2.7/site-packages/django/utils/decorators.py", line 67, in _wrapper
    return bound_func(*args, **kwargs)
  File "/home/kk/.virtualenvs/blog-env/local/lib/python2.7/site-packages/django/utils/decorators.py", line 149, in _wrapped_view
    response = view_func(request, *args, **kwargs)
  File "/home/kk/.virtualenvs/blog-env/local/lib/python2.7/site-packages/django/utils/decorators.py", line 63, in bound_func
    return func.__get__(self, type(self))(*args2, **kwargs2)
  File "/home/kk/.virtualenvs/blog-env/local/lib/python2.7/site-packages/django/contrib/admin/options.py", line 1662, in changelist_view
    selection_note=_('0 of %(cnt)s selected') % {'cnt': len(cl.result_list)},
  File "/home/kk/.virtualenvs/blog-env/local/lib/python2.7/site-packages/django/db/models/query.py", line 232, in __len__
    self._fetch_all()
  File "/home/kk/.virtualenvs/blog-env/local/lib/python2.7/site-packages/django/db/models/query.py", line 1118, in _fetch_all
    self._result_cache = list(self._iterable_class(self))
  File "/home/kk/.virtualenvs/blog-env/local/lib/python2.7/site-packages/django/db/models/query.py", line 53, in __iter__
    results = compiler.execute_sql(chunked_fetch=self.chunked_fetch)
  File "/home/kk/.virtualenvs/blog-env/local/lib/python2.7/site-packages/django/db/models/sql/compiler.py", line 886, in execute_sql
    raise original_exception
OperationalError: (1153, "Got a packet bigger than 'max_allowed_packet' bytes")
[18/Mar/2018 08:55:49] "GET /self/blog_admin/selfblog/post/ HTTP/1.1" 500 120151
[18/Mar/2018 08:56:02] "GET /self/blog_admin/ HTTP/1.1" 200 7610
[18/Mar/2018 08:56:04] "GET /self/blog_admin/selfblog/post/add/ HTTP/1.1" 200 8468
[18/Mar/2018 08:56:04] "GET /self/blog_admin/jsi18n/ HTTP/1.1" 200 7758
[18/Mar/2018 08:56:06] "GET /self/blog_admin/ HTTP/1.1" 200 7610
Internal Server Error: /self/blog_admin/selfblog/post/
Traceback (most recent call last):
  File "/home/kk/.virtualenvs/blog-env/local/lib/python2.7/site-packages/django/core/handlers/exception.py", line 41, in inner
    response = get_response(request)
  File "/home/kk/.virtualenvs/blog-env/local/lib/python2.7/site-packages/django/core/handlers/base.py", line 187, in _get_response
    response = self.process_exception_by_middleware(e, request)
  File "/home/kk/.virtualenvs/blog-env/local/lib/python2.7/site-packages/django/core/handlers/base.py", line 185, in _get_response
    response = wrapped_callback(request, *callback_args, **callback_kwargs)
  File "/home/kk/.virtualenvs/blog-env/local/lib/python2.7/site-packages/django/contrib/admin/options.py", line 551, in wrapper
    return self.admin_site.admin_view(view)(*args, **kwargs)
  File "/home/kk/.virtualenvs/blog-env/local/lib/python2.7/site-packages/django/utils/decorators.py", line 149, in _wrapped_view
    response = view_func(request, *args, **kwargs)
  File "/home/kk/.virtualenvs/blog-env/local/lib/python2.7/site-packages/django/views/decorators/cache.py", line 57, in _wrapped_view_func
    response = view_func(request, *args, **kwargs)
  File "/home/kk/.virtualenvs/blog-env/local/lib/python2.7/site-packages/django/contrib/admin/sites.py", line 224, in inner
    return view(request, *args, **kwargs)
  File "/home/kk/.virtualenvs/blog-env/local/lib/python2.7/site-packages/django/utils/decorators.py", line 67, in _wrapper
    return bound_func(*args, **kwargs)
  File "/home/kk/.virtualenvs/blog-env/local/lib/python2.7/site-packages/django/utils/decorators.py", line 149, in _wrapped_view
    response = view_func(request, *args, **kwargs)
  File "/home/kk/.virtualenvs/blog-env/local/lib/python2.7/site-packages/django/utils/decorators.py", line 63, in bound_func
    return func.__get__(self, type(self))(*args2, **kwargs2)
  File "/home/kk/.virtualenvs/blog-env/local/lib/python2.7/site-packages/django/contrib/admin/options.py", line 1662, in changelist_view
    selection_note=_('0 of %(cnt)s selected') % {'cnt': len(cl.result_list)},
  File "/home/kk/.virtualenvs/blog-env/local/lib/python2.7/site-packages/django/db/models/query.py", line 232, in __len__
    self._fetch_all()
  File "/home/kk/.virtualenvs/blog-env/local/lib/python2.7/site-packages/django/db/models/query.py", line 1118, in _fetch_all
    self._result_cache = list(self._iterable_class(self))
  File "/home/kk/.virtualenvs/blog-env/local/lib/python2.7/site-packages/django/db/models/query.py", line 53, in __iter__
    results = compiler.execute_sql(chunked_fetch=self.chunked_fetch)
  File "/home/kk/.virtualenvs/blog-env/local/lib/python2.7/site-packages/django/db/models/sql/compiler.py", line 886, in execute_sql
    raise original_exception
OperationalError: (1153, "Got a packet bigger than 'max_allowed_packet' bytes")
[18/Mar/2018 08:56:07] "GET /self/blog_admin/selfblog/post/ HTTP/1.1" 500 120149
[18/Mar/2018 08:57:05] "GET /self/blog_admin/ HTTP/1.1" 200 7610
[18/Mar/2018 08:57:06] "GET /self/blog_admin/comment/comment/add/ HTTP/1.1" 200 7048
[18/Mar/2018 08:57:06] "GET /self/blog_admin/jsi18n/ HTTP/1.1" 200 7758
[18/Mar/2018 08:57:10] "GET /self/blog_admin/ HTTP/1.1" 200 7610
[18/Mar/2018 08:57:11] "GET /self/blog_admin/selfblog/post/add/ HTTP/1.1" 200 8468
[18/Mar/2018 08:57:11] "GET /self/blog_admin/jsi18n/ HTTP/1.1" 200 7758
[18/Mar/2018 08:57:53] "POST /self/blog_admin/selfblog/post/add/ HTTP/1.1" 302 0
[18/Mar/2018 08:57:53] "GET /self/blog_admin/selfblog/post/add/ HTTP/1.1" 200 8704
[18/Mar/2018 08:57:53] "GET /self/blog_admin/jsi18n/ HTTP/1.1" 200 7758
[18/Mar/2018 08:58:12] "POST /self/blog_admin/selfblog/post/add/ HTTP/1.1" 302 0
[18/Mar/2018 08:58:12] "GET /self/blog_admin/selfblog/post/add/ HTTP/1.1" 200 8709
[18/Mar/2018 08:58:12] "GET /self/blog_admin/jsi18n/ HTTP/1.1" 200 7758
[18/Mar/2018 08:58:40] "POST /self/blog_admin/selfblog/post/add/ HTTP/1.1" 302 0
[18/Mar/2018 08:58:40] "GET /self/blog_admin/selfblog/post/add/ HTTP/1.1" 200 8700
[18/Mar/2018 08:58:40] "GET /self/blog_admin/jsi18n/ HTTP/1.1" 200 7758
[18/Mar/2018 08:58:42] "GET /kylin/category/4 HTTP/1.1" 200 9932
[18/Mar/2018 08:58:42] "GET /static/img/header.jpg HTTP/1.1" 304 0
[18/Mar/2018 08:58:42] "GET /static/css/base.css HTTP/1.1" 304 0
[18/Mar/2018 08:58:44] "GET /kylin HTTP/1.1" 200 10586
[18/Mar/2018 08:58:48] "GET /kylin/post/4 HTTP/1.1" 200 9186
[18/Mar/2018 08:58:50] "GET /kylin HTTP/1.1" 200 10586
[18/Mar/2018 08:58:58] "GET /kylin/post/2 HTTP/1.1" 200 9193
[18/Mar/2018 08:59:02] "GET /kylin/post/2 HTTP/1.1" 200 9193
[18/Mar/2018 08:59:03] "GET /kylin/post/3 HTTP/1.1" 200 9211
[18/Mar/2018 08:59:04] "GET /kylin/post/4 HTTP/1.1" 200 9186
[18/Mar/2018 08:59:06] "GET /kylin HTTP/1.1" 200 10586
[18/Mar/2018 08:59:10] "GET /kylin/category/4 HTTP/1.1" 200 9932
[18/Mar/2018 08:59:11] "GET /kylin/category/5 HTTP/1.1" 200 9236
[18/Mar/2018 08:59:12] "GET /kylin/category/4 HTTP/1.1" 200 9932
[18/Mar/2018 08:59:13] "GET /kylin/category/5 HTTP/1.1" 200 9236
[18/Mar/2018 08:59:13] "GET /kylin/category/6 HTTP/1.1" 200 8601
[18/Mar/2018 08:59:14] "GET /kylin/category/8 HTTP/1.1" 200 8604
[18/Mar/2018 08:59:15] "GET /kylin/category/6 HTTP/1.1" 200 8601
[18/Mar/2018 08:59:15] "GET /kylin HTTP/1.1" 200 10586
[18/Mar/2018 08:59:35] "POST /self/blog_admin/selfblog/post/add/ HTTP/1.1" 302 0
[18/Mar/2018 08:59:36] "GET /self/blog_admin/selfblog/post/add/ HTTP/1.1" 200 8690
[18/Mar/2018 08:59:36] "GET /self/blog_admin/jsi18n/ HTTP/1.1" 200 7758
[18/Mar/2018 09:00:00] "POST /self/blog_admin/selfblog/post/add/ HTTP/1.1" 302 0
[18/Mar/2018 09:00:00] "GET /self/blog_admin/selfblog/post/add/ HTTP/1.1" 200 8695
[18/Mar/2018 09:00:00] "GET /self/blog_admin/jsi18n/ HTTP/1.1" 200 7758
[18/Mar/2018 09:00:02] "GET /kylin HTTP/1.1" 200 12122
[18/Mar/2018 09:00:02] "GET /static/css/base.css HTTP/1.1" 304 0
[18/Mar/2018 09:00:02] "GET /static/img/header.jpg HTTP/1.1" 304 0
[18/Mar/2018 09:00:05] "GET /kylin/category/4 HTTP/1.1" 200 10155
[18/Mar/2018 09:00:06] "GET /kylin/category/5 HTTP/1.1" 200 9459
[18/Mar/2018 09:00:07] "GET /kylin/category/6 HTTP/1.1" 200 9433
[18/Mar/2018 09:00:07] "GET /kylin/category/8 HTTP/1.1" 200 9463
[18/Mar/2018 09:00:08] "GET /kylin HTTP/1.1" 200 12122
[18/Mar/2018 09:00:49] "POST /self/blog_admin/selfblog/post/add/ HTTP/1.1" 302 0
[18/Mar/2018 09:00:49] "GET /self/blog_admin/selfblog/post/add/ HTTP/1.1" 200 8700
[18/Mar/2018 09:00:49] "GET /self/blog_admin/jsi18n/ HTTP/1.1" 200 7758
Internal Server Error: /self/blog_admin/selfblog/post/add/
Traceback (most recent call last):
  File "/home/kk/.virtualenvs/blog-env/local/lib/python2.7/site-packages/django/core/handlers/exception.py", line 41, in inner
    response = get_response(request)
  File "/home/kk/.virtualenvs/blog-env/local/lib/python2.7/site-packages/django/core/handlers/base.py", line 187, in _get_response
    response = self.process_exception_by_middleware(e, request)
  File "/home/kk/.virtualenvs/blog-env/local/lib/python2.7/site-packages/django/core/handlers/base.py", line 185, in _get_response
    response = wrapped_callback(request, *callback_args, **callback_kwargs)
  File "/home/kk/.virtualenvs/blog-env/local/lib/python2.7/site-packages/django/contrib/admin/options.py", line 551, in wrapper
    return self.admin_site.admin_view(view)(*args, **kwargs)
  File "/home/kk/.virtualenvs/blog-env/local/lib/python2.7/site-packages/django/utils/decorators.py", line 149, in _wrapped_view
    response = view_func(request, *args, **kwargs)
  File "/home/kk/.virtualenvs/blog-env/local/lib/python2.7/site-packages/django/views/decorators/cache.py", line 57, in _wrapped_view_func
    response = view_func(request, *args, **kwargs)
  File "/home/kk/.virtualenvs/blog-env/local/lib/python2.7/site-packages/django/contrib/admin/sites.py", line 224, in inner
    return view(request, *args, **kwargs)
  File "/home/kk/.virtualenvs/blog-env/local/lib/python2.7/site-packages/django/contrib/admin/options.py", line 1508, in add_view
    return self.changeform_view(request, None, form_url, extra_context)
  File "/home/kk/.virtualenvs/blog-env/local/lib/python2.7/site-packages/django/utils/decorators.py", line 67, in _wrapper
    return bound_func(*args, **kwargs)
  File "/home/kk/.virtualenvs/blog-env/local/lib/python2.7/site-packages/django/utils/decorators.py", line 149, in _wrapped_view
    response = view_func(request, *args, **kwargs)
  File "/home/kk/.virtualenvs/blog-env/local/lib/python2.7/site-packages/django/utils/decorators.py", line 63, in bound_func
    return func.__get__(self, type(self))(*args2, **kwargs2)
  File "/home/kk/.virtualenvs/blog-env/local/lib/python2.7/site-packages/django/contrib/admin/options.py", line 1408, in changeform_view
    return self._changeform_view(request, object_id, form_url, extra_context)
  File "/home/kk/.virtualenvs/blog-env/local/lib/python2.7/site-packages/django/contrib/admin/options.py", line 1448, in _changeform_view
    self.save_model(request, new_object, form, not add)
  File "/home/kk/prac/blog/selfblog/baseadmin.py", line 11, in save_model
    super(BaseOwnerAdmin, self).save_model(request, obj, form, change)
  File "/home/kk/.virtualenvs/blog-env/local/lib/python2.7/site-packages/django/contrib/admin/options.py", line 979, in save_model
    obj.save()
  File "/home/kk/.virtualenvs/blog-env/local/lib/python2.7/site-packages/django/db/models/base.py", line 807, in save
    force_update=force_update, update_fields=update_fields)
  File "/home/kk/.virtualenvs/blog-env/local/lib/python2.7/site-packages/django/db/models/base.py", line 837, in save_base
    updated = self._save_table(raw, cls, force_insert, force_update, using, update_fields)
  File "/home/kk/.virtualenvs/blog-env/local/lib/python2.7/site-packages/django/db/models/base.py", line 923, in _save_table
    result = self._do_insert(cls._base_manager, using, fields, update_pk, raw)
  File "/home/kk/.virtualenvs/blog-env/local/lib/python2.7/site-packages/django/db/models/base.py", line 962, in _do_insert
    using=using, raw=raw)
  File "/home/kk/.virtualenvs/blog-env/local/lib/python2.7/site-packages/django/db/models/manager.py", line 85, in manager_method
    return getattr(self.get_queryset(), name)(*args, **kwargs)
  File "/home/kk/.virtualenvs/blog-env/local/lib/python2.7/site-packages/django/db/models/query.py", line 1076, in _insert
    return query.get_compiler(using=using).execute_sql(return_id)
  File "/home/kk/.virtualenvs/blog-env/local/lib/python2.7/site-packages/django/db/models/sql/compiler.py", line 1099, in execute_sql
    cursor.execute(sql, params)
  File "/home/kk/.virtualenvs/blog-env/local/lib/python2.7/site-packages/django/db/backends/utils.py", line 80, in execute
    return super(CursorDebugWrapper, self).execute(sql, params)
  File "/home/kk/.virtualenvs/blog-env/local/lib/python2.7/site-packages/django/db/backends/utils.py", line 65, in execute
    return self.cursor.execute(sql, params)
  File "/home/kk/.virtualenvs/blog-env/local/lib/python2.7/site-packages/django/db/utils.py", line 94, in __exit__
    six.reraise(dj_exc_type, dj_exc_value, traceback)
  File "/home/kk/.virtualenvs/blog-env/local/lib/python2.7/site-packages/django/db/backends/utils.py", line 65, in execute
    return self.cursor.execute(sql, params)
  File "/home/kk/.virtualenvs/blog-env/local/lib/python2.7/site-packages/django/db/backends/mysql/base.py", line 101, in execute
    return self.cursor.execute(query, args)
  File "/home/kk/.virtualenvs/blog-env/local/lib/python2.7/site-packages/MySQLdb/cursors.py", line 250, in execute
    self.errorhandler(self, exc, value)
  File "/home/kk/.virtualenvs/blog-env/local/lib/python2.7/site-packages/MySQLdb/connections.py", line 50, in defaulterrorhandler
    raise errorvalue
OperationalError: (1153, "Got a packet bigger than 'max_allowed_packet' bytes")
[18/Mar/2018 09:01:16] "POST /self/blog_admin/selfblog/post/add/ HTTP/1.1" 500 211876
[18/Mar/2018 09:01:31] "GET /self/blog_admin/selfblog/post/add/ HTTP/1.1" 200 8468
[18/Mar/2018 09:01:43] "POST /self/blog_admin/selfblog/post/add/ HTTP/1.1" 302 0
Internal Server Error: /self/blog_admin/selfblog/post/
Traceback (most recent call last):
  File "/home/kk/.virtualenvs/blog-env/local/lib/python2.7/site-packages/django/core/handlers/exception.py", line 41, in inner
    response = get_response(request)
  File "/home/kk/.virtualenvs/blog-env/local/lib/python2.7/site-packages/django/core/handlers/base.py", line 187, in _get_response
    response = self.process_exception_by_middleware(e, request)
  File "/home/kk/.virtualenvs/blog-env/local/lib/python2.7/site-packages/django/core/handlers/base.py", line 185, in _get_response
    response = wrapped_callback(request, *callback_args, **callback_kwargs)
  File "/home/kk/.virtualenvs/blog-env/local/lib/python2.7/site-packages/django/contrib/admin/options.py", line 551, in wrapper
    return self.admin_site.admin_view(view)(*args, **kwargs)
  File "/home/kk/.virtualenvs/blog-env/local/lib/python2.7/site-packages/django/utils/decorators.py", line 149, in _wrapped_view
    response = view_func(request, *args, **kwargs)
  File "/home/kk/.virtualenvs/blog-env/local/lib/python2.7/site-packages/django/views/decorators/cache.py", line 57, in _wrapped_view_func
    response = view_func(request, *args, **kwargs)
  File "/home/kk/.virtualenvs/blog-env/local/lib/python2.7/site-packages/django/contrib/admin/sites.py", line 224, in inner
    return view(request, *args, **kwargs)
  File "/home/kk/.virtualenvs/blog-env/local/lib/python2.7/site-packages/django/utils/decorators.py", line 67, in _wrapper
    return bound_func(*args, **kwargs)
  File "/home/kk/.virtualenvs/blog-env/local/lib/python2.7/site-packages/django/utils/decorators.py", line 149, in _wrapped_view
    response = view_func(request, *args, **kwargs)
  File "/home/kk/.virtualenvs/blog-env/local/lib/python2.7/site-packages/django/utils/decorators.py", line 63, in bound_func
    return func.__get__(self, type(self))(*args2, **kwargs2)
  File "/home/kk/.virtualenvs/blog-env/local/lib/python2.7/site-packages/django/contrib/admin/options.py", line 1662, in changelist_view
    selection_note=_('0 of %(cnt)s selected') % {'cnt': len(cl.result_list)},
  File "/home/kk/.virtualenvs/blog-env/local/lib/python2.7/site-packages/django/db/models/query.py", line 232, in __len__
    self._fetch_all()
  File "/home/kk/.virtualenvs/blog-env/local/lib/python2.7/site-packages/django/db/models/query.py", line 1118, in _fetch_all
    self._result_cache = list(self._iterable_class(self))
  File "/home/kk/.virtualenvs/blog-env/local/lib/python2.7/site-packages/django/db/models/query.py", line 53, in __iter__
    results = compiler.execute_sql(chunked_fetch=self.chunked_fetch)
  File "/home/kk/.virtualenvs/blog-env/local/lib/python2.7/site-packages/django/db/models/sql/compiler.py", line 886, in execute_sql
    raise original_exception
OperationalError: (1153, "Got a packet bigger than 'max_allowed_packet' bytes")
[18/Mar/2018 09:01:44] "GET /self/blog_admin/selfblog/post/ HTTP/1.1" 500 121174
[18/Mar/2018 09:01:46] "GET /kylin HTTP/1.1" 200 13335
[18/Mar/2018 09:01:46] "GET /static/css/base.css HTTP/1.1" 304 0
[18/Mar/2018 09:01:46] "GET /static/img/header.jpg HTTP/1.1" 304 0
[18/Mar/2018 09:01:49] "GET /kylin/post/8 HTTP/1.1" 200 9575
[18/Mar/2018 09:01:57] "GET /kylin?page=2 HTTP/1.1" 200 9802
[18/Mar/2018 09:01:58] "GET /kylin/category/8 HTTP/1.1" 200 9694
[18/Mar/2018 09:01:59] "GET /kylin/category/6 HTTP/1.1" 200 10517
[18/Mar/2018 09:01:59] "GET /kylin/category/5 HTTP/1.1" 200 9690
[18/Mar/2018 09:02:00] "GET /kylin/category/4 HTTP/1.1" 200 10386
[18/Mar/2018 09:02:01] "GET /kylin HTTP/1.1" 200 13335
[18/Mar/2018 09:02:06] "GET /kylin?page=2 HTTP/1.1" 200 9802
[18/Mar/2018 09:02:08] "GET /kylin?page=1 HTTP/1.1" 200 13335
[18/Mar/2018 09:10:18] "GET /self/blog_admin/selfblog/post/ HTTP/1.1" 200 12591
[18/Mar/2018 09:10:18] "GET /static/admin/css/base.css HTTP/1.1" 304 0
[18/Mar/2018 09:10:19] "GET /static/admin/css/changelists.css HTTP/1.1" 304 0
[18/Mar/2018 09:10:19] "GET /static/admin/js/core.js HTTP/1.1" 304 0
[18/Mar/2018 09:10:19] "GET /static/admin/js/vendor/jquery/jquery.js HTTP/1.1" 304 0
[18/Mar/2018 09:10:19] "GET /static/admin/js/jquery.init.js HTTP/1.1" 304 0
[18/Mar/2018 09:10:19] "GET /static/admin/js/admin/RelatedObjectLookups.js HTTP/1.1" 304 0
[18/Mar/2018 09:10:19] "GET /static/admin/js/actions.js HTTP/1.1" 304 0
[18/Mar/2018 09:10:19] "GET /static/admin/js/urlify.js HTTP/1.1" 304 0
[18/Mar/2018 09:10:19] "GET /static/admin/js/prepopulate.js HTTP/1.1" 304 0
[18/Mar/2018 09:10:19] "GET /static/admin/js/vendor/xregexp/xregexp.js HTTP/1.1" 304 0
[18/Mar/2018 09:10:19] "GET /static/admin/css/fonts.css HTTP/1.1" 304 0
[18/Mar/2018 09:10:19] "GET /self/blog_admin/jsi18n/ HTTP/1.1" 200 7758
[18/Mar/2018 09:10:19] "GET /static/admin/img/icon-yes.svg HTTP/1.1" 304 0
[18/Mar/2018 09:10:19] "GET /static/admin/img/icon-no.svg HTTP/1.1" 304 0
[18/Mar/2018 09:10:19] "GET /static/admin/fonts/Roboto-Light-webfont.woff HTTP/1.1" 304 0
[18/Mar/2018 09:10:19] "GET /static/admin/fonts/Roboto-Bold-webfont.woff HTTP/1.1" 304 0
[18/Mar/2018 09:10:19] "GET /static/admin/fonts/Roboto-Regular-webfont.woff HTTP/1.1" 304 0
[18/Mar/2018 09:10:19] "GET /static/admin/img/tooltag-add.svg HTTP/1.1" 304 0
[18/Mar/2018 09:10:32] "GET /self/blog_admin/selfblog/post/5/change/ HTTP/1.1" 200 9386
[18/Mar/2018 09:10:32] "GET /self/blog_admin/jsi18n/ HTTP/1.1" 200 7758
[18/Mar/2018 09:10:34] "GET /self/blog_admin/selfblog/post/ HTTP/1.1" 200 12416
[18/Mar/2018 09:11:04] "GET /self/blog_admin/selfblog/ HTTP/1.1" 200 3164
[18/Mar/2018 09:11:07] "GET /self/blog_admin/selfblog/post/add/ HTTP/1.1" 200 8468
[18/Mar/2018 09:11:07] "GET /self/blog_admin/jsi18n/ HTTP/1.1" 200 7758
[18/Mar/2018 09:11:45] "POST /self/blog_admin/selfblog/post/add/ HTTP/1.1" 200 11033
[18/Mar/2018 09:11:46] "GET /self/blog_admin/jsi18n/ HTTP/1.1" 200 7758
[18/Mar/2018 09:11:53] "POST /self/blog_admin/selfblog/post/add/ HTTP/1.1" 200 10519
[18/Mar/2018 09:11:53] "GET /self/blog_admin/jsi18n/ HTTP/1.1" 200 7758
[18/Mar/2018 09:12:01] "POST /self/blog_admin/selfblog/post/add/ HTTP/1.1" 302 0
[18/Mar/2018 09:12:02] "GET /self/blog_admin/selfblog/post/add/ HTTP/1.1" 200 8695
[18/Mar/2018 09:12:02] "GET /self/blog_admin/jsi18n/ HTTP/1.1" 200 7758
[18/Mar/2018 09:12:30] "POST /self/blog_admin/selfblog/post/add/ HTTP/1.1" 302 0
[18/Mar/2018 09:12:30] "GET /self/blog_admin/selfblog/post/add/ HTTP/1.1" 200 8696
[18/Mar/2018 09:12:31] "GET /self/blog_admin/jsi18n/ HTTP/1.1" 200 7758
[18/Mar/2018 09:13:16] "GET /self/blog_admin/selfblog/category/add/?_to_field=id&_popup=1 HTTP/1.1" 200 3806
[18/Mar/2018 09:13:16] "GET /self/blog_admin/jsi18n/ HTTP/1.1" 200 7758
[18/Mar/2018 09:13:26] "POST /self/blog_admin/selfblog/category/add/?_to_field=id&_popup=1 HTTP/1.1" 200 378
[18/Mar/2018 09:13:26] "GET /static/admin/js/popup_response.js HTTP/1.1" 200 569
[18/Mar/2018 09:13:30] "GET /self/blog_admin/selfblog/tag/add/?_to_field=id&_popup=1 HTTP/1.1" 200 3390
[18/Mar/2018 09:13:30] "GET /self/blog_admin/jsi18n/ HTTP/1.1" 200 7758
[18/Mar/2018 09:13:34] "POST /self/blog_admin/selfblog/tag/add/?_to_field=id&_popup=1 HTTP/1.1" 200 370
[18/Mar/2018 09:13:39] "POST /self/blog_admin/selfblog/post/add/ HTTP/1.1" 302 0
[18/Mar/2018 09:13:39] "GET /self/blog_admin/selfblog/post/add/ HTTP/1.1" 200 8815
[18/Mar/2018 09:13:39] "GET /self/blog_admin/jsi18n/ HTTP/1.1" 200 7758
[18/Mar/2018 09:14:00] "POST /self/blog_admin/selfblog/post/add/ HTTP/1.1" 302 0
[18/Mar/2018 09:14:00] "GET /self/blog_admin/selfblog/post/ HTTP/1.1" 200 15341
[18/Mar/2018 09:14:00] "GET /self/blog_admin/jsi18n/ HTTP/1.1" 200 7758
[18/Mar/2018 09:14:02] "GET /kylin?page=1 HTTP/1.1" 200 15161
[18/Mar/2018 09:14:02] "GET /static/css/base.css HTTP/1.1" 304 0
[18/Mar/2018 09:14:02] "GET /static/img/header.jpg HTTP/1.1" 304 0
[18/Mar/2018 09:14:05] "GET /kylin HTTP/1.1" 200 15161
[18/Mar/2018 09:14:11] "GET /kylin?page=2 HTTP/1.1" 200 13074
[18/Mar/2018 09:14:17] "GET /search?q=o&username=kylin HTTP/1.1" 200 15209
[18/Mar/2018 09:14:25] "GET /search?page=2&q=o&username=kylin HTTP/1.1" 200 10417
[18/Mar/2018 09:14:31] "GET /search?page=1&q=o&username=kylin HTTP/1.1" 200 15209
[18/Mar/2018 09:14:32] "GET /kylin/category/4 HTTP/1.1" 200 13173
[18/Mar/2018 09:14:33] "GET /kylin/category/5 HTTP/1.1" 200 10283
[18/Mar/2018 09:14:33] "GET /kylin/category/6 HTTP/1.1" 200 11110
[18/Mar/2018 09:14:33] "GET /kylin/category/8 HTTP/1.1" 200 10287
[18/Mar/2018 09:14:34] "GET /kylin HTTP/1.1" 200 15161
[18/Mar/2018 09:15:02] "GET /self/blog_admin/ HTTP/1.1" 200 7596
[18/Mar/2018 09:15:06] "GET /self/blog_admin/config/sidebar/ HTTP/1.1" 200 5097
[18/Mar/2018 09:15:06] "GET /self/blog_admin/jsi18n/ HTTP/1.1" 200 7758
[18/Mar/2018 09:15:09] "GET /self/blog_admin/config/sidebar/add/ HTTP/1.1" 200 6321
[18/Mar/2018 09:15:09] "GET /self/blog_admin/jsi18n/ HTTP/1.1" 200 7758
[18/Mar/2018 09:15:24] "POST /self/blog_admin/config/sidebar/add/ HTTP/1.1" 302 0
[18/Mar/2018 09:15:24] "GET /self/blog_admin/config/sidebar/ HTTP/1.1" 200 5630
[18/Mar/2018 09:15:24] "GET /self/blog_admin/jsi18n/ HTTP/1.1" 200 7758
[18/Mar/2018 09:19:25] "GET /self/blog_admin/config/sidebar/3/change/ HTTP/1.1" 200 6579
[18/Mar/2018 09:19:25] "GET /self/blog_admin/jsi18n/ HTTP/1.1" 200 7758
Performing system checks...

System check identified no issues (0 silenced).
March 17, 2018 - 21:24:13
Django version 1.11.3, using settings 'blog.settings.product'
Starting development server at http://0:800/
Quit the server with CONTROL-C.
----------------------------------------
Exception happened during processing of request from ('117.152.240.8', 37886)
----------------------------------------
----------------------------------------
Exception happened during processing of request from ('117.152.240.8', 34116)
----------------------------------------
----------------------------------------
Exception happened during processing of request from ('117.152.240.8', 35593)
----------------------------------------
----------------------------------------
Exception happened during processing of request from ('117.152.240.8', 37626)
----------------------------------------
[18/Mar/2018 10:42:14] "GET /kylin HTTP/1.1" 200 16799
[18/Mar/2018 10:42:14] "GET /static/css/base.css HTTP/1.1" 304 0
[18/Mar/2018 10:42:14] "GET /static/img/header.jpg HTTP/1.1" 304 0
[18/Mar/2018 10:47:35] "GET /kylin HTTP/1.1" 200 16799
[18/Mar/2018 10:47:35] "GET /static/css/base.css HTTP/1.1" 304 0
[18/Mar/2018 10:47:35] "GET /static/img/header.jpg HTTP/1.1" 304 0
[18/Mar/2018 10:47:38] "GET /kylin/post/8 HTTP/1.1" 200 11835
[18/Mar/2018 10:47:42] "GET /kylin/post/8 HTTP/1.1" 200 11835
[18/Mar/2018 10:47:42] "GET /static/css/base.css HTTP/1.1" 304 0
[18/Mar/2018 10:47:42] "GET /static/img/header.jpg HTTP/1.1" 304 0
[18/Mar/2018 10:47:44] "GET /kylin HTTP/1.1" 200 16799
[18/Mar/2018 10:47:48] "GET /kylin?page=2 HTTP/1.1" 200 14715
[18/Mar/2018 10:47:51] "GET /kylin?page=1 HTTP/1.1" 200 16799
[18/Mar/2018 10:47:53] "GET /kylin/post/12 HTTP/1.1" 200 11867
[18/Mar/2018 10:47:55] "GET /kylin HTTP/1.1" 200 16799
[18/Mar/2018 10:47:59] "GET /kylin/post/10 HTTP/1.1" 200 12396
[18/Mar/2018 10:48:00] "GET /kylin HTTP/1.1" 200 16799
[18/Mar/2018 10:48:04] "GET /kylin/post/7 HTTP/1.1" 200 11970
[18/Mar/2018 10:48:07] "GET /kylin HTTP/1.1" 200 16799
[18/Mar/2018 10:48:10] "GET /kylin/post/12 HTTP/1.1" 200 11867
[18/Mar/2018 10:48:19] "GET /kylin/post/12 HTTP/1.1" 200 11867
[18/Mar/2018 10:48:22] "GET /kylin/category/9 HTTP/1.1" 200 12975
[18/Mar/2018 10:48:28] "GET /kylin/post/12 HTTP/1.1" 200 11867
[18/Mar/2018 10:48:30] "GET /kylin/category/9 HTTP/1.1" 200 12975
[18/Mar/2018 10:48:42] "GET /kylin/post/12 HTTP/1.1" 200 11867
[18/Mar/2018 10:48:42] "GET /static/css/base.css HTTP/1.1" 304 0
[18/Mar/2018 10:48:43] "GET /static/img/header.jpg HTTP/1.1" 304 0
[18/Mar/2018 10:48:44] "GET /kylin/post/12 HTTP/1.1" 200 11867
[18/Mar/2018 10:48:44] "GET /static/css/base.css HTTP/1.1" 200 128
[18/Mar/2018 10:48:44] "GET /static/img/header.jpg HTTP/1.1" 200 7014
[18/Mar/2018 10:48:48] "GET /kylin/post/12 HTTP/1.1" 200 11867
Not Found: /favicon.ico
[18/Mar/2018 10:48:49] "GET /favicon.ico HTTP/1.1" 404 3007
[18/Mar/2018 10:48:51] "GET /kylin/category/9 HTTP/1.1" 200 12975
[18/Mar/2018 10:48:54] "GET /kylin/post/11 HTTP/1.1" 200 11969
[18/Mar/2018 10:48:54] "GET /kylin/post/11 HTTP/1.1" 200 11969
[18/Mar/2018 10:48:55] "GET /kylin/category/9 HTTP/1.1" 200 12975
[18/Mar/2018 10:48:57] "GET /kylin/post/11 HTTP/1.1" 200 11969
[18/Mar/2018 10:48:59] "GET /kylin/category/9 HTTP/1.1" 200 12975
[18/Mar/2018 10:49:00] "GET /kylin/post/12 HTTP/1.1" 200 11867
[18/Mar/2018 10:49:02] "GET /kylin/category/9 HTTP/1.1" 200 12975
[18/Mar/2018 10:49:09] "GET /kylin/category/8 HTTP/1.1" 200 11935
[18/Mar/2018 10:49:11] "GET /kylin/post/6 HTTP/1.1" 200 11894
[18/Mar/2018 10:49:15] "GET /kylin/post/6 HTTP/1.1" 200 11894
[18/Mar/2018 10:49:25] "GET /kylin/post/11 HTTP/1.1" 200 11969
[18/Mar/2018 10:52:24] "GET /kk HTTP/1.1" 200 6646
Not Found: /favicon.ico
[18/Mar/2018 10:52:24] "GET /favicon.ico HTTP/1.1" 404 3007
[18/Mar/2018 10:52:34] "GET /kk/post/1 HTTP/1.1" 200 8052
[18/Mar/2018 10:52:41] "GET /kk HTTP/1.1" 200 6646
[18/Mar/2018 10:52:43] "GET /kk/post/1 HTTP/1.1" 200 8052
[18/Mar/2018 10:52:44] "GET /kk HTTP/1.1" 200 6646
[18/Mar/2018 10:52:52] "GET /kylin HTTP/1.1" 200 16799
[18/Mar/2018 10:52:55] "GET /kylin/post/8 HTTP/1.1" 200 11835
[18/Mar/2018 10:52:58] "GET /kylin HTTP/1.1" 200 16799
[18/Mar/2018 10:53:01] "GET /kylin/post/7 HTTP/1.1" 200 11970
[18/Mar/2018 10:53:04] "GET /kylin/category/7 HTTP/1.1" 200 11931
[18/Mar/2018 10:53:06] "GET /kylin/category/8 HTTP/1.1" 200 11935
[18/Mar/2018 10:53:08] "GET /kylin/post/6 HTTP/1.1" 200 11894
[18/Mar/2018 10:53:11] "GET /kylin/category/8 HTTP/1.1" 200 11935
[18/Mar/2018 10:53:13] "GET /kylin/category/4 HTTP/1.1" 200 14816
[18/Mar/2018 10:53:15] "GET /kylin/post/10 HTTP/1.1" 200 12396
[18/Mar/2018 10:53:19] "GET /kylin/category/4 HTTP/1.1" 200 14816
[18/Mar/2018 12:01:28] "GET /kylin/post/2 HTTP/1.1" 200 11891
[18/Mar/2018 12:01:28] "GET /static/css/base.css HTTP/1.1" 200 128
[18/Mar/2018 12:01:28] "GET /static/img/header.jpg HTTP/1.1" 200 7014
Not Found: /favicon.ico
[18/Mar/2018 12:01:28] "GET /favicon.ico HTTP/1.1" 404 3007
[18/Mar/2018 12:01:31] "GET /kylin/category/4 HTTP/1.1" 200 14816
[18/Mar/2018 12:01:38] "GET /kylin/post/10 HTTP/1.1" 200 12396
[18/Mar/2018 12:01:42] "GET /kylin/category/4 HTTP/1.1" 200 14816
[18/Mar/2018 12:01:45] "GET /kylin/post/9 HTTP/1.1" 200 12355
[18/Mar/2018 12:02:03] "GET /kylin/post/10 HTTP/1.1" 200 12396
[18/Mar/2018 12:02:35] "GET /kylin/category/4 HTTP/1.1" 200 14816
[18/Mar/2018 12:02:39] "GET /kylin/post/2 HTTP/1.1" 200 11891
[18/Mar/2018 17:29:24] "GET /kylin/post/2 HTTP/1.1" 200 11891
[18/Mar/2018 17:29:24] "GET /static/css/base.css HTTP/1.1" 200 128
[18/Mar/2018 17:29:25] "GET /static/img/header.jpg HTTP/1.1" 200 7014
[18/Mar/2018 17:29:29] "GET /kylin/category/4 HTTP/1.1" 200 14816
[18/Mar/2018 17:29:32] "GET /kylin HTTP/1.1" 200 16799
[18/Mar/2018 17:29:36] "GET /kylin/category/4 HTTP/1.1" 200 14816
[18/Mar/2018 17:29:53] "GET /kylin/category/4 HTTP/1.1" 200 14816
[18/Mar/2018 17:29:54] "GET /static/css/base.css HTTP/1.1" 304 0
[18/Mar/2018 17:29:54] "GET /static/img/header.jpg HTTP/1.1" 304 0
Not Found: /favicon.ico
[18/Mar/2018 17:29:55] "GET /favicon.ico HTTP/1.1" 404 3007
[18/Mar/2018 17:30:00] "GET /kylin/post/2 HTTP/1.1" 200 11891
Not Found: /favicon.ico
[18/Mar/2018 17:30:01] "GET /favicon.ico HTTP/1.1" 404 3007
[18/Mar/2018 17:30:11] "GET /kylin/category/4 HTTP/1.1" 200 14816
[18/Mar/2018 17:30:15] "GET /kylin/post/9 HTTP/1.1" 200 12355
[18/Mar/2018 17:30:32] "GET /kylin HTTP/1.1" 200 16799
[18/Mar/2018 17:33:07] "GET /kylin/category/4 HTTP/1.1" 200 14816
Internal Server Error: /self/blog_admin/selfblog/post/
Traceback (most recent call last):
  File "/home/kk/.virtualenvs/blog-env/local/lib/python2.7/site-packages/django/core/handlers/exception.py", line 41, in inner
    response = get_response(request)
  File "/home/kk/.virtualenvs/blog-env/local/lib/python2.7/site-packages/django/core/handlers/base.py", line 187, in _get_response
    response = self.process_exception_by_middleware(e, request)
  File "/home/kk/.virtualenvs/blog-env/local/lib/python2.7/site-packages/django/core/handlers/base.py", line 185, in _get_response
    response = wrapped_callback(request, *callback_args, **callback_kwargs)
  File "/home/kk/.virtualenvs/blog-env/local/lib/python2.7/site-packages/django/contrib/admin/options.py", line 551, in wrapper
    return self.admin_site.admin_view(view)(*args, **kwargs)
  File "/home/kk/.virtualenvs/blog-env/local/lib/python2.7/site-packages/django/utils/decorators.py", line 149, in _wrapped_view
    response = view_func(request, *args, **kwargs)
  File "/home/kk/.virtualenvs/blog-env/local/lib/python2.7/site-packages/django/views/decorators/cache.py", line 57, in _wrapped_view_func
    response = view_func(request, *args, **kwargs)
  File "/home/kk/.virtualenvs/blog-env/local/lib/python2.7/site-packages/django/contrib/admin/sites.py", line 224, in inner
    return view(request, *args, **kwargs)
  File "/home/kk/.virtualenvs/blog-env/local/lib/python2.7/site-packages/django/utils/decorators.py", line 67, in _wrapper
    return bound_func(*args, **kwargs)
  File "/home/kk/.virtualenvs/blog-env/local/lib/python2.7/site-packages/django/utils/decorators.py", line 149, in _wrapped_view
    response = view_func(request, *args, **kwargs)
  File "/home/kk/.virtualenvs/blog-env/local/lib/python2.7/site-packages/django/utils/decorators.py", line 63, in bound_func
    return func.__get__(self, type(self))(*args2, **kwargs2)
  File "/home/kk/.virtualenvs/blog-env/local/lib/python2.7/site-packages/django/contrib/admin/options.py", line 1662, in changelist_view
    selection_note=_('0 of %(cnt)s selected') % {'cnt': len(cl.result_list)},
  File "/home/kk/.virtualenvs/blog-env/local/lib/python2.7/site-packages/django/db/models/query.py", line 232, in __len__
    self._fetch_all()
  File "/home/kk/.virtualenvs/blog-env/local/lib/python2.7/site-packages/django/db/models/query.py", line 1118, in _fetch_all
    self._result_cache = list(self._iterable_class(self))
  File "/home/kk/.virtualenvs/blog-env/local/lib/python2.7/site-packages/django/db/models/query.py", line 53, in __iter__
    results = compiler.execute_sql(chunked_fetch=self.chunked_fetch)
  File "/home/kk/.virtualenvs/blog-env/local/lib/python2.7/site-packages/django/db/models/sql/compiler.py", line 886, in execute_sql
    raise original_exception
OperationalError: (1153, "Got a packet bigger than 'max_allowed_packet' bytes")
[18/Mar/2018 17:38:04] "GET /static/css/base.css HTTP/1.1" 304 0
[18/Mar/2018 17:38:04] "GET /self/blog_admin/selfblog/post/ HTTP/1.1" 500 120343
Not Found: /favicon.ico
[18/Mar/2018 17:38:05] "GET /favicon.ico HTTP/1.1" 404 3007
Internal Server Error: /self/blog_admin/selfblog/post/
Traceback (most recent call last):
  File "/home/kk/.virtualenvs/blog-env/local/lib/python2.7/site-packages/django/core/handlers/exception.py", line 41, in inner
    response = get_response(request)
  File "/home/kk/.virtualenvs/blog-env/local/lib/python2.7/site-packages/django/core/handlers/base.py", line 187, in _get_response
    response = self.process_exception_by_middleware(e, request)
  File "/home/kk/.virtualenvs/blog-env/local/lib/python2.7/site-packages/django/core/handlers/base.py", line 185, in _get_response
    response = wrapped_callback(request, *callback_args, **callback_kwargs)
  File "/home/kk/.virtualenvs/blog-env/local/lib/python2.7/site-packages/django/contrib/admin/options.py", line 551, in wrapper
    return self.admin_site.admin_view(view)(*args, **kwargs)
  File "/home/kk/.virtualenvs/blog-env/local/lib/python2.7/site-packages/django/utils/decorators.py", line 149, in _wrapped_view
    response = view_func(request, *args, **kwargs)
  File "/home/kk/.virtualenvs/blog-env/local/lib/python2.7/site-packages/django/views/decorators/cache.py", line 57, in _wrapped_view_func
    response = view_func(request, *args, **kwargs)
  File "/home/kk/.virtualenvs/blog-env/local/lib/python2.7/site-packages/django/contrib/admin/sites.py", line 224, in inner
    return view(request, *args, **kwargs)
  File "/home/kk/.virtualenvs/blog-env/local/lib/python2.7/site-packages/django/utils/decorators.py", line 67, in _wrapper
    return bound_func(*args, **kwargs)
  File "/home/kk/.virtualenvs/blog-env/local/lib/python2.7/site-packages/django/utils/decorators.py", line 149, in _wrapped_view
    response = view_func(request, *args, **kwargs)
  File "/home/kk/.virtualenvs/blog-env/local/lib/python2.7/site-packages/django/utils/decorators.py", line 63, in bound_func
    return func.__get__(self, type(self))(*args2, **kwargs2)
  File "/home/kk/.virtualenvs/blog-env/local/lib/python2.7/site-packages/django/contrib/admin/options.py", line 1662, in changelist_view
    selection_note=_('0 of %(cnt)s selected') % {'cnt': len(cl.result_list)},
  File "/home/kk/.virtualenvs/blog-env/local/lib/python2.7/site-packages/django/db/models/query.py", line 232, in __len__
    self._fetch_all()
  File "/home/kk/.virtualenvs/blog-env/local/lib/python2.7/site-packages/django/db/models/query.py", line 1118, in _fetch_all
    self._result_cache = list(self._iterable_class(self))
  File "/home/kk/.virtualenvs/blog-env/local/lib/python2.7/site-packages/django/db/models/query.py", line 53, in __iter__
    results = compiler.execute_sql(chunked_fetch=self.chunked_fetch)
  File "/home/kk/.virtualenvs/blog-env/local/lib/python2.7/site-packages/django/db/models/sql/compiler.py", line 886, in execute_sql
    raise original_exception
OperationalError: (1153, "Got a packet bigger than 'max_allowed_packet' bytes")
[18/Mar/2018 17:38:08] "GET /self/blog_admin/selfblog/post/ HTTP/1.1" 500 120478
Internal Server Error: /self/blog_admin/selfblog/post/
Traceback (most recent call last):
  File "/home/kk/.virtualenvs/blog-env/local/lib/python2.7/site-packages/django/core/handlers/exception.py", line 41, in inner
    response = get_response(request)
  File "/home/kk/.virtualenvs/blog-env/local/lib/python2.7/site-packages/django/core/handlers/base.py", line 187, in _get_response
    response = self.process_exception_by_middleware(e, request)
  File "/home/kk/.virtualenvs/blog-env/local/lib/python2.7/site-packages/django/core/handlers/base.py", line 185, in _get_response
    response = wrapped_callback(request, *callback_args, **callback_kwargs)
  File "/home/kk/.virtualenvs/blog-env/local/lib/python2.7/site-packages/django/contrib/admin/options.py", line 551, in wrapper
    return self.admin_site.admin_view(view)(*args, **kwargs)
  File "/home/kk/.virtualenvs/blog-env/local/lib/python2.7/site-packages/django/utils/decorators.py", line 149, in _wrapped_view
    response = view_func(request, *args, **kwargs)
  File "/home/kk/.virtualenvs/blog-env/local/lib/python2.7/site-packages/django/views/decorators/cache.py", line 57, in _wrapped_view_func
    response = view_func(request, *args, **kwargs)
  File "/home/kk/.virtualenvs/blog-env/local/lib/python2.7/site-packages/django/contrib/admin/sites.py", line 224, in inner
    return view(request, *args, **kwargs)
  File "/home/kk/.virtualenvs/blog-env/local/lib/python2.7/site-packages/django/utils/decorators.py", line 67, in _wrapper
    return bound_func(*args, **kwargs)
  File "/home/kk/.virtualenvs/blog-env/local/lib/python2.7/site-packages/django/utils/decorators.py", line 149, in _wrapped_view
    response = view_func(request, *args, **kwargs)
  File "/home/kk/.virtualenvs/blog-env/local/lib/python2.7/site-packages/django/utils/decorators.py", line 63, in bound_func
    return func.__get__(self, type(self))(*args2, **kwargs2)
  File "/home/kk/.virtualenvs/blog-env/local/lib/python2.7/site-packages/django/contrib/admin/options.py", line 1662, in changelist_view
    selection_note=_('0 of %(cnt)s selected') % {'cnt': len(cl.result_list)},
  File "/home/kk/.virtualenvs/blog-env/local/lib/python2.7/site-packages/django/db/models/query.py", line 232, in __len__
    self._fetch_all()
  File "/home/kk/.virtualenvs/blog-env/local/lib/python2.7/site-packages/django/db/models/query.py", line 1118, in _fetch_all
    self._result_cache = list(self._iterable_class(self))
  File "/home/kk/.virtualenvs/blog-env/local/lib/python2.7/site-packages/django/db/models/query.py", line 53, in __iter__
    results = compiler.execute_sql(chunked_fetch=self.chunked_fetch)
  File "/home/kk/.virtualenvs/blog-env/local/lib/python2.7/site-packages/django/db/models/sql/compiler.py", line 886, in execute_sql
    raise original_exception
OperationalError: (1153, "Got a packet bigger than 'max_allowed_packet' bytes")
[18/Mar/2018 17:38:11] "GET /self/blog_admin/selfblog/post/ HTTP/1.1" 500 120478
[18/Mar/2018 17:38:20] "GET /self/blog_admin/ HTTP/1.1" 200 7715
[18/Mar/2018 17:38:20] "GET /static/admin/css/base.css HTTP/1.1" 304 0
[18/Mar/2018 17:38:20] "GET /static/admin/css/dashboard.css HTTP/1.1" 304 0
[18/Mar/2018 17:38:20] "GET /static/admin/css/fonts.css HTTP/1.1" 304 0
[18/Mar/2018 17:38:20] "GET /static/admin/fonts/Roboto-Regular-webfont.woff HTTP/1.1" 304 0
[18/Mar/2018 17:38:20] "GET /static/admin/fonts/Roboto-Light-webfont.woff HTTP/1.1" 304 0
[18/Mar/2018 17:38:20] "GET /static/admin/fonts/Roboto-Bold-webfont.woff HTTP/1.1" 304 0
[18/Mar/2018 17:38:20] "GET /static/admin/img/icon-addlink.svg HTTP/1.1" 304 0
[18/Mar/2018 17:38:20] "GET /static/admin/img/icon-changelink.svg HTTP/1.1" 304 0
[18/Mar/2018 17:38:23] "GET /self/blog_admin/selfblog/post/add/ HTTP/1.1" 200 8148
[18/Mar/2018 17:38:23] "GET /static/admin/css/forms.css HTTP/1.1" 304 0
[18/Mar/2018 17:38:23] "GET /self/blog_admin/jsi18n/ HTTP/1.1" 200 7758
[18/Mar/2018 17:38:23] "GET /static/admin/js/vendor/jquery/jquery.js HTTP/1.1" 304 0
[18/Mar/2018 17:38:23] "GET /static/admin/js/jquery.init.js HTTP/1.1" 304 0
[18/Mar/2018 17:38:23] "GET /static/admin/js/core.js HTTP/1.1" 304 0
[18/Mar/2018 17:38:23] "GET /static/admin/js/admin/RelatedObjectLookups.js HTTP/1.1" 304 0
[18/Mar/2018 17:38:23] "GET /static/admin/css/widgets.css HTTP/1.1" 304 0
[18/Mar/2018 17:38:23] "GET /static/admin/js/actions.js HTTP/1.1" 304 0
[18/Mar/2018 17:38:23] "GET /static/admin/js/prepopulate.js HTTP/1.1" 304 0
[18/Mar/2018 17:38:23] "GET /static/admin/js/urlify.js HTTP/1.1" 304 0
[18/Mar/2018 17:38:23] "GET /static/admin/js/vendor/xregexp/xregexp.js HTTP/1.1" 304 0
[18/Mar/2018 17:38:23] "GET /static/admin/js/change_form.js HTTP/1.1" 304 0
[18/Mar/2018 17:38:23] "GET /static/admin/js/prepopulate_init.js HTTP/1.1" 304 0
[18/Mar/2018 17:38:25] "GET /self/blog_admin/ HTTP/1.1" 200 7715
Internal Server Error: /self/blog_admin/selfblog/post/
Traceback (most recent call last):
  File "/home/kk/.virtualenvs/blog-env/local/lib/python2.7/site-packages/django/core/handlers/exception.py", line 41, in inner
    response = get_response(request)
  File "/home/kk/.virtualenvs/blog-env/local/lib/python2.7/site-packages/django/core/handlers/base.py", line 187, in _get_response
    response = self.process_exception_by_middleware(e, request)
  File "/home/kk/.virtualenvs/blog-env/local/lib/python2.7/site-packages/django/core/handlers/base.py", line 185, in _get_response
    response = wrapped_callback(request, *callback_args, **callback_kwargs)
  File "/home/kk/.virtualenvs/blog-env/local/lib/python2.7/site-packages/django/contrib/admin/options.py", line 551, in wrapper
    return self.admin_site.admin_view(view)(*args, **kwargs)
  File "/home/kk/.virtualenvs/blog-env/local/lib/python2.7/site-packages/django/utils/decorators.py", line 149, in _wrapped_view
    response = view_func(request, *args, **kwargs)
  File "/home/kk/.virtualenvs/blog-env/local/lib/python2.7/site-packages/django/views/decorators/cache.py", line 57, in _wrapped_view_func
    response = view_func(request, *args, **kwargs)
  File "/home/kk/.virtualenvs/blog-env/local/lib/python2.7/site-packages/django/contrib/admin/sites.py", line 224, in inner
    return view(request, *args, **kwargs)
  File "/home/kk/.virtualenvs/blog-env/local/lib/python2.7/site-packages/django/utils/decorators.py", line 67, in _wrapper
    return bound_func(*args, **kwargs)
  File "/home/kk/.virtualenvs/blog-env/local/lib/python2.7/site-packages/django/utils/decorators.py", line 149, in _wrapped_view
    response = view_func(request, *args, **kwargs)
  File "/home/kk/.virtualenvs/blog-env/local/lib/python2.7/site-packages/django/utils/decorators.py", line 63, in bound_func
    return func.__get__(self, type(self))(*args2, **kwargs2)
  File "/home/kk/.virtualenvs/blog-env/local/lib/python2.7/site-packages/django/contrib/admin/options.py", line 1662, in changelist_view
    selection_note=_('0 of %(cnt)s selected') % {'cnt': len(cl.result_list)},
  File "/home/kk/.virtualenvs/blog-env/local/lib/python2.7/site-packages/django/db/models/query.py", line 232, in __len__
    self._fetch_all()
  File "/home/kk/.virtualenvs/blog-env/local/lib/python2.7/site-packages/django/db/models/query.py", line 1118, in _fetch_all
    self._result_cache = list(self._iterable_class(self))
  File "/home/kk/.virtualenvs/blog-env/local/lib/python2.7/site-packages/django/db/models/query.py", line 53, in __iter__
    results = compiler.execute_sql(chunked_fetch=self.chunked_fetch)
  File "/home/kk/.virtualenvs/blog-env/local/lib/python2.7/site-packages/django/db/models/sql/compiler.py", line 886, in execute_sql
    raise original_exception
OperationalError: (1153, "Got a packet bigger than 'max_allowed_packet' bytes")
[18/Mar/2018 17:38:26] "GET /self/blog_admin/selfblog/post/ HTTP/1.1" 500 120334
Internal Server Error: /self/blog_admin/selfblog/post/
Traceback (most recent call last):
  File "/home/kk/.virtualenvs/blog-env/local/lib/python2.7/site-packages/django/core/handlers/exception.py", line 41, in inner
    response = get_response(request)
  File "/home/kk/.virtualenvs/blog-env/local/lib/python2.7/site-packages/django/core/handlers/base.py", line 187, in _get_response
    response = self.process_exception_by_middleware(e, request)
  File "/home/kk/.virtualenvs/blog-env/local/lib/python2.7/site-packages/django/core/handlers/base.py", line 185, in _get_response
    response = wrapped_callback(request, *callback_args, **callback_kwargs)
  File "/home/kk/.virtualenvs/blog-env/local/lib/python2.7/site-packages/django/contrib/admin/options.py", line 551, in wrapper
    return self.admin_site.admin_view(view)(*args, **kwargs)
  File "/home/kk/.virtualenvs/blog-env/local/lib/python2.7/site-packages/django/utils/decorators.py", line 149, in _wrapped_view
    response = view_func(request, *args, **kwargs)
  File "/home/kk/.virtualenvs/blog-env/local/lib/python2.7/site-packages/django/views/decorators/cache.py", line 57, in _wrapped_view_func
    response = view_func(request, *args, **kwargs)
  File "/home/kk/.virtualenvs/blog-env/local/lib/python2.7/site-packages/django/contrib/admin/sites.py", line 224, in inner
    return view(request, *args, **kwargs)
  File "/home/kk/.virtualenvs/blog-env/local/lib/python2.7/site-packages/django/utils/decorators.py", line 67, in _wrapper
    return bound_func(*args, **kwargs)
  File "/home/kk/.virtualenvs/blog-env/local/lib/python2.7/site-packages/django/utils/decorators.py", line 149, in _wrapped_view
    response = view_func(request, *args, **kwargs)
  File "/home/kk/.virtualenvs/blog-env/local/lib/python2.7/site-packages/django/utils/decorators.py", line 63, in bound_func
    return func.__get__(self, type(self))(*args2, **kwargs2)
  File "/home/kk/.virtualenvs/blog-env/local/lib/python2.7/site-packages/django/contrib/admin/options.py", line 1662, in changelist_view
    selection_note=_('0 of %(cnt)s selected') % {'cnt': len(cl.result_list)},
  File "/home/kk/.virtualenvs/blog-env/local/lib/python2.7/site-packages/django/db/models/query.py", line 232, in __len__
    self._fetch_all()
  File "/home/kk/.virtualenvs/blog-env/local/lib/python2.7/site-packages/django/db/models/query.py", line 1118, in _fetch_all
    self._result_cache = list(self._iterable_class(self))
  File "/home/kk/.virtualenvs/blog-env/local/lib/python2.7/site-packages/django/db/models/query.py", line 53, in __iter__
    results = compiler.execute_sql(chunked_fetch=self.chunked_fetch)
  File "/home/kk/.virtualenvs/blog-env/local/lib/python2.7/site-packages/django/db/models/sql/compiler.py", line 886, in execute_sql
    raise original_exception
OperationalError: (1153, "Got a packet bigger than 'max_allowed_packet' bytes")
[18/Mar/2018 17:44:03] "GET /self/blog_admin/selfblog/post/ HTTP/1.1" 500 120469
Internal Server Error: /self/blog_admin/selfblog/post/
Traceback (most recent call last):
  File "/home/kk/.virtualenvs/blog-env/local/lib/python2.7/site-packages/django/core/handlers/exception.py", line 41, in inner
    response = get_response(request)
  File "/home/kk/.virtualenvs/blog-env/local/lib/python2.7/site-packages/django/core/handlers/base.py", line 187, in _get_response
    response = self.process_exception_by_middleware(e, request)
  File "/home/kk/.virtualenvs/blog-env/local/lib/python2.7/site-packages/django/core/handlers/base.py", line 185, in _get_response
    response = wrapped_callback(request, *callback_args, **callback_kwargs)
  File "/home/kk/.virtualenvs/blog-env/local/lib/python2.7/site-packages/django/contrib/admin/options.py", line 551, in wrapper
    return self.admin_site.admin_view(view)(*args, **kwargs)
  File "/home/kk/.virtualenvs/blog-env/local/lib/python2.7/site-packages/django/utils/decorators.py", line 149, in _wrapped_view
    response = view_func(request, *args, **kwargs)
  File "/home/kk/.virtualenvs/blog-env/local/lib/python2.7/site-packages/django/views/decorators/cache.py", line 57, in _wrapped_view_func
    response = view_func(request, *args, **kwargs)
  File "/home/kk/.virtualenvs/blog-env/local/lib/python2.7/site-packages/django/contrib/admin/sites.py", line 224, in inner
    return view(request, *args, **kwargs)
  File "/home/kk/.virtualenvs/blog-env/local/lib/python2.7/site-packages/django/utils/decorators.py", line 67, in _wrapper
    return bound_func(*args, **kwargs)
  File "/home/kk/.virtualenvs/blog-env/local/lib/python2.7/site-packages/django/utils/decorators.py", line 149, in _wrapped_view
    response = view_func(request, *args, **kwargs)
  File "/home/kk/.virtualenvs/blog-env/local/lib/python2.7/site-packages/django/utils/decorators.py", line 63, in bound_func
    return func.__get__(self, type(self))(*args2, **kwargs2)
  File "/home/kk/.virtualenvs/blog-env/local/lib/python2.7/site-packages/django/contrib/admin/options.py", line 1662, in changelist_view
    selection_note=_('0 of %(cnt)s selected') % {'cnt': len(cl.result_list)},
  File "/home/kk/.virtualenvs/blog-env/local/lib/python2.7/site-packages/django/db/models/query.py", line 232, in __len__
    self._fetch_all()
  File "/home/kk/.virtualenvs/blog-env/local/lib/python2.7/site-packages/django/db/models/query.py", line 1118, in _fetch_all
    self._result_cache = list(self._iterable_class(self))
  File "/home/kk/.virtualenvs/blog-env/local/lib/python2.7/site-packages/django/db/models/query.py", line 53, in __iter__
    results = compiler.execute_sql(chunked_fetch=self.chunked_fetch)
  File "/home/kk/.virtualenvs/blog-env/local/lib/python2.7/site-packages/django/db/models/sql/compiler.py", line 886, in execute_sql
    raise original_exception
OperationalError: (1153, "Got a packet bigger than 'max_allowed_packet' bytes")
[18/Mar/2018 17:44:05] "GET /self/blog_admin/selfblog/post/ HTTP/1.1" 500 120469
Internal Server Error: /self/blog_admin/selfblog/post/
Traceback (most recent call last):
  File "/home/kk/.virtualenvs/blog-env/local/lib/python2.7/site-packages/django/core/handlers/exception.py", line 41, in inner
    response = get_response(request)
  File "/home/kk/.virtualenvs/blog-env/local/lib/python2.7/site-packages/django/core/handlers/base.py", line 187, in _get_response
    response = self.process_exception_by_middleware(e, request)
  File "/home/kk/.virtualenvs/blog-env/local/lib/python2.7/site-packages/django/core/handlers/base.py", line 185, in _get_response
    response = wrapped_callback(request, *callback_args, **callback_kwargs)
  File "/home/kk/.virtualenvs/blog-env/local/lib/python2.7/site-packages/django/contrib/admin/options.py", line 551, in wrapper
    return self.admin_site.admin_view(view)(*args, **kwargs)
  File "/home/kk/.virtualenvs/blog-env/local/lib/python2.7/site-packages/django/utils/decorators.py", line 149, in _wrapped_view
    response = view_func(request, *args, **kwargs)
  File "/home/kk/.virtualenvs/blog-env/local/lib/python2.7/site-packages/django/views/decorators/cache.py", line 57, in _wrapped_view_func
    response = view_func(request, *args, **kwargs)
  File "/home/kk/.virtualenvs/blog-env/local/lib/python2.7/site-packages/django/contrib/admin/sites.py", line 224, in inner
    return view(request, *args, **kwargs)
  File "/home/kk/.virtualenvs/blog-env/local/lib/python2.7/site-packages/django/utils/decorators.py", line 67, in _wrapper
    return bound_func(*args, **kwargs)
  File "/home/kk/.virtualenvs/blog-env/local/lib/python2.7/site-packages/django/utils/decorators.py", line 149, in _wrapped_view
    response = view_func(request, *args, **kwargs)
  File "/home/kk/.virtualenvs/blog-env/local/lib/python2.7/site-packages/django/utils/decorators.py", line 63, in bound_func
    return func.__get__(self, type(self))(*args2, **kwargs2)
  File "/home/kk/.virtualenvs/blog-env/local/lib/python2.7/site-packages/django/contrib/admin/options.py", line 1662, in changelist_view
    selection_note=_('0 of %(cnt)s selected') % {'cnt': len(cl.result_list)},
  File "/home/kk/.virtualenvs/blog-env/local/lib/python2.7/site-packages/django/db/models/query.py", line 232, in __len__
    self._fetch_all()
  File "/home/kk/.virtualenvs/blog-env/local/lib/python2.7/site-packages/django/db/models/query.py", line 1118, in _fetch_all
    self._result_cache = list(self._iterable_class(self))
  File "/home/kk/.virtualenvs/blog-env/local/lib/python2.7/site-packages/django/db/models/query.py", line 53, in __iter__
    results = compiler.execute_sql(chunked_fetch=self.chunked_fetch)
  File "/home/kk/.virtualenvs/blog-env/local/lib/python2.7/site-packages/django/db/models/sql/compiler.py", line 886, in execute_sql
    raise original_exception
OperationalError: (1153, "Got a packet bigger than 'max_allowed_packet' bytes")
[18/Mar/2018 17:44:06] "GET /self/blog_admin/selfblog/post/ HTTP/1.1" 500 120469
[18/Mar/2018 17:46:32] "GET /self/blog_admin/ HTTP/1.1" 200 7715
[18/Mar/2018 17:46:34] "GET /self/blog_admin/selfblog/post/ HTTP/1.1" 200 16430
[18/Mar/2018 17:46:34] "GET /static/admin/css/changelists.css HTTP/1.1" 304 0
[18/Mar/2018 17:46:34] "GET /self/blog_admin/jsi18n/ HTTP/1.1" 200 7758
[18/Mar/2018 17:46:34] "GET /static/admin/img/icon-no.svg HTTP/1.1" 304 0
[18/Mar/2018 17:46:34] "GET /static/admin/img/icon-yes.svg HTTP/1.1" 304 0
[18/Mar/2018 17:46:34] "GET /static/admin/img/tooltag-add.svg HTTP/1.1" 304 0
[18/Mar/2018 17:46:35] "GET /self/blog_admin/ HTTP/1.1" 200 7715
[18/Mar/2018 17:46:37] "GET /self/blog_admin/selfblog/post/add/ HTTP/1.1" 200 8148
[18/Mar/2018 17:46:37] "GET /self/blog_admin/jsi18n/ HTTP/1.1" 200 7758
[18/Mar/2018 17:46:38] "GET /self/blog_admin/ HTTP/1.1" 200 7715
[18/Mar/2018 17:46:39] "GET /self/blog_admin/selfblog/post/ HTTP/1.1" 200 16430
[18/Mar/2018 17:46:39] "GET /self/blog_admin/jsi18n/ HTTP/1.1" 200 7758
[18/Mar/2018 17:46:39] "GET /self/blog_admin/ HTTP/1.1" 200 7715
[18/Mar/2018 17:46:40] "GET /self/blog_admin/selfblog/category/ HTTP/1.1" 200 8858
[18/Mar/2018 17:46:40] "GET /self/blog_admin/jsi18n/ HTTP/1.1" 200 7758
[18/Mar/2018 17:46:41] "GET /self/blog_admin/ HTTP/1.1" 200 7715
[18/Mar/2018 17:46:42] "GET /self/blog_admin/selfblog/tag/ HTTP/1.1" 200 8981
[18/Mar/2018 17:46:42] "GET /self/blog_admin/jsi18n/ HTTP/1.1" 200 7758
[18/Mar/2018 17:46:49] "GET /self/blog_admin/ HTTP/1.1" 200 7715
[18/Mar/2018 17:46:51] "GET /self/blog_admin/selfblog/tag/ HTTP/1.1" 200 8981
[18/Mar/2018 17:46:51] "GET /self/blog_admin/jsi18n/ HTTP/1.1" 200 7758
[18/Mar/2018 17:46:56] "GET /self/blog_admin/ HTTP/1.1" 200 7715
[18/Mar/2018 17:46:57] "GET /self/blog_admin/selfblog/post/ HTTP/1.1" 200 16430
[18/Mar/2018 17:46:58] "GET /self/blog_admin/jsi18n/ HTTP/1.1" 200 7758
[18/Mar/2018 17:47:00] "GET /self/blog_admin/ HTTP/1.1" 200 7715
[18/Mar/2018 17:47:02] "GET /self/blog_admin/selfblog/category/ HTTP/1.1" 200 8858
[18/Mar/2018 17:47:02] "GET /self/blog_admin/jsi18n/ HTTP/1.1" 200 7758
[18/Mar/2018 17:47:04] "GET /self/blog_admin/ HTTP/1.1" 200 7715
[18/Mar/2018 17:47:07] "GET /self/blog_admin/logout/ HTTP/1.1" 200 1030
[18/Mar/2018 17:47:08] "GET /self/blog_admin/ HTTP/1.1" 302 0
[18/Mar/2018 17:47:08] "GET /self/blog_admin/login/?next=/self/blog_admin/ HTTP/1.1" 200 1681
[18/Mar/2018 17:47:08] "GET /static/admin/css/login.css HTTP/1.1" 304 0
[18/Mar/2018 17:47:12] "POST /self/blog_admin/login/?next=/self/blog_admin/ HTTP/1.1" 302 0
[18/Mar/2018 17:47:12] "GET /self/blog_admin/ HTTP/1.1" 200 7611
[18/Mar/2018 17:47:15] "GET /self/blog_admin/selfblog/post/ HTTP/1.1" 200 15166
[18/Mar/2018 17:47:15] "GET /self/blog_admin/jsi18n/ HTTP/1.1" 200 7758
[18/Mar/2018 17:47:17] "GET /self/blog_admin/ HTTP/1.1" 200 7611
[18/Mar/2018 17:47:18] "GET /self/blog_admin/selfblog/tag/ HTTP/1.1" 200 7364
[18/Mar/2018 17:47:18] "GET /self/blog_admin/jsi18n/ HTTP/1.1" 200 7758
[18/Mar/2018 17:47:21] "GET /self/blog_admin/ HTTP/1.1" 200 7611
[18/Mar/2018 17:47:22] "GET /self/blog_admin/selfblog/category/ HTTP/1.1" 200 7090
[18/Mar/2018 17:47:22] "GET /self/blog_admin/jsi18n/ HTTP/1.1" 200 7758
[18/Mar/2018 17:47:25] "GET /self/blog_admin/ HTTP/1.1" 200 7611
[18/Mar/2018 17:47:43] "GET /kk HTTP/1.1" 200 6646
[18/Mar/2018 17:47:48] "GET /kylin HTTP/1.1" 200 16799
[18/Mar/2018 17:47:48] "GET /static/img/header.jpg HTTP/1.1" 200 7014
[18/Mar/2018 17:47:54] "GET /kylin/post/8 HTTP/1.1" 200 11835
[18/Mar/2018 17:47:56] "GET /kylin HTTP/1.1" 200 16799
[18/Mar/2018 17:47:59] "GET /kylin/post/12 HTTP/1.1" 200 11867
[18/Mar/2018 17:48:01] "GET /kylin HTTP/1.1" 200 16799
[18/Mar/2018 17:48:03] "GET /kylin/category/5 HTTP/1.1" 200 11931
[18/Mar/2018 17:48:04] "GET /kylin/post/4 HTTP/1.1" 200 11895
[18/Mar/2018 17:48:07] "GET /kylin/category/5 HTTP/1.1" 200 11931
[18/Mar/2018 17:48:09] "GET /kylin/category/8 HTTP/1.1" 200 11935
[18/Mar/2018 17:48:10] "GET /kylin/post/6 HTTP/1.1" 200 11894
[18/Mar/2018 17:48:12] "GET /kylin/category/8 HTTP/1.1" 200 11935
[18/Mar/2018 17:48:16] "GET /kylin/post/9 HTTP/1.1" 200 12355
[18/Mar/2018 17:48:20] "GET /kylin/category/4 HTTP/1.1" 200 14816
[18/Mar/2018 17:48:25] "GET /kylin HTTP/1.1" 200 16799
[18/Mar/2018 17:48:41] "GET /kylin/category/6 HTTP/1.1" 200 12756
[18/Mar/2018 17:48:42] "GET /kylin/category/5 HTTP/1.1" 200 11931
[18/Mar/2018 17:48:42] "GET /kylin/category/4 HTTP/1.1" 200 14816
[18/Mar/2018 17:48:42] "GET /kylin HTTP/1.1" 200 16799
[18/Mar/2018 17:48:43] "GET /kylin/category/8 HTTP/1.1" 200 11935
[18/Mar/2018 17:48:43] "GET /kylin/category/6 HTTP/1.1" 200 12756
[18/Mar/2018 19:24:16] "GET /kylin/post/2 HTTP/1.1" 200 11891
[18/Mar/2018 19:26:02] "GET /kylin/post/3 HTTP/1.1" 200 11907
[18/Mar/2018 19:26:04] "GET /kylin/post/4 HTTP/1.1" 200 11895
[18/Mar/2018 19:26:06] "GET /kylin/post/5 HTTP/1.1" 200 11958
[18/Mar/2018 19:26:07] "GET /kylin/post/6 HTTP/1.1" 200 11894
[18/Mar/2018 19:26:08] "GET /kylin/post/7 HTTP/1.1" 200 11970
[18/Mar/2018 20:38:13] "GET /kk/post/1 HTTP/1.1" 200 8053
Not Found: /favicon.ico
[18/Mar/2018 20:38:14] "GET /favicon.ico HTTP/1.1" 404 3007
[18/Mar/2018 20:38:16] "GET /kk HTTP/1.1" 200 6647
[18/Mar/2018 20:38:16] "GET /kk/category/1 HTTP/1.1" 200 6656
[18/Mar/2018 20:38:17] "GET /kk/category/2 HTTP/1.1" 200 6038
[18/Mar/2018 20:38:19] "GET /kk HTTP/1.1" 200 6647
[19/Mar/2018 06:42:17] "GET /kylin/post/2 HTTP/1.1" 200 11891
[19/Mar/2018 06:42:18] "GET /static/css/base.css HTTP/1.1" 304 0
[19/Mar/2018 06:42:18] "GET /static/img/header.jpg HTTP/1.1" 304 0
[19/Mar/2018 06:42:23] "GET /kylin HTTP/1.1" 200 16799
Not Found: /jsrpc.php
[19/Mar/2018 22:31:35] "GET /jsrpc.php?sid=0bcd4ade648214dc&type=9&method=screen.get&timestamp=1471403798083&mode=2&screenid=&groupid=&hostid=0&pageFile=history.php&profileIdx=web.item.graph&profileIdx2=999'&updateProfile=true&screenitemid=.=3600&stime=20160817050632&resourcetype=17&itemids%5B23297%5D=23297&action=showlatest&filter=&filter_task=&mark_color=1 HTTP/1.1" 404 3403
Not Found: /
[19/Mar/2018 22:31:35] "GET / HTTP/1.1" 404 2956
[19/Mar/2018 22:31:42] code 400, message Bad request syntax ('\x12\x01\x00\x00gE\x8bk\x00\x00\x00\x00\xd4\x07\x00\x00\x00\x00\x00\x00admin.$cmd\x00\x00\x00\x00\x00\xff\xff\xff\xff\xeb\x00\x00\x00\x10ismaster\x00\x01\x00\x00\x00\x03client\x00\xd0\x00\x00\x00\x03driver\x00*\x00\x00\x00\x02name\x00\x08\x00\x00\x00PyMongo\x00\x02version\x00\x06\x00\x00\x003.5.1\x00\x00\x03os\x00p\x00\x00\x00\x02type\x00\x06\x00\x00\x00Linux\x00\x02name\x00\x11\x00\x00\x00CentOS 6.4 Final\x00\x02architecture\x00\x07\x00\x00\x00x86_64\x00\x02version\x00\x1a\x00\x00\x002.6.32-358.2.1.el6.x86_64\x00\x00\x02platform\x00\x17\x00\x00\x00CPython 2.7.11.final.0\x00\x00\x00')
Traceback (most recent call last):
  File "/usr/lib/python2.7/logging/__init__.py", line 861, in emit
    msg = self.format(record)
  File "/usr/lib/python2.7/logging/__init__.py", line 734, in format
    return fmt.format(record)
  File "/home/kk/.virtualenvs/blog-env/local/lib/python2.7/site-packages/django/utils/log.py", line 192, in format
    return super(ServerFormatter, self).format(record)
  File "/usr/lib/python2.7/logging/__init__.py", line 476, in format
    raise e
UnicodeDecodeError: 'utf8' codec can't decode byte 0x8b in position 7: invalid start byte
Logged from file basehttp.py, line 124
Not Found: /
[19/Mar/2018 22:31:42] "POST / HTTP/1.1" 404 2957
[19/Mar/2018 22:31:43] code 400, message Bad request syntax ('INFO')
[19/Mar/2018 22:31:43] "INFO" 400 -
Not Found: /
[19/Mar/2018 22:31:43] "GET / HTTP/1.1" 404 2960
[19/Mar/2018 22:31:44] code 400, message Bad request syntax ('stats')
[19/Mar/2018 22:31:44] "stats" 400 -
[19/Mar/2018 22:31:50] code 400, message Bad request syntax ('envi')
[19/Mar/2018 22:31:50] "envi" 400 -
[19/Mar/2018 22:31:50] code 400, message Bad request syntax ('SSH-2.0-paramiko_2.4.0')
[19/Mar/2018 22:31:50] "SSH-2.0-paramiko_2.4.0" 400 -
[19/Mar/2018 22:31:50] code 400, message Bad request syntax ('SSH-2.0-paramiko_2.4.0')
[19/Mar/2018 22:31:50] "SSH-2.0-paramiko_2.4.0" 400 -
[19/Mar/2018 22:31:50] code 400, message Bad request syntax ('SSH-2.0-paramiko_2.4.0')
[19/Mar/2018 22:31:50] "SSH-2.0-paramiko_2.4.0" 400 -
[19/Mar/2018 22:31:50] code 400, message Bad request syntax ('SSH-2.0-paramiko_2.4.0')
[19/Mar/2018 22:31:50] "SSH-2.0-paramiko_2.4.0" 400 -
[19/Mar/2018 22:31:50] code 400, message Bad request syntax ('SSH-2.0-paramiko_2.4.0')
[19/Mar/2018 22:31:50] "SSH-2.0-paramiko_2.4.0" 400 -
Not Found: /.svn/all-wcprops
[19/Mar/2018 22:31:57] "GET /.svn/all-wcprops HTTP/1.1" 404 3022
Not Found: /.git/config
[19/Mar/2018 22:31:57] "GET /.git/config HTTP/1.1" 404 3007
Not Found: /script
[19/Mar/2018 22:31:57] "GET /script HTTP/1.1" 404 1696
Not Found: /invoker/JMXInvokerServlet
[19/Mar/2018 22:31:57] "GET /invoker/JMXInvokerServlet HTTP/1.1" 404 3049
Not Found: /phpinfo.php
[19/Mar/2018 22:31:57] "GET /phpinfo.php HTTP/1.1" 404 3007
[19/Mar/2018 22:32:03] code 400, message Bad HTTP/0.9 request type ('\x12\x01\x004\x00\x00\x00\x00\x00\x00\x15\x00\x06\x01\x00\x1b\x00\x01\x02\x00\x1c\x00')
Traceback (most recent call last):
  File "/usr/lib/python2.7/logging/__init__.py", line 861, in emit
    msg = self.format(record)
  File "/usr/lib/python2.7/logging/__init__.py", line 734, in format
    return fmt.format(record)
  File "/home/kk/.virtualenvs/blog-env/local/lib/python2.7/site-packages/django/utils/log.py", line 192, in format
    return super(ServerFormatter, self).format(record)
  File "/usr/lib/python2.7/logging/__init__.py", line 476, in format
    raise e
UnicodeDecodeError: 'utf8' codec can't decode byte 0xff in position 29: invalid start byte
Logged from file basehttp.py, line 124
Not Found: /wls-wsat/CoordinatorPortType
[19/Mar/2018 22:32:03] "GET /wls-wsat/CoordinatorPortType HTTP/1.1" 404 3058
Not Found: /wls-wsat/CoordinatorPortType11
[19/Mar/2018 22:32:03] "GET /wls-wsat/CoordinatorPortType11 HTTP/1.1" 404 3064
Not Found: /
[20/Mar/2018 10:03:14] "GET / HTTP/1.1" 404 2956
[20/Mar/2018 13:45:08] "GET /kylin HTTP/1.1" 200 16799
[20/Mar/2018 13:45:08] "GET /static/css/base.css HTTP/1.1" 304 0
[20/Mar/2018 13:45:08] "GET /static/img/header.jpg HTTP/1.1" 304 0
Not Found: /favicon.ico
[20/Mar/2018 13:45:09] "GET /favicon.ico HTTP/1.1" 404 3007
[20/Mar/2018 13:45:14] "GET /kylin/post/8 HTTP/1.1" 200 11835
[20/Mar/2018 13:45:21] "GET /kylin HTTP/1.1" 200 16799
[20/Mar/2018 13:45:27] "GET /kylin/post/12 HTTP/1.1" 200 11867
[20/Mar/2018 13:45:30] "GET /kylin HTTP/1.1" 200 16799
[20/Mar/2018 13:45:35] "GET /kylin/category/8 HTTP/1.1" 200 11935
[20/Mar/2018 13:45:37] "GET /kylin/post/6 HTTP/1.1" 200 11894
[20/Mar/2018 13:45:39] "GET /kylin/category/8 HTTP/1.1" 200 11935
[20/Mar/2018 13:45:41] "GET /kylin/category/6 HTTP/1.1" 200 12756
[20/Mar/2018 13:45:44] "GET /kylin/post/5 HTTP/1.1" 200 11958
[20/Mar/2018 13:45:46] "GET /kylin/category/6 HTTP/1.1" 200 12756
[20/Mar/2018 13:45:48] "GET /kylin/post/8 HTTP/1.1" 200 11835
[20/Mar/2018 13:45:49] "GET /kylin/category/6 HTTP/1.1" 200 12756
[20/Mar/2018 13:45:52] "GET /kylin/category/5 HTTP/1.1" 200 11931
[20/Mar/2018 13:45:54] "GET /kylin/post/4 HTTP/1.1" 200 11895
[20/Mar/2018 13:45:56] "GET /kylin/category/5 HTTP/1.1" 200 11931
[20/Mar/2018 13:46:02] "GET /kylin/category/4 HTTP/1.1" 200 14816
[20/Mar/2018 13:46:04] "GET /kylin/post/10 HTTP/1.1" 200 12396
[20/Mar/2018 13:46:06] "GET /kylin/category/4 HTTP/1.1" 200 14816
[20/Mar/2018 13:46:16] "GET /kylin HTTP/1.1" 200 16799
[20/Mar/2018 14:07:51] "GET /kylin/post/4 HTTP/1.1" 200 11895
[20/Mar/2018 14:08:17] "GET /kylin/post/4 HTTP/1.1" 200 11896
[20/Mar/2018 14:08:17] "GET /static/css/base.css HTTP/1.1" 200 128
[20/Mar/2018 14:11:02] "GET /kylin/post/10 HTTP/1.1" 200 12396
[20/Mar/2018 14:12:00] "GET /kylin/post/10 HTTP/1.1" 200 12396
[20/Mar/2018 14:12:00] "GET /static/css/base.css HTTP/1.1" 200 128
[20/Mar/2018 14:12:29] "GET /kylin/category/8 HTTP/1.1" 200 11935
[20/Mar/2018 14:13:00] "GET /kylin/category/8 HTTP/1.1" 200 11935
[20/Mar/2018 14:13:00] "GET /static/css/base.css HTTP/1.1" 200 128
[20/Mar/2018 14:15:54] "GET /kylin/post/12 HTTP/1.1" 200 11867
[20/Mar/2018 14:16:15] "GET /kylin/post/12 HTTP/1.1" 200 11867
[20/Mar/2018 14:16:15] "GET /static/css/base.css HTTP/1.1" 200 128
[20/Mar/2018 14:17:38] "GET /kylin HTTP/1.1" 200 16799
[20/Mar/2018 14:19:46] "GET /kylin HTTP/1.1" 200 16799
[20/Mar/2018 14:19:46] "GET /static/css/base.css HTTP/1.1" 200 128
[20/Mar/2018 14:33:36] "GET /kylin/category/6 HTTP/1.1" 200 12756
[20/Mar/2018 14:36:13] "GET /kylin/category/6 HTTP/1.1" 200 12756
[20/Mar/2018 14:36:13] "GET /static/css/base.css HTTP/1.1" 200 128
[20/Mar/2018 14:52:42] "GET /kylin/post/5 HTTP/1.1" 200 11958
[20/Mar/2018 14:53:09] "GET /kylin/post/5 HTTP/1.1" 200 11958
[20/Mar/2018 14:53:09] "GET /static/css/base.css HTTP/1.1" 200 128
[20/Mar/2018 14:55:17] "GET /kylin/post/8 HTTP/1.1" 200 11835
[20/Mar/2018 14:55:30] "GET /kylin/post/8 HTTP/1.1" 200 11836
[20/Mar/2018 14:55:30] "GET /static/css/base.css HTTP/1.1" 200 128
[21/Mar/2018 16:46:38] "GET /kk/post/1 HTTP/1.1" 200 8053
[21/Mar/2018 16:46:38] "GET /static/css/base.css HTTP/1.1" 200 128
Not Found: /favicon.ico
[21/Mar/2018 16:46:38] "GET /favicon.ico HTTP/1.1" 404 3007
Performing system checks...

System check identified no issues (0 silenced).
March 18, 2018 - 10:42:11
Django version 1.11.3, using settings 'blog.settings.product'
Starting development server at http://0:800/
Quit the server with CONTROL-C.
Unhandled exception in thread started by <function wrapper at 0x7f848156ec08>
Performing system checks...

Traceback (most recent call last):
  File "/home/kk/.virtualenvs/blog-env/local/lib/python2.7/site-packages/django/utils/autoreload.py", line 227, in wrapper
    fn(*args, **kwargs)
  File "/home/kk/.virtualenvs/blog-env/local/lib/python2.7/site-packages/django/core/management/commands/runserver.py", line 125, in inner_run
    self.check(display_num_errors=True)
  File "/home/kk/.virtualenvs/blog-env/local/lib/python2.7/site-packages/django/core/management/base.py", line 359, in check
    include_deployment_checks=include_deployment_checks,
  File "/home/kk/.virtualenvs/blog-env/local/lib/python2.7/site-packages/django/core/management/base.py", line 346, in _run_checks
    return checks.run_checks(**kwargs)
  File "/home/kk/.virtualenvs/blog-env/local/lib/python2.7/site-packages/django/core/checks/registry.py", line 81, in run_checks
    new_errors = check(app_configs=app_configs)
  File "/home/kk/.virtualenvs/blog-env/local/lib/python2.7/site-packages/django/core/checks/urls.py", line 16, in check_url_config
    return check_resolver(resolver)
  File "/home/kk/.virtualenvs/blog-env/local/lib/python2.7/site-packages/django/core/checks/urls.py", line 26, in check_resolver
    return check_method()
  File "/home/kk/.virtualenvs/blog-env/local/lib/python2.7/site-packages/django/urls/resolvers.py", line 254, in check
    for pattern in self.url_patterns:
  File "/home/kk/.virtualenvs/blog-env/local/lib/python2.7/site-packages/django/utils/functional.py", line 35, in __get__
    res = instance.__dict__[self.name] = self.func(instance)
  File "/home/kk/.virtualenvs/blog-env/local/lib/python2.7/site-packages/django/urls/resolvers.py", line 405, in url_patterns
    patterns = getattr(self.urlconf_module, "urlpatterns", self.urlconf_module)
  File "/home/kk/.virtualenvs/blog-env/local/lib/python2.7/site-packages/django/utils/functional.py", line 35, in __get__
    res = instance.__dict__[self.name] = self.func(instance)
  File "/home/kk/.virtualenvs/blog-env/local/lib/python2.7/site-packages/django/urls/resolvers.py", line 398, in urlconf_module
    return import_module(self.urlconf_name)
  File "/usr/lib/python2.7/importlib/__init__.py", line 37, in import_module
    __import__(name)
  File "/home/kk/prac/blog/blog/urls.py", line 21, in <module>
    from selfblog.views import PostDetailView, IndexView, CategoryView, TagView, SearchView,test
ImportError: cannot import name test
[21/Mar/2018 20:39:34] "GET /test HTTP/1.1" 200 6427
Not Found: /favicon.ico
[21/Mar/2018 20:39:34] "GET /favicon.ico HTTP/1.1" 404 3113
[21/Mar/2018 20:40:15] "GET /test HTTP/1.1" 200 6427
[21/Mar/2018 20:40:27] "GET /test HTTP/1.1" 200 6427
Not Found: /favicon.ico
[21/Mar/2018 20:40:27] "GET /favicon.ico HTTP/1.1" 404 3113
[21/Mar/2018 20:41:15] "GET /test HTTP/1.1" 200 6427
Not Found: /http:/www.baidu.com/
[22/Mar/2018 02:20:18] "GET http://www.baidu.com/ HTTP/1.1" 404 1660
Not Found: /http:/wujieliulan.com/
[22/Mar/2018 02:20:18] "GET http://wujieliulan.com/ HTTP/1.1" 404 1668
Not Found: /http:/www.123cha.com/
[22/Mar/2018 02:20:18] "GET http://www.123cha.com/ HTTP/1.1" 404 1664
Not Found: /http:/www.epochtimes.com/
[22/Mar/2018 02:20:18] "GET http://www.epochtimes.com/ HTTP/1.1" 404 1680
Not Found: /http:/www.bing.com/
[22/Mar/2018 02:20:18] "GET http://www.bing.com/ HTTP/1.1" 404 1656
Not Found: /http:/www.boxun.com/
[22/Mar/2018 02:20:18] "GET http://www.boxun.com/ HTTP/1.1" 404 1660
Not Found: /http:/www.minghui.org/
[22/Mar/2018 02:20:19] "GET http://www.minghui.org/ HTTP/1.1" 404 1668
Not Found: /http:/www.rfa.org/
[22/Mar/2018 02:20:19] "GET http://www.rfa.org/ HTTP/1.1" 404 1652
Not Found: /http:/www.bing.com/
[22/Mar/2018 02:21:16] "GET http://www.bing.com/ HTTP/1.1" 404 1656
Not Found: /http:/wujieliulan.com/
[22/Mar/2018 02:21:16] "GET http://wujieliulan.com/ HTTP/1.1" 404 1668
Not Found: /http:/www.minghui.org/
[22/Mar/2018 02:21:16] "GET http://www.minghui.org/ HTTP/1.1" 404 1668
Not Found: /http:/www.boxun.com/
[22/Mar/2018 02:21:16] "GET http://www.boxun.com/ HTTP/1.1" 404 1660
Not Found: /http:/www.rfa.org/
[22/Mar/2018 02:21:16] "GET http://www.rfa.org/ HTTP/1.1" 404 1652
Not Found: /http:/www.123cha.com/
[22/Mar/2018 02:21:17] "GET http://www.123cha.com/ HTTP/1.1" 404 1664
Not Found: /http:/www.epochtimes.com/
[22/Mar/2018 02:21:17] "GET http://www.epochtimes.com/ HTTP/1.1" 404 1680
Not Found: /http:/www.baidu.com/
[22/Mar/2018 02:21:17] "GET http://www.baidu.com/ HTTP/1.1" 404 1660
Not Found: /www.voanews.com:443
[22/Mar/2018 02:21:17] "CONNECT www.voanews.com:443 HTTP/1.0" 404 1666
[22/Mar/2018 03:05:39] "GET /test HTTP/1.1" 200 6427
[22/Mar/2018 03:05:39] "GET /test HTTP/1.1" 200 6427
[22/Mar/2018 14:35:47] "GET /kylin HTTP/1.1" 200 16800
[22/Mar/2018 14:35:47] "GET /static/css/base.css HTTP/1.1" 200 128
[22/Mar/2018 14:35:47] "GET /static/img/header.jpg HTTP/1.1" 200 7014
Not Found: /favicon.ico
[22/Mar/2018 14:35:48] "GET /favicon.ico HTTP/1.1" 404 3113
[22/Mar/2018 14:35:56] "GET /kylin HTTP/1.1" 200 16800
[22/Mar/2018 14:35:56] "GET /static/css/base.css HTTP/1.1" 304 0
[22/Mar/2018 14:35:56] "GET /static/img/header.jpg HTTP/1.1" 304 0
[22/Mar/2018 14:36:03] "GET /kylin/category/5 HTTP/1.1" 200 11932
[22/Mar/2018 14:36:19] "GET /kylin HTTP/1.1" 200 16800
Not Found: /
[22/Mar/2018 14:36:24] "GET / HTTP/1.1" 404 3062
[22/Mar/2018 14:36:34] "GET /kylin HTTP/1.1" 200 16800
[22/Mar/2018 14:36:34] "GET /static/css/base.css HTTP/1.1" 200 128
Not Found: /
[22/Mar/2018 14:36:54] "GET / HTTP/1.1" 404 3062
[22/Mar/2018 14:38:15] "GET /kylin/category/5 HTTP/1.1" 200 11932
[22/Mar/2018 14:38:15] "GET /static/css/base.css HTTP/1.1" 304 0
[22/Mar/2018 14:38:15] "GET /static/img/header.jpg HTTP/1.1" 304 0
[22/Mar/2018 15:04:49] "GET /kylin/category/5 HTTP/1.1" 200 11932
[22/Mar/2018 15:05:17] "GET /kylin/category/5 HTTP/1.1" 200 11932
[22/Mar/2018 15:05:17] "GET /static/css/base.css HTTP/1.1" 200 128
[22/Mar/2018 19:46:12] "GET /kk/post/1 HTTP/1.1" 200 8053
[22/Mar/2018 19:46:12] "GET /static/css/base.css HTTP/1.1" 200 128
Not Found: /favicon.ico
[22/Mar/2018 19:46:12] "GET /favicon.ico HTTP/1.1" 404 3113
Not Found: /
[23/Mar/2018 08:39:23] "GET / HTTP/1.1" 404 3062
Not Found: /favicon.ico
[23/Mar/2018 08:39:24] "GET /favicon.ico HTTP/1.1" 404 3113
Not Found: /
[23/Mar/2018 08:39:51] "GET / HTTP/1.1" 404 3058
Not Found: /
[23/Mar/2018 08:40:08] "GET / HTTP/1.1" 404 3062
Not Found: /
[23/Mar/2018 08:40:08] "GET / HTTP/1.1" 404 3062
[23/Mar/2018 18:21:59] "GET /kylin HTTP/1.1" 200 16800
[23/Mar/2018 18:21:59] "GET /static/css/base.css HTTP/1.1" 304 0
[23/Mar/2018 18:22:00] "GET /static/img/header.jpg HTTP/1.1" 200 7014
Not Found: /favicon.ico
[23/Mar/2018 18:22:00] "GET /favicon.ico HTTP/1.1" 404 3113
[23/Mar/2018 18:22:06] "GET /kylin/post/8 HTTP/1.1" 200 11837
[23/Mar/2018 18:22:10] "GET /kylin HTTP/1.1" 200 16800
[23/Mar/2018 18:22:11] "GET /kylin/category/5 HTTP/1.1" 200 11932
[23/Mar/2018 18:22:12] "GET /kylin/category/6 HTTP/1.1" 200 12757
[23/Mar/2018 18:22:12] "GET /kylin/category/8 HTTP/1.1" 200 11935
[23/Mar/2018 18:22:13] "GET /kylin HTTP/1.1" 200 16800
[23/Mar/2018 18:22:26] "GET /kylin/post/8 HTTP/1.1" 200 11837
[23/Mar/2018 18:22:32] "GET /kylin HTTP/1.1" 200 16800
[23/Mar/2018 18:22:33] "GET /kylin HTTP/1.1" 200 16800
[23/Mar/2018 18:22:35] "GET /kylin/category/5 HTTP/1.1" 200 11932
[23/Mar/2018 18:22:36] "GET /kylin/category/4 HTTP/1.1" 200 14816
[23/Mar/2018 18:22:36] "GET /kylin HTTP/1.1" 200 16800
[23/Mar/2018 18:22:37] "GET /kylin/category/8 HTTP/1.1" 200 11935
[23/Mar/2018 18:22:38] "GET /kylin HTTP/1.1" 200 16800
[23/Mar/2018 18:22:45] "GET /kylin/post/8 HTTP/1.1" 200 11837
[23/Mar/2018 18:22:52] "GET /kylin HTTP/1.1" 200 16800
[23/Mar/2018 18:23:30] "GET /kylin HTTP/1.1" 200 16800
[23/Mar/2018 18:23:31] "GET /static/css/base.css HTTP/1.1" 200 128
[23/Mar/2018 18:23:31] "GET /static/img/header.jpg HTTP/1.1" 200 7014
[23/Mar/2018 18:23:38] "GET /kylin/post/8 HTTP/1.1" 200 11837
[23/Mar/2018 18:24:00] "GET /kylin HTTP/1.1" 200 16800
[23/Mar/2018 18:24:38] "GET /kylin/post/8 HTTP/1.1" 200 11837
[23/Mar/2018 18:43:16] "GET /kylin HTTP/1.1" 200 16800
[23/Mar/2018 18:43:16] "GET /static/css/base.css HTTP/1.1" 200 128
[23/Mar/2018 18:43:17] "GET /static/img/header.jpg HTTP/1.1" 200 7014
[23/Mar/2018 20:26:48] "GET /kylin/post/8 HTTP/1.1" 200 17342
Forbidden (CSRF token missing or incorrect.): /comment
[23/Mar/2018 20:27:00] "POST /comment HTTP/1.1" 403 2497
Forbidden (CSRF token missing or incorrect.): /comment
[23/Mar/2018 20:27:22] "POST /comment HTTP/1.1" 403 2497
Forbidden (CSRF token missing or incorrect.): /comment
[23/Mar/2018 20:27:31] "POST /comment HTTP/1.1" 403 2497
[23/Mar/2018 20:33:18] "GET /kylin/post/8 HTTP/1.1" 200 17496
Forbidden (CSRF token missing or incorrect.): /comment
[23/Mar/2018 20:33:25] "POST /comment HTTP/1.1" 403 2497
[23/Mar/2018 20:37:47] "GET /kylin/post/8 HTTP/1.1" 200 17513
Forbidden (CSRF token missing or incorrect.): /comment
[23/Mar/2018 20:38:04] "POST /comment HTTP/1.1" 403 2497
Forbidden (CSRF token missing or incorrect.): /comment
[23/Mar/2018 20:39:16] "POST /comment HTTP/1.1" 403 2497
[23/Mar/2018 20:39:19] "GET /kylin/post/8 HTTP/1.1" 200 17513
Forbidden (CSRF token missing or incorrect.): /comment
[23/Mar/2018 20:39:50] "POST /comment HTTP/1.1" 403 2497
Performing system checks...

System check identified no issues (0 silenced).
March 21, 2018 - 20:38:54
Django version 1.11.3, using settings 'blog.settings.product'
Starting development server at http://0:800/
Quit the server with CONTROL-C.
Unhandled exception in thread started by <function wrapper at 0x7fdad3b7ac08>
Performing system checks...

Traceback (most recent call last):
  File "/home/kk/.virtualenvs/blog-env/local/lib/python2.7/site-packages/django/utils/autoreload.py", line 227, in wrapper
    fn(*args, **kwargs)
  File "/home/kk/.virtualenvs/blog-env/local/lib/python2.7/site-packages/django/core/management/commands/runserver.py", line 125, in inner_run
    self.check(display_num_errors=True)
  File "/home/kk/.virtualenvs/blog-env/local/lib/python2.7/site-packages/django/core/management/base.py", line 359, in check
    include_deployment_checks=include_deployment_checks,
  File "/home/kk/.virtualenvs/blog-env/local/lib/python2.7/site-packages/django/core/management/base.py", line 346, in _run_checks
    return checks.run_checks(**kwargs)
  File "/home/kk/.virtualenvs/blog-env/local/lib/python2.7/site-packages/django/core/checks/registry.py", line 81, in run_checks
    new_errors = check(app_configs=app_configs)
  File "/home/kk/.virtualenvs/blog-env/local/lib/python2.7/site-packages/django/core/checks/urls.py", line 16, in check_url_config
    return check_resolver(resolver)
  File "/home/kk/.virtualenvs/blog-env/local/lib/python2.7/site-packages/django/core/checks/urls.py", line 26, in check_resolver
    return check_method()
  File "/home/kk/.virtualenvs/blog-env/local/lib/python2.7/site-packages/django/urls/resolvers.py", line 254, in check
    for pattern in self.url_patterns:
  File "/home/kk/.virtualenvs/blog-env/local/lib/python2.7/site-packages/django/utils/functional.py", line 35, in __get__
    res = instance.__dict__[self.name] = self.func(instance)
  File "/home/kk/.virtualenvs/blog-env/local/lib/python2.7/site-packages/django/urls/resolvers.py", line 405, in url_patterns
    patterns = getattr(self.urlconf_module, "urlpatterns", self.urlconf_module)
  File "/home/kk/.virtualenvs/blog-env/local/lib/python2.7/site-packages/django/utils/functional.py", line 35, in __get__
    res = instance.__dict__[self.name] = self.func(instance)
  File "/home/kk/.virtualenvs/blog-env/local/lib/python2.7/site-packages/django/urls/resolvers.py", line 398, in urlconf_module
    return import_module(self.urlconf_name)
  File "/usr/lib/python2.7/importlib/__init__.py", line 37, in import_module
    __import__(name)
  File "/home/kk/prac/blog/blog/urls.py", line 21, in <module>
    from selfblog.views import PostDetailView, IndexView, CategoryView, TagView, SearchView,test, comment
ImportError: cannot import name comment
[23/Mar/2018 20:46:07] "GET /kylin/post/8 HTTP/1.1" 200 17496
[23/Mar/2018 20:46:10] "POST /comment HTTP/1.1" 200 2
[23/Mar/2018 20:46:19] "GET /kylin/post/8 HTTP/1.1" 200 17496
[23/Mar/2018 20:49:09] "POST /comment HTTP/1.1" 200 2
Performing system checks...

System check identified no issues (0 silenced).
March 23, 2018 - 20:46:04
Django version 1.11.3, using settings 'blog.settings.product'
Starting development server at http://0:800/
Quit the server with CONTROL-C.
Performing system checks...

System check identified no issues (0 silenced).
March 23, 2018 - 20:56:44
Django version 1.11.3, using settings 'blog.settings.product'
Starting development server at http://0:800/
Quit the server with CONTROL-C.
Performing system checks...

System check identified no issues (0 silenced).
March 23, 2018 - 21:01:50
Django version 1.11.3, using settings 'blog.settings.product'
Starting development server at http://0:800/
Quit the server with CONTROL-C.
Unhandled exception in thread started by <function wrapper at 0x7f392d326e60>
Traceback (most recent call last):
  File "/home/kk/.virtualenvs/blog-env/local/lib/python2.7/site-packages/django/utils/autoreload.py", line 235, in wrapper
    filename = traceback.extract_tb(tb)[-1][0]
  File "/usr/lib/python2.7/traceback.py", line 101, in extract_tb
    line = linecache.getline(filename, lineno, f.f_globals)
  File "/home/kk/.virtualenvs/blog-env/lib/python2.7/linecache.py", line 14, in getline
    lines = getlines(filename, module_globals)
  File "/home/kk/.virtualenvs/blog-env/lib/python2.7/linecache.py", line 41, in getlines
    return updatecache(filename, module_globals)
  File "/home/kk/.virtualenvs/blog-env/lib/python2.7/linecache.py", line 138, in updatecache
    cache[filename] = size, mtime, lines, fullname
TypeError: 'NoneType' object does not support item assignment
Performing system checks...

System check identified no issues (0 silenced).

You have 1 unapplied migration(s). Your project may not work properly until you apply the migrations for app(s): comment.
Run 'python manage.py migrate' to apply them.
March 23, 2018 - 21:02:20
Django version 1.11.3, using settings 'blog.settings.product'
Starting development server at http://0:800/
Quit the server with CONTROL-C.
Performing system checks...

System check identified no issues (0 silenced).

You have 2 unapplied migration(s). Your project may not work properly until you apply the migrations for app(s): comment.
Run 'python manage.py migrate' to apply them.
March 23, 2018 - 21:05:03
Django version 1.11.3, using settings 'blog.settings.product'
Starting development server at http://0:800/
Quit the server with CONTROL-C.
Performing system checks...

System check identified no issues (0 silenced).

You have 2 unapplied migration(s). Your project may not work properly until you apply the migrations for app(s): comment.
Run 'python manage.py migrate' to apply them.
March 23, 2018 - 21:07:29
Django version 1.11.3, using settings 'blog.settings.product'
Starting development server at http://0:800/
Quit the server with CONTROL-C.
Performing system checks...

System check identified no issues (0 silenced).

You have 3 unapplied migration(s). Your project may not work properly until you apply the migrations for app(s): comment.
Run 'python manage.py migrate' to apply them.
March 23, 2018 - 21:08:02
Django version 1.11.3, using settings 'blog.settings.product'
Starting development server at http://0:800/
Quit the server with CONTROL-C.
Performing system checks...

System check identified no issues (0 silenced).

You have 4 unapplied migration(s). Your project may not work properly until you apply the migrations for app(s): comment.
Run 'python manage.py migrate' to apply them.
March 23, 2018 - 21:08:40
Django version 1.11.3, using settings 'blog.settings.product'
Starting development server at http://0:800/
Quit the server with CONTROL-C.
[23/Mar/2018 21:12:09] "GET /kylin/post/8 HTTP/1.1" 200 17520
Internal Server Error: /comment
Traceback (most recent call last):
  File "/home/kk/.virtualenvs/blog-env/local/lib/python2.7/site-packages/django/core/handlers/exception.py", line 41, in inner
    response = get_response(request)
  File "/home/kk/.virtualenvs/blog-env/local/lib/python2.7/site-packages/django/core/handlers/base.py", line 187, in _get_response
    response = self.process_exception_by_middleware(e, request)
  File "/home/kk/.virtualenvs/blog-env/local/lib/python2.7/site-packages/django/core/handlers/base.py", line 185, in _get_response
    response = wrapped_callback(request, *callback_args, **callback_kwargs)
  File "/home/kk/.virtualenvs/blog-env/local/lib/python2.7/site-packages/django/views/decorators/csrf.py", line 58, in wrapped_view
    return view_func(*args, **kwargs)
  File "/home/kk/prac/blog/selfblog/views.py", line 297, in comment
    com = Comment.objects.create(content=txt, nickname='nobody', target=target, pid=pid)
  File "/home/kk/.virtualenvs/blog-env/local/lib/python2.7/site-packages/django/db/models/manager.py", line 85, in manager_method
    return getattr(self.get_queryset(), name)(*args, **kwargs)
  File "/home/kk/.virtualenvs/blog-env/local/lib/python2.7/site-packages/django/db/models/query.py", line 392, in create
    obj = self.model(**kwargs)
  File "/home/kk/.virtualenvs/blog-env/local/lib/python2.7/site-packages/django/db/models/base.py", line 554, in __init__
    _setattr(self, field.name, rel_obj)
  File "/home/kk/.virtualenvs/blog-env/local/lib/python2.7/site-packages/django/db/models/fields/related_descriptors.py", line 216, in __set__
    self.field.remote_field.model._meta.object_name,
ValueError: Cannot assign "u'0'": "Comment.pid" must be a "Comment" instance.
[23/Mar/2018 21:12:14] "POST /comment HTTP/1.1" 500 16257
[23/Mar/2018 21:12:20] "GET /kylin/post/8 HTTP/1.1" 200 17520
Internal Server Error: /comment
Traceback (most recent call last):
  File "/home/kk/.virtualenvs/blog-env/local/lib/python2.7/site-packages/django/core/handlers/exception.py", line 41, in inner
    response = get_response(request)
  File "/home/kk/.virtualenvs/blog-env/local/lib/python2.7/site-packages/django/core/handlers/base.py", line 187, in _get_response
    response = self.process_exception_by_middleware(e, request)
  File "/home/kk/.virtualenvs/blog-env/local/lib/python2.7/site-packages/django/core/handlers/base.py", line 185, in _get_response
    response = wrapped_callback(request, *callback_args, **callback_kwargs)
  File "/home/kk/.virtualenvs/blog-env/local/lib/python2.7/site-packages/django/views/decorators/csrf.py", line 58, in wrapped_view
    return view_func(*args, **kwargs)
  File "/home/kk/prac/blog/selfblog/views.py", line 297, in comment
    com = Comment.objects.create(content=txt, nickname='nobody', target=target, pid=pid)
  File "/home/kk/.virtualenvs/blog-env/local/lib/python2.7/site-packages/django/db/models/manager.py", line 85, in manager_method
    return getattr(self.get_queryset(), name)(*args, **kwargs)
  File "/home/kk/.virtualenvs/blog-env/local/lib/python2.7/site-packages/django/db/models/query.py", line 392, in create
    obj = self.model(**kwargs)
  File "/home/kk/.virtualenvs/blog-env/local/lib/python2.7/site-packages/django/db/models/base.py", line 554, in __init__
    _setattr(self, field.name, rel_obj)
  File "/home/kk/.virtualenvs/blog-env/local/lib/python2.7/site-packages/django/db/models/fields/related_descriptors.py", line 216, in __set__
    self.field.remote_field.model._meta.object_name,
ValueError: Cannot assign "u'0'": "Comment.pid" must be a "Comment" instance.
[23/Mar/2018 21:12:36] "POST /comment HTTP/1.1" 500 16165
Performing system checks...

System check identified no issues (0 silenced).

You have 2 unapplied migration(s). Your project may not work properly until you apply the migrations for app(s): comment.
Run 'python manage.py migrate' to apply them.
March 23, 2018 - 21:11:13
Django version 1.11.3, using settings 'blog.settings.product'
Starting development server at http://0:800/
Quit the server with CONTROL-C.
[23/Mar/2018 21:13:34] "GET /kylin/post/8 HTTP/1.1" 200 17520
Internal Server Error: /comment
Traceback (most recent call last):
  File "/home/kk/.virtualenvs/blog-env/local/lib/python2.7/site-packages/django/core/handlers/exception.py", line 41, in inner
    response = get_response(request)
  File "/home/kk/.virtualenvs/blog-env/local/lib/python2.7/site-packages/django/core/handlers/base.py", line 187, in _get_response
    response = self.process_exception_by_middleware(e, request)
  File "/home/kk/.virtualenvs/blog-env/local/lib/python2.7/site-packages/django/core/handlers/base.py", line 185, in _get_response
    response = wrapped_callback(request, *callback_args, **callback_kwargs)
  File "/home/kk/.virtualenvs/blog-env/local/lib/python2.7/site-packages/django/views/decorators/csrf.py", line 58, in wrapped_view
    return view_func(*args, **kwargs)
  File "/home/kk/prac/blog/selfblog/views.py", line 299, in comment
    com = Comment.objects.create(content=txt, nickname='nobody', target=target, pid=pid)
  File "/home/kk/.virtualenvs/blog-env/local/lib/python2.7/site-packages/django/db/models/manager.py", line 85, in manager_method
    return getattr(self.get_queryset(), name)(*args, **kwargs)
  File "/home/kk/.virtualenvs/blog-env/local/lib/python2.7/site-packages/django/db/models/query.py", line 392, in create
    obj = self.model(**kwargs)
  File "/home/kk/.virtualenvs/blog-env/local/lib/python2.7/site-packages/django/db/models/base.py", line 554, in __init__
    _setattr(self, field.name, rel_obj)
  File "/home/kk/.virtualenvs/blog-env/local/lib/python2.7/site-packages/django/db/models/fields/related_descriptors.py", line 216, in __set__
    self.field.remote_field.model._meta.object_name,
ValueError: Cannot assign "u'0'": "Comment.pid" must be a "Comment" instance.
[23/Mar/2018 21:13:36] "POST /comment HTTP/1.1" 500 16165
Internal Server Error: /comment
Traceback (most recent call last):
  File "/home/kk/.virtualenvs/blog-env/local/lib/python2.7/site-packages/django/core/handlers/exception.py", line 41, in inner
    response = get_response(request)
  File "/home/kk/.virtualenvs/blog-env/local/lib/python2.7/site-packages/django/core/handlers/base.py", line 187, in _get_response
    response = self.process_exception_by_middleware(e, request)
  File "/home/kk/.virtualenvs/blog-env/local/lib/python2.7/site-packages/django/core/handlers/base.py", line 185, in _get_response
    response = wrapped_callback(request, *callback_args, **callback_kwargs)
  File "/home/kk/.virtualenvs/blog-env/local/lib/python2.7/site-packages/django/views/decorators/csrf.py", line 58, in wrapped_view
    return view_func(*args, **kwargs)
  File "/home/kk/prac/blog/selfblog/views.py", line 299, in comment
    com = Comment.objects.create(content=txt, nickname='nobody', target=target, pid=pid)
  File "/home/kk/.virtualenvs/blog-env/local/lib/python2.7/site-packages/django/db/models/manager.py", line 85, in manager_method
    return getattr(self.get_queryset(), name)(*args, **kwargs)
  File "/home/kk/.virtualenvs/blog-env/local/lib/python2.7/site-packages/django/db/models/query.py", line 392, in create
    obj = self.model(**kwargs)
  File "/home/kk/.virtualenvs/blog-env/local/lib/python2.7/site-packages/django/db/models/base.py", line 554, in __init__
    _setattr(self, field.name, rel_obj)
  File "/home/kk/.virtualenvs/blog-env/local/lib/python2.7/site-packages/django/db/models/fields/related_descriptors.py", line 216, in __set__
    self.field.remote_field.model._meta.object_name,
ValueError: Cannot assign "u'0'": "Comment.pid" must be a "Comment" instance.
[23/Mar/2018 21:13:44] "POST /comment HTTP/1.1" 500 16165
[23/Mar/2018 21:13:52] "GET /kylin/category/4 HTTP/1.1" 200 14851
[23/Mar/2018 21:13:56] "GET /kylin HTTP/1.1" 200 16835
[23/Mar/2018 21:13:57] "GET /kylin/category/4 HTTP/1.1" 200 14851
[23/Mar/2018 21:13:57] "GET /kylin/post/10 HTTP/1.1" 200 18079
Internal Server Error: /comment
Traceback (most recent call last):
  File "/home/kk/.virtualenvs/blog-env/local/lib/python2.7/site-packages/django/core/handlers/exception.py", line 41, in inner
    response = get_response(request)
  File "/home/kk/.virtualenvs/blog-env/local/lib/python2.7/site-packages/django/core/handlers/base.py", line 187, in _get_response
    response = self.process_exception_by_middleware(e, request)
  File "/home/kk/.virtualenvs/blog-env/local/lib/python2.7/site-packages/django/core/handlers/base.py", line 185, in _get_response
    response = wrapped_callback(request, *callback_args, **callback_kwargs)
  File "/home/kk/.virtualenvs/blog-env/local/lib/python2.7/site-packages/django/views/decorators/csrf.py", line 58, in wrapped_view
    return view_func(*args, **kwargs)
  File "/home/kk/prac/blog/selfblog/views.py", line 299, in comment
    com = Comment.objects.create(content=txt, nickname='nobody', target=target, pid=pid)
  File "/home/kk/.virtualenvs/blog-env/local/lib/python2.7/site-packages/django/db/models/manager.py", line 85, in manager_method
    return getattr(self.get_queryset(), name)(*args, **kwargs)
  File "/home/kk/.virtualenvs/blog-env/local/lib/python2.7/site-packages/django/db/models/query.py", line 392, in create
    obj = self.model(**kwargs)
  File "/home/kk/.virtualenvs/blog-env/local/lib/python2.7/site-packages/django/db/models/base.py", line 554, in __init__
    _setattr(self, field.name, rel_obj)
  File "/home/kk/.virtualenvs/blog-env/local/lib/python2.7/site-packages/django/db/models/fields/related_descriptors.py", line 216, in __set__
    self.field.remote_field.model._meta.object_name,
ValueError: Cannot assign "u'0'": "Comment.pid" must be a "Comment" instance.
[23/Mar/2018 21:14:05] "POST /comment HTTP/1.1" 500 16167
Performing system checks...

System check identified no issues (0 silenced).

You have 2 unapplied migration(s). Your project may not work properly until you apply the migrations for app(s): comment.
Run 'python manage.py migrate' to apply them.
March 23, 2018 - 21:13:31
Django version 1.11.3, using settings 'blog.settings.product'
Starting development server at http://0:800/
Quit the server with CONTROL-C.
Performing system checks...

System check identified no issues (0 silenced).

You have 2 unapplied migration(s). Your project may not work properly until you apply the migrations for app(s): comment.
Run 'python manage.py migrate' to apply them.
March 23, 2018 - 21:18:58
Django version 1.11.3, using settings 'blog.settings.product'
Starting development server at http://0:800/
Quit the server with CONTROL-C.
Unhandled exception in thread started by <function wrapper at 0x7feeae2198c0>
Performing system checks...

Traceback (most recent call last):
  File "/home/kk/.virtualenvs/blog-env/local/lib/python2.7/site-packages/django/utils/autoreload.py", line 227, in wrapper
    fn(*args, **kwargs)
  File "/home/kk/.virtualenvs/blog-env/local/lib/python2.7/site-packages/django/core/management/commands/runserver.py", line 125, in inner_run
    self.check(display_num_errors=True)
  File "/home/kk/.virtualenvs/blog-env/local/lib/python2.7/site-packages/django/core/management/base.py", line 359, in check
    include_deployment_checks=include_deployment_checks,
  File "/home/kk/.virtualenvs/blog-env/local/lib/python2.7/site-packages/django/core/management/base.py", line 346, in _run_checks
    return checks.run_checks(**kwargs)
  File "/home/kk/.virtualenvs/blog-env/local/lib/python2.7/site-packages/django/core/checks/registry.py", line 81, in run_checks
    new_errors = check(app_configs=app_configs)
  File "/home/kk/.virtualenvs/blog-env/local/lib/python2.7/site-packages/django/core/checks/urls.py", line 16, in check_url_config
    return check_resolver(resolver)
  File "/home/kk/.virtualenvs/blog-env/local/lib/python2.7/site-packages/django/core/checks/urls.py", line 26, in check_resolver
    return check_method()
  File "/home/kk/.virtualenvs/blog-env/local/lib/python2.7/site-packages/django/urls/resolvers.py", line 254, in check
    for pattern in self.url_patterns:
  File "/home/kk/.virtualenvs/blog-env/local/lib/python2.7/site-packages/django/utils/functional.py", line 35, in __get__
    res = instance.__dict__[self.name] = self.func(instance)
  File "/home/kk/.virtualenvs/blog-env/local/lib/python2.7/site-packages/django/urls/resolvers.py", line 405, in url_patterns
    patterns = getattr(self.urlconf_module, "urlpatterns", self.urlconf_module)
  File "/home/kk/.virtualenvs/blog-env/local/lib/python2.7/site-packages/django/utils/functional.py", line 35, in __get__
    res = instance.__dict__[self.name] = self.func(instance)
  File "/home/kk/.virtualenvs/blog-env/local/lib/python2.7/site-packages/django/urls/resolvers.py", line 398, in urlconf_module
    return import_module(self.urlconf_name)
  File "/usr/lib/python2.7/importlib/__init__.py", line 37, in import_module
    __import__(name)
  File "/home/kk/prac/blog/blog/urls.py", line 21, in <module>
    from selfblog.views import PostDetailView, IndexView, CategoryView, TagView, SearchView,test, comment
  File "/home/kk/prac/blog/selfblog/views.py", line 23, in <module>
    from comment.models import Comment
  File "/home/kk/prac/blog/comment/models.py", line 9, in <module>
    class Comment(models.Model):
  File "/home/kk/.virtualenvs/blog-env/local/lib/python2.7/site-packages/django/db/models/base.py", line 118, in __new__
    "INSTALLED_APPS." % (module, name)
RuntimeError: Model class comment.models.Comment doesn't declare an explicit app_label and isn't in an application in INSTALLED_APPS.
[23/Mar/2018 21:24:13] "GET /kylin HTTP/1.1" 200 16835
[23/Mar/2018 21:24:15] "GET /kylin/post/8 HTTP/1.1" 200 17520
Internal Server Error: /comment
Traceback (most recent call last):
  File "/home/kk/.virtualenvs/blog-env/local/lib/python2.7/site-packages/django/core/handlers/exception.py", line 41, in inner
    response = get_response(request)
  File "/home/kk/.virtualenvs/blog-env/local/lib/python2.7/site-packages/django/core/handlers/base.py", line 187, in _get_response
    response = self.process_exception_by_middleware(e, request)
  File "/home/kk/.virtualenvs/blog-env/local/lib/python2.7/site-packages/django/core/handlers/base.py", line 185, in _get_response
    response = wrapped_callback(request, *callback_args, **callback_kwargs)
  File "/home/kk/.virtualenvs/blog-env/local/lib/python2.7/site-packages/django/views/decorators/csrf.py", line 58, in wrapped_view
    return view_func(*args, **kwargs)
  File "/home/kk/prac/blog/selfblog/views.py", line 299, in comment
    com = Comment.objects.create(content=txt, nickname='nobody', target=target, pid=pid)
  File "/home/kk/.virtualenvs/blog-env/local/lib/python2.7/site-packages/django/db/models/manager.py", line 85, in manager_method
    return getattr(self.get_queryset(), name)(*args, **kwargs)
  File "/home/kk/.virtualenvs/blog-env/local/lib/python2.7/site-packages/django/db/models/query.py", line 392, in create
    obj = self.model(**kwargs)
  File "/home/kk/.virtualenvs/blog-env/local/lib/python2.7/site-packages/django/db/models/base.py", line 554, in __init__
    _setattr(self, field.name, rel_obj)
  File "/home/kk/.virtualenvs/blog-env/local/lib/python2.7/site-packages/django/db/models/fields/related_descriptors.py", line 216, in __set__
    self.field.remote_field.model._meta.object_name,
ValueError: Cannot assign "u'0'": "Comment.pid" must be a "Comment" instance.
[23/Mar/2018 21:24:18] "POST /comment HTTP/1.1" 500 16164
Internal Server Error: /comment
Traceback (most recent call last):
  File "/home/kk/.virtualenvs/blog-env/local/lib/python2.7/site-packages/django/core/handlers/exception.py", line 41, in inner
    response = get_response(request)
  File "/home/kk/.virtualenvs/blog-env/local/lib/python2.7/site-packages/django/core/handlers/base.py", line 187, in _get_response
    response = self.process_exception_by_middleware(e, request)
  File "/home/kk/.virtualenvs/blog-env/local/lib/python2.7/site-packages/django/core/handlers/base.py", line 185, in _get_response
    response = wrapped_callback(request, *callback_args, **callback_kwargs)
  File "/home/kk/.virtualenvs/blog-env/local/lib/python2.7/site-packages/django/views/decorators/csrf.py", line 58, in wrapped_view
    return view_func(*args, **kwargs)
  File "/home/kk/prac/blog/selfblog/views.py", line 299, in comment
    com = Comment.objects.create(content=txt, nickname='nobody', target=target, pid=pid)
  File "/home/kk/.virtualenvs/blog-env/local/lib/python2.7/site-packages/django/db/models/manager.py", line 85, in manager_method
    return getattr(self.get_queryset(), name)(*args, **kwargs)
  File "/home/kk/.virtualenvs/blog-env/local/lib/python2.7/site-packages/django/db/models/query.py", line 392, in create
    obj = self.model(**kwargs)
  File "/home/kk/.virtualenvs/blog-env/local/lib/python2.7/site-packages/django/db/models/base.py", line 554, in __init__
    _setattr(self, field.name, rel_obj)
  File "/home/kk/.virtualenvs/blog-env/local/lib/python2.7/site-packages/django/db/models/fields/related_descriptors.py", line 216, in __set__
    self.field.remote_field.model._meta.object_name,
ValueError: Cannot assign "u'0'": "Comment.pid" must be a "Comment" instance.
[23/Mar/2018 21:24:19] "POST /comment HTTP/1.1" 500 16164
Internal Server Error: /comment
Traceback (most recent call last):
  File "/home/kk/.virtualenvs/blog-env/local/lib/python2.7/site-packages/django/core/handlers/exception.py", line 41, in inner
    response = get_response(request)
  File "/home/kk/.virtualenvs/blog-env/local/lib/python2.7/site-packages/django/core/handlers/base.py", line 187, in _get_response
    response = self.process_exception_by_middleware(e, request)
  File "/home/kk/.virtualenvs/blog-env/local/lib/python2.7/site-packages/django/core/handlers/base.py", line 185, in _get_response
    response = wrapped_callback(request, *callback_args, **callback_kwargs)
  File "/home/kk/.virtualenvs/blog-env/local/lib/python2.7/site-packages/django/views/decorators/csrf.py", line 58, in wrapped_view
    return view_func(*args, **kwargs)
  File "/home/kk/prac/blog/selfblog/views.py", line 299, in comment
    com = Comment.objects.create(content=txt, nickname='nobody', target=target, pid=pid)
  File "/home/kk/.virtualenvs/blog-env/local/lib/python2.7/site-packages/django/db/models/manager.py", line 85, in manager_method
    return getattr(self.get_queryset(), name)(*args, **kwargs)
  File "/home/kk/.virtualenvs/blog-env/local/lib/python2.7/site-packages/django/db/models/query.py", line 392, in create
    obj = self.model(**kwargs)
  File "/home/kk/.virtualenvs/blog-env/local/lib/python2.7/site-packages/django/db/models/base.py", line 554, in __init__
    _setattr(self, field.name, rel_obj)
  File "/home/kk/.virtualenvs/blog-env/local/lib/python2.7/site-packages/django/db/models/fields/related_descriptors.py", line 216, in __set__
    self.field.remote_field.model._meta.object_name,
ValueError: Cannot assign "u'0'": "Comment.pid" must be a "Comment" instance.
[23/Mar/2018 21:24:19] "POST /comment HTTP/1.1" 500 16164
Internal Server Error: /comment
Traceback (most recent call last):
  File "/home/kk/.virtualenvs/blog-env/local/lib/python2.7/site-packages/django/core/handlers/exception.py", line 41, in inner
    response = get_response(request)
  File "/home/kk/.virtualenvs/blog-env/local/lib/python2.7/site-packages/django/core/handlers/base.py", line 187, in _get_response
    response = self.process_exception_by_middleware(e, request)
  File "/home/kk/.virtualenvs/blog-env/local/lib/python2.7/site-packages/django/core/handlers/base.py", line 185, in _get_response
    response = wrapped_callback(request, *callback_args, **callback_kwargs)
  File "/home/kk/.virtualenvs/blog-env/local/lib/python2.7/site-packages/django/views/decorators/csrf.py", line 58, in wrapped_view
    return view_func(*args, **kwargs)
  File "/home/kk/prac/blog/selfblog/views.py", line 299, in comment
    com = Comment.objects.create(content=txt, nickname='nobody', target=target, pid=pid)
  File "/home/kk/.virtualenvs/blog-env/local/lib/python2.7/site-packages/django/db/models/manager.py", line 85, in manager_method
    return getattr(self.get_queryset(), name)(*args, **kwargs)
  File "/home/kk/.virtualenvs/blog-env/local/lib/python2.7/site-packages/django/db/models/query.py", line 392, in create
    obj = self.model(**kwargs)
  File "/home/kk/.virtualenvs/blog-env/local/lib/python2.7/site-packages/django/db/models/base.py", line 554, in __init__
    _setattr(self, field.name, rel_obj)
  File "/home/kk/.virtualenvs/blog-env/local/lib/python2.7/site-packages/django/db/models/fields/related_descriptors.py", line 216, in __set__
    self.field.remote_field.model._meta.object_name,
ValueError: Cannot assign "u'0'": "Comment.pid" must be a "Comment" instance.
[23/Mar/2018 21:24:19] "POST /comment HTTP/1.1" 500 16164
Internal Server Error: /comment
Traceback (most recent call last):
  File "/home/kk/.virtualenvs/blog-env/local/lib/python2.7/site-packages/django/core/handlers/exception.py", line 41, in inner
    response = get_response(request)
  File "/home/kk/.virtualenvs/blog-env/local/lib/python2.7/site-packages/django/core/handlers/base.py", line 187, in _get_response
    response = self.process_exception_by_middleware(e, request)
  File "/home/kk/.virtualenvs/blog-env/local/lib/python2.7/site-packages/django/core/handlers/base.py", line 185, in _get_response
    response = wrapped_callback(request, *callback_args, **callback_kwargs)
  File "/home/kk/.virtualenvs/blog-env/local/lib/python2.7/site-packages/django/views/decorators/csrf.py", line 58, in wrapped_view
    return view_func(*args, **kwargs)
  File "/home/kk/prac/blog/selfblog/views.py", line 299, in comment
    com = Comment.objects.create(content=txt, nickname='nobody', target=target, pid=pid)
  File "/home/kk/.virtualenvs/blog-env/local/lib/python2.7/site-packages/django/db/models/manager.py", line 85, in manager_method
    return getattr(self.get_queryset(), name)(*args, **kwargs)
  File "/home/kk/.virtualenvs/blog-env/local/lib/python2.7/site-packages/django/db/models/query.py", line 392, in create
    obj = self.model(**kwargs)
  File "/home/kk/.virtualenvs/blog-env/local/lib/python2.7/site-packages/django/db/models/base.py", line 554, in __init__
    _setattr(self, field.name, rel_obj)
  File "/home/kk/.virtualenvs/blog-env/local/lib/python2.7/site-packages/django/db/models/fields/related_descriptors.py", line 216, in __set__
    self.field.remote_field.model._meta.object_name,
ValueError: Cannot assign "u'0'": "Comment.pid" must be a "Comment" instance.
[23/Mar/2018 21:24:19] "POST /comment HTTP/1.1" 500 16164
[23/Mar/2018 21:39:29] "GET /kylin HTTP/1.1" 200 16835
[23/Mar/2018 21:39:32] "GET /kylin/post/8 HTTP/1.1" 200 17520
Internal Server Error: /comment
Traceback (most recent call last):
  File "/home/kk/.virtualenvs/blog-env/local/lib/python2.7/site-packages/django/core/handlers/exception.py", line 41, in inner
    response = get_response(request)
  File "/home/kk/.virtualenvs/blog-env/local/lib/python2.7/site-packages/django/core/handlers/base.py", line 187, in _get_response
    response = self.process_exception_by_middleware(e, request)
  File "/home/kk/.virtualenvs/blog-env/local/lib/python2.7/site-packages/django/core/handlers/base.py", line 185, in _get_response
    response = wrapped_callback(request, *callback_args, **callback_kwargs)
  File "/home/kk/.virtualenvs/blog-env/local/lib/python2.7/site-packages/django/views/decorators/csrf.py", line 58, in wrapped_view
    return view_func(*args, **kwargs)
  File "/home/kk/prac/blog/selfblog/views.py", line 299, in comment
    com = Comment.objects.create(content=txt, nickname='nobody', target=target, pid=pid)
  File "/home/kk/.virtualenvs/blog-env/local/lib/python2.7/site-packages/django/db/models/manager.py", line 85, in manager_method
    return getattr(self.get_queryset(), name)(*args, **kwargs)
  File "/home/kk/.virtualenvs/blog-env/local/lib/python2.7/site-packages/django/db/models/query.py", line 392, in create
    obj = self.model(**kwargs)
  File "/home/kk/.virtualenvs/blog-env/local/lib/python2.7/site-packages/django/db/models/base.py", line 554, in __init__
    _setattr(self, field.name, rel_obj)
  File "/home/kk/.virtualenvs/blog-env/local/lib/python2.7/site-packages/django/db/models/fields/related_descriptors.py", line 216, in __set__
    self.field.remote_field.model._meta.object_name,
ValueError: Cannot assign "u'0'": "Comment.pid" must be a "Comment" instance.
[23/Mar/2018 21:39:53] "POST /comment HTTP/1.1" 500 16401
Internal Server Error: /comment
Traceback (most recent call last):
  File "/home/kk/.virtualenvs/blog-env/local/lib/python2.7/site-packages/django/core/handlers/exception.py", line 41, in inner
    response = get_response(request)
  File "/home/kk/.virtualenvs/blog-env/local/lib/python2.7/site-packages/django/core/handlers/base.py", line 187, in _get_response
    response = self.process_exception_by_middleware(e, request)
  File "/home/kk/.virtualenvs/blog-env/local/lib/python2.7/site-packages/django/core/handlers/base.py", line 185, in _get_response
    response = wrapped_callback(request, *callback_args, **callback_kwargs)
  File "/home/kk/.virtualenvs/blog-env/local/lib/python2.7/site-packages/django/views/decorators/csrf.py", line 58, in wrapped_view
    return view_func(*args, **kwargs)
  File "/home/kk/prac/blog/selfblog/views.py", line 299, in comment
    com = Comment.objects.create(content=txt, nickname='nobody', target=target, pid=pid)
  File "/home/kk/.virtualenvs/blog-env/local/lib/python2.7/site-packages/django/db/models/manager.py", line 85, in manager_method
    return getattr(self.get_queryset(), name)(*args, **kwargs)
  File "/home/kk/.virtualenvs/blog-env/local/lib/python2.7/site-packages/django/db/models/query.py", line 392, in create
    obj = self.model(**kwargs)
  File "/home/kk/.virtualenvs/blog-env/local/lib/python2.7/site-packages/django/db/models/base.py", line 554, in __init__
    _setattr(self, field.name, rel_obj)
  File "/home/kk/.virtualenvs/blog-env/local/lib/python2.7/site-packages/django/db/models/fields/related_descriptors.py", line 216, in __set__
    self.field.remote_field.model._meta.object_name,
ValueError: Cannot assign "u'0'": "Comment.pid" must be a "Comment" instance.
[23/Mar/2018 21:39:54] "POST /comment HTTP/1.1" 500 16401
Internal Server Error: /comment
Traceback (most recent call last):
  File "/home/kk/.virtualenvs/blog-env/local/lib/python2.7/site-packages/django/core/handlers/exception.py", line 41, in inner
    response = get_response(request)
  File "/home/kk/.virtualenvs/blog-env/local/lib/python2.7/site-packages/django/core/handlers/base.py", line 187, in _get_response
    response = self.process_exception_by_middleware(e, request)
  File "/home/kk/.virtualenvs/blog-env/local/lib/python2.7/site-packages/django/core/handlers/base.py", line 185, in _get_response
    response = wrapped_callback(request, *callback_args, **callback_kwargs)
  File "/home/kk/.virtualenvs/blog-env/local/lib/python2.7/site-packages/django/views/decorators/csrf.py", line 58, in wrapped_view
    return view_func(*args, **kwargs)
  File "/home/kk/prac/blog/selfblog/views.py", line 299, in comment
    com = Comment.objects.create(content=txt, nickname='nobody', target=target, pid=pid)
  File "/home/kk/.virtualenvs/blog-env/local/lib/python2.7/site-packages/django/db/models/manager.py", line 85, in manager_method
    return getattr(self.get_queryset(), name)(*args, **kwargs)
  File "/home/kk/.virtualenvs/blog-env/local/lib/python2.7/site-packages/django/db/models/query.py", line 392, in create
    obj = self.model(**kwargs)
  File "/home/kk/.virtualenvs/blog-env/local/lib/python2.7/site-packages/django/db/models/base.py", line 554, in __init__
    _setattr(self, field.name, rel_obj)
  File "/home/kk/.virtualenvs/blog-env/local/lib/python2.7/site-packages/django/db/models/fields/related_descriptors.py", line 216, in __set__
    self.field.remote_field.model._meta.object_name,
ValueError: Cannot assign "u'0'": "Comment.pid" must be a "Comment" instance.
[23/Mar/2018 21:39:55] "POST /comment HTTP/1.1" 500 16401
Internal Server Error: /comment
Traceback (most recent call last):
  File "/home/kk/.virtualenvs/blog-env/local/lib/python2.7/site-packages/django/core/handlers/exception.py", line 41, in inner
    response = get_response(request)
  File "/home/kk/.virtualenvs/blog-env/local/lib/python2.7/site-packages/django/core/handlers/base.py", line 187, in _get_response
    response = self.process_exception_by_middleware(e, request)
  File "/home/kk/.virtualenvs/blog-env/local/lib/python2.7/site-packages/django/core/handlers/base.py", line 185, in _get_response
    response = wrapped_callback(request, *callback_args, **callback_kwargs)
  File "/home/kk/.virtualenvs/blog-env/local/lib/python2.7/site-packages/django/views/decorators/csrf.py", line 58, in wrapped_view
    return view_func(*args, **kwargs)
  File "/home/kk/prac/blog/selfblog/views.py", line 299, in comment
    com = Comment.objects.create(content=txt, nickname='nobody', target=target, pid=pid)
  File "/home/kk/.virtualenvs/blog-env/local/lib/python2.7/site-packages/django/db/models/manager.py", line 85, in manager_method
    return getattr(self.get_queryset(), name)(*args, **kwargs)
  File "/home/kk/.virtualenvs/blog-env/local/lib/python2.7/site-packages/django/db/models/query.py", line 392, in create
    obj = self.model(**kwargs)
  File "/home/kk/.virtualenvs/blog-env/local/lib/python2.7/site-packages/django/db/models/base.py", line 554, in __init__
    _setattr(self, field.name, rel_obj)
  File "/home/kk/.virtualenvs/blog-env/local/lib/python2.7/site-packages/django/db/models/fields/related_descriptors.py", line 216, in __set__
    self.field.remote_field.model._meta.object_name,
ValueError: Cannot assign "u'0'": "Comment.pid" must be a "Comment" instance.
[23/Mar/2018 21:39:56] "POST /comment HTTP/1.1" 500 16401
Internal Server Error: /comment
Traceback (most recent call last):
  File "/home/kk/.virtualenvs/blog-env/local/lib/python2.7/site-packages/django/core/handlers/exception.py", line 41, in inner
    response = get_response(request)
  File "/home/kk/.virtualenvs/blog-env/local/lib/python2.7/site-packages/django/core/handlers/base.py", line 187, in _get_response
    response = self.process_exception_by_middleware(e, request)
  File "/home/kk/.virtualenvs/blog-env/local/lib/python2.7/site-packages/django/core/handlers/base.py", line 185, in _get_response
    response = wrapped_callback(request, *callback_args, **callback_kwargs)
  File "/home/kk/.virtualenvs/blog-env/local/lib/python2.7/site-packages/django/views/decorators/csrf.py", line 58, in wrapped_view
    return view_func(*args, **kwargs)
  File "/home/kk/prac/blog/selfblog/views.py", line 299, in comment
    com = Comment.objects.create(content=txt, nickname='nobody', target=target, pid=pid)
  File "/home/kk/.virtualenvs/blog-env/local/lib/python2.7/site-packages/django/db/models/manager.py", line 85, in manager_method
    return getattr(self.get_queryset(), name)(*args, **kwargs)
  File "/home/kk/.virtualenvs/blog-env/local/lib/python2.7/site-packages/django/db/models/query.py", line 392, in create
    obj = self.model(**kwargs)
  File "/home/kk/.virtualenvs/blog-env/local/lib/python2.7/site-packages/django/db/models/base.py", line 554, in __init__
    _setattr(self, field.name, rel_obj)
  File "/home/kk/.virtualenvs/blog-env/local/lib/python2.7/site-packages/django/db/models/fields/related_descriptors.py", line 216, in __set__
    self.field.remote_field.model._meta.object_name,
ValueError: Cannot assign "u'0'": "Comment.pid" must be a "Comment" instance.
[23/Mar/2018 21:39:56] "POST /comment HTTP/1.1" 500 16401
Internal Server Error: /comment
Traceback (most recent call last):
  File "/home/kk/.virtualenvs/blog-env/local/lib/python2.7/site-packages/django/core/handlers/exception.py", line 41, in inner
    response = get_response(request)
  File "/home/kk/.virtualenvs/blog-env/local/lib/python2.7/site-packages/django/core/handlers/base.py", line 187, in _get_response
    response = self.process_exception_by_middleware(e, request)
  File "/home/kk/.virtualenvs/blog-env/local/lib/python2.7/site-packages/django/core/handlers/base.py", line 185, in _get_response
    response = wrapped_callback(request, *callback_args, **callback_kwargs)
  File "/home/kk/.virtualenvs/blog-env/local/lib/python2.7/site-packages/django/views/decorators/csrf.py", line 58, in wrapped_view
    return view_func(*args, **kwargs)
  File "/home/kk/prac/blog/selfblog/views.py", line 299, in comment
    com = Comment.objects.create(content=txt, nickname='nobody', target=target, pid=pid)
  File "/home/kk/.virtualenvs/blog-env/local/lib/python2.7/site-packages/django/db/models/manager.py", line 85, in manager_method
    return getattr(self.get_queryset(), name)(*args, **kwargs)
  File "/home/kk/.virtualenvs/blog-env/local/lib/python2.7/site-packages/django/db/models/query.py", line 392, in create
    obj = self.model(**kwargs)
  File "/home/kk/.virtualenvs/blog-env/local/lib/python2.7/site-packages/django/db/models/base.py", line 554, in __init__
    _setattr(self, field.name, rel_obj)
  File "/home/kk/.virtualenvs/blog-env/local/lib/python2.7/site-packages/django/db/models/fields/related_descriptors.py", line 216, in __set__
    self.field.remote_field.model._meta.object_name,
ValueError: Cannot assign "u'0'": "Comment.pid" must be a "Comment" instance.
[23/Mar/2018 21:39:56] "POST /comment HTTP/1.1" 500 16401
Internal Server Error: /comment
Traceback (most recent call last):
  File "/home/kk/.virtualenvs/blog-env/local/lib/python2.7/site-packages/django/core/handlers/exception.py", line 41, in inner
    response = get_response(request)
  File "/home/kk/.virtualenvs/blog-env/local/lib/python2.7/site-packages/django/core/handlers/base.py", line 187, in _get_response
    response = self.process_exception_by_middleware(e, request)
  File "/home/kk/.virtualenvs/blog-env/local/lib/python2.7/site-packages/django/core/handlers/base.py", line 185, in _get_response
    response = wrapped_callback(request, *callback_args, **callback_kwargs)
  File "/home/kk/.virtualenvs/blog-env/local/lib/python2.7/site-packages/django/views/decorators/csrf.py", line 58, in wrapped_view
    return view_func(*args, **kwargs)
  File "/home/kk/prac/blog/selfblog/views.py", line 299, in comment
    com = Comment.objects.create(content=txt, nickname='nobody', target=target, pid=pid)
  File "/home/kk/.virtualenvs/blog-env/local/lib/python2.7/site-packages/django/db/models/manager.py", line 85, in manager_method
    return getattr(self.get_queryset(), name)(*args, **kwargs)
  File "/home/kk/.virtualenvs/blog-env/local/lib/python2.7/site-packages/django/db/models/query.py", line 392, in create
    obj = self.model(**kwargs)
  File "/home/kk/.virtualenvs/blog-env/local/lib/python2.7/site-packages/django/db/models/base.py", line 554, in __init__
    _setattr(self, field.name, rel_obj)
  File "/home/kk/.virtualenvs/blog-env/local/lib/python2.7/site-packages/django/db/models/fields/related_descriptors.py", line 216, in __set__
    self.field.remote_field.model._meta.object_name,
ValueError: Cannot assign "u'0'": "Comment.pid" must be a "Comment" instance.
[23/Mar/2018 21:39:56] "POST /comment HTTP/1.1" 500 16401
Internal Server Error: /comment
Traceback (most recent call last):
  File "/home/kk/.virtualenvs/blog-env/local/lib/python2.7/site-packages/django/core/handlers/exception.py", line 41, in inner
    response = get_response(request)
  File "/home/kk/.virtualenvs/blog-env/local/lib/python2.7/site-packages/django/core/handlers/base.py", line 187, in _get_response
    response = self.process_exception_by_middleware(e, request)
  File "/home/kk/.virtualenvs/blog-env/local/lib/python2.7/site-packages/django/core/handlers/base.py", line 185, in _get_response
    response = wrapped_callback(request, *callback_args, **callback_kwargs)
  File "/home/kk/.virtualenvs/blog-env/local/lib/python2.7/site-packages/django/views/decorators/csrf.py", line 58, in wrapped_view
    return view_func(*args, **kwargs)
  File "/home/kk/prac/blog/selfblog/views.py", line 299, in comment
    com = Comment.objects.create(content=txt, nickname='nobody', target=target, pid=pid)
  File "/home/kk/.virtualenvs/blog-env/local/lib/python2.7/site-packages/django/db/models/manager.py", line 85, in manager_method
    return getattr(self.get_queryset(), name)(*args, **kwargs)
  File "/home/kk/.virtualenvs/blog-env/local/lib/python2.7/site-packages/django/db/models/query.py", line 392, in create
    obj = self.model(**kwargs)
  File "/home/kk/.virtualenvs/blog-env/local/lib/python2.7/site-packages/django/db/models/base.py", line 554, in __init__
    _setattr(self, field.name, rel_obj)
  File "/home/kk/.virtualenvs/blog-env/local/lib/python2.7/site-packages/django/db/models/fields/related_descriptors.py", line 216, in __set__
    self.field.remote_field.model._meta.object_name,
ValueError: Cannot assign "u'0'": "Comment.pid" must be a "Comment" instance.
[23/Mar/2018 21:39:56] "POST /comment HTTP/1.1" 500 16401
Internal Server Error: /comment
Traceback (most recent call last):
  File "/home/kk/.virtualenvs/blog-env/local/lib/python2.7/site-packages/django/core/handlers/exception.py", line 41, in inner
    response = get_response(request)
  File "/home/kk/.virtualenvs/blog-env/local/lib/python2.7/site-packages/django/core/handlers/base.py", line 187, in _get_response
    response = self.process_exception_by_middleware(e, request)
  File "/home/kk/.virtualenvs/blog-env/local/lib/python2.7/site-packages/django/core/handlers/base.py", line 185, in _get_response
    response = wrapped_callback(request, *callback_args, **callback_kwargs)
  File "/home/kk/.virtualenvs/blog-env/local/lib/python2.7/site-packages/django/views/decorators/csrf.py", line 58, in wrapped_view
    return view_func(*args, **kwargs)
  File "/home/kk/prac/blog/selfblog/views.py", line 299, in comment
    com = Comment.objects.create(content=txt, nickname='nobody', target=target, pid=pid)
  File "/home/kk/.virtualenvs/blog-env/local/lib/python2.7/site-packages/django/db/models/manager.py", line 85, in manager_method
    return getattr(self.get_queryset(), name)(*args, **kwargs)
  File "/home/kk/.virtualenvs/blog-env/local/lib/python2.7/site-packages/django/db/models/query.py", line 392, in create
    obj = self.model(**kwargs)
  File "/home/kk/.virtualenvs/blog-env/local/lib/python2.7/site-packages/django/db/models/base.py", line 554, in __init__
    _setattr(self, field.name, rel_obj)
  File "/home/kk/.virtualenvs/blog-env/local/lib/python2.7/site-packages/django/db/models/fields/related_descriptors.py", line 216, in __set__
    self.field.remote_field.model._meta.object_name,
ValueError: Cannot assign "u'0'": "Comment.pid" must be a "Comment" instance.
[23/Mar/2018 21:39:57] "POST /comment HTTP/1.1" 500 16401
Internal Server Error: /comment
Traceback (most recent call last):
  File "/home/kk/.virtualenvs/blog-env/local/lib/python2.7/site-packages/django/core/handlers/exception.py", line 41, in inner
    response = get_response(request)
  File "/home/kk/.virtualenvs/blog-env/local/lib/python2.7/site-packages/django/core/handlers/base.py", line 187, in _get_response
    response = self.process_exception_by_middleware(e, request)
  File "/home/kk/.virtualenvs/blog-env/local/lib/python2.7/site-packages/django/core/handlers/base.py", line 185, in _get_response
    response = wrapped_callback(request, *callback_args, **callback_kwargs)
  File "/home/kk/.virtualenvs/blog-env/local/lib/python2.7/site-packages/django/views/decorators/csrf.py", line 58, in wrapped_view
    return view_func(*args, **kwargs)
  File "/home/kk/prac/blog/selfblog/views.py", line 299, in comment
    com = Comment.objects.create(content=txt, nickname='nobody', target=target, pid=pid)
  File "/home/kk/.virtualenvs/blog-env/local/lib/python2.7/site-packages/django/db/models/manager.py", line 85, in manager_method
    return getattr(self.get_queryset(), name)(*args, **kwargs)
  File "/home/kk/.virtualenvs/blog-env/local/lib/python2.7/site-packages/django/db/models/query.py", line 392, in create
    obj = self.model(**kwargs)
  File "/home/kk/.virtualenvs/blog-env/local/lib/python2.7/site-packages/django/db/models/base.py", line 554, in __init__
    _setattr(self, field.name, rel_obj)
  File "/home/kk/.virtualenvs/blog-env/local/lib/python2.7/site-packages/django/db/models/fields/related_descriptors.py", line 216, in __set__
    self.field.remote_field.model._meta.object_name,
ValueError: Cannot assign "u'0'": "Comment.pid" must be a "Comment" instance.
[23/Mar/2018 21:39:57] "POST /comment HTTP/1.1" 500 16401
Internal Server Error: /comment
Traceback (most recent call last):
  File "/home/kk/.virtualenvs/blog-env/local/lib/python2.7/site-packages/django/core/handlers/exception.py", line 41, in inner
    response = get_response(request)
  File "/home/kk/.virtualenvs/blog-env/local/lib/python2.7/site-packages/django/core/handlers/base.py", line 187, in _get_response
    response = self.process_exception_by_middleware(e, request)
  File "/home/kk/.virtualenvs/blog-env/local/lib/python2.7/site-packages/django/core/handlers/base.py", line 185, in _get_response
    response = wrapped_callback(request, *callback_args, **callback_kwargs)
  File "/home/kk/.virtualenvs/blog-env/local/lib/python2.7/site-packages/django/views/decorators/csrf.py", line 58, in wrapped_view
    return view_func(*args, **kwargs)
  File "/home/kk/prac/blog/selfblog/views.py", line 299, in comment
    com = Comment.objects.create(content=txt, nickname='nobody', target=target, pid=pid)
  File "/home/kk/.virtualenvs/blog-env/local/lib/python2.7/site-packages/django/db/models/manager.py", line 85, in manager_method
    return getattr(self.get_queryset(), name)(*args, **kwargs)
  File "/home/kk/.virtualenvs/blog-env/local/lib/python2.7/site-packages/django/db/models/query.py", line 392, in create
    obj = self.model(**kwargs)
  File "/home/kk/.virtualenvs/blog-env/local/lib/python2.7/site-packages/django/db/models/base.py", line 554, in __init__
    _setattr(self, field.name, rel_obj)
  File "/home/kk/.virtualenvs/blog-env/local/lib/python2.7/site-packages/django/db/models/fields/related_descriptors.py", line 216, in __set__
    self.field.remote_field.model._meta.object_name,
ValueError: Cannot assign "u'0'": "Comment.pid" must be a "Comment" instance.
[23/Mar/2018 21:39:57] "POST /comment HTTP/1.1" 500 16401
Internal Server Error: /comment
Traceback (most recent call last):
  File "/home/kk/.virtualenvs/blog-env/local/lib/python2.7/site-packages/django/core/handlers/exception.py", line 41, in inner
    response = get_response(request)
  File "/home/kk/.virtualenvs/blog-env/local/lib/python2.7/site-packages/django/core/handlers/base.py", line 187, in _get_response
    response = self.process_exception_by_middleware(e, request)
  File "/home/kk/.virtualenvs/blog-env/local/lib/python2.7/site-packages/django/core/handlers/base.py", line 185, in _get_response
    response = wrapped_callback(request, *callback_args, **callback_kwargs)
  File "/home/kk/.virtualenvs/blog-env/local/lib/python2.7/site-packages/django/views/decorators/csrf.py", line 58, in wrapped_view
    return view_func(*args, **kwargs)
  File "/home/kk/prac/blog/selfblog/views.py", line 299, in comment
    com = Comment.objects.create(content=txt, nickname='nobody', target=target, pid=pid)
  File "/home/kk/.virtualenvs/blog-env/local/lib/python2.7/site-packages/django/db/models/manager.py", line 85, in manager_method
    return getattr(self.get_queryset(), name)(*args, **kwargs)
  File "/home/kk/.virtualenvs/blog-env/local/lib/python2.7/site-packages/django/db/models/query.py", line 392, in create
    obj = self.model(**kwargs)
  File "/home/kk/.virtualenvs/blog-env/local/lib/python2.7/site-packages/django/db/models/base.py", line 554, in __init__
    _setattr(self, field.name, rel_obj)
  File "/home/kk/.virtualenvs/blog-env/local/lib/python2.7/site-packages/django/db/models/fields/related_descriptors.py", line 216, in __set__
    self.field.remote_field.model._meta.object_name,
ValueError: Cannot assign "u'0'": "Comment.pid" must be a "Comment" instance.
[23/Mar/2018 21:40:00] "POST /comment HTTP/1.1" 500 16401
Internal Server Error: /comment
Traceback (most recent call last):
  File "/home/kk/.virtualenvs/blog-env/local/lib/python2.7/site-packages/django/core/handlers/exception.py", line 41, in inner
    response = get_response(request)
  File "/home/kk/.virtualenvs/blog-env/local/lib/python2.7/site-packages/django/core/handlers/base.py", line 187, in _get_response
    response = self.process_exception_by_middleware(e, request)
  File "/home/kk/.virtualenvs/blog-env/local/lib/python2.7/site-packages/django/core/handlers/base.py", line 185, in _get_response
    response = wrapped_callback(request, *callback_args, **callback_kwargs)
  File "/home/kk/.virtualenvs/blog-env/local/lib/python2.7/site-packages/django/views/decorators/csrf.py", line 58, in wrapped_view
    return view_func(*args, **kwargs)
  File "/home/kk/prac/blog/selfblog/views.py", line 299, in comment
    com = Comment.objects.create(content=txt, nickname='nobody', target=target, pid=pid)
  File "/home/kk/.virtualenvs/blog-env/local/lib/python2.7/site-packages/django/db/models/manager.py", line 85, in manager_method
    return getattr(self.get_queryset(), name)(*args, **kwargs)
  File "/home/kk/.virtualenvs/blog-env/local/lib/python2.7/site-packages/django/db/models/query.py", line 392, in create
    obj = self.model(**kwargs)
  File "/home/kk/.virtualenvs/blog-env/local/lib/python2.7/site-packages/django/db/models/base.py", line 554, in __init__
    _setattr(self, field.name, rel_obj)
  File "/home/kk/.virtualenvs/blog-env/local/lib/python2.7/site-packages/django/db/models/fields/related_descriptors.py", line 216, in __set__
    self.field.remote_field.model._meta.object_name,
ValueError: Cannot assign "u'0'": "Comment.pid" must be a "Comment" instance.
[23/Mar/2018 21:40:00] "POST /comment HTTP/1.1" 500 16401
Internal Server Error: /comment
Traceback (most recent call last):
  File "/home/kk/.virtualenvs/blog-env/local/lib/python2.7/site-packages/django/core/handlers/exception.py", line 41, in inner
    response = get_response(request)
  File "/home/kk/.virtualenvs/blog-env/local/lib/python2.7/site-packages/django/core/handlers/base.py", line 187, in _get_response
    response = self.process_exception_by_middleware(e, request)
  File "/home/kk/.virtualenvs/blog-env/local/lib/python2.7/site-packages/django/core/handlers/base.py", line 185, in _get_response
    response = wrapped_callback(request, *callback_args, **callback_kwargs)
  File "/home/kk/.virtualenvs/blog-env/local/lib/python2.7/site-packages/django/views/decorators/csrf.py", line 58, in wrapped_view
    return view_func(*args, **kwargs)
  File "/home/kk/prac/blog/selfblog/views.py", line 299, in comment
    com = Comment.objects.create(content=txt, nickname='nobody', target=target, pid=pid)
  File "/home/kk/.virtualenvs/blog-env/local/lib/python2.7/site-packages/django/db/models/manager.py", line 85, in manager_method
    return getattr(self.get_queryset(), name)(*args, **kwargs)
  File "/home/kk/.virtualenvs/blog-env/local/lib/python2.7/site-packages/django/db/models/query.py", line 392, in create
    obj = self.model(**kwargs)
  File "/home/kk/.virtualenvs/blog-env/local/lib/python2.7/site-packages/django/db/models/base.py", line 554, in __init__
    _setattr(self, field.name, rel_obj)
  File "/home/kk/.virtualenvs/blog-env/local/lib/python2.7/site-packages/django/db/models/fields/related_descriptors.py", line 216, in __set__
    self.field.remote_field.model._meta.object_name,
ValueError: Cannot assign "u'0'": "Comment.pid" must be a "Comment" instance.
[23/Mar/2018 21:40:00] "POST /comment HTTP/1.1" 500 16401
Internal Server Error: /comment
Traceback (most recent call last):
  File "/home/kk/.virtualenvs/blog-env/local/lib/python2.7/site-packages/django/core/handlers/exception.py", line 41, in inner
    response = get_response(request)
  File "/home/kk/.virtualenvs/blog-env/local/lib/python2.7/site-packages/django/core/handlers/base.py", line 187, in _get_response
    response = self.process_exception_by_middleware(e, request)
  File "/home/kk/.virtualenvs/blog-env/local/lib/python2.7/site-packages/django/core/handlers/base.py", line 185, in _get_response
    response = wrapped_callback(request, *callback_args, **callback_kwargs)
  File "/home/kk/.virtualenvs/blog-env/local/lib/python2.7/site-packages/django/views/decorators/csrf.py", line 58, in wrapped_view
    return view_func(*args, **kwargs)
  File "/home/kk/prac/blog/selfblog/views.py", line 299, in comment
    com = Comment.objects.create(content=txt, nickname='nobody', target=target, pid=pid)
  File "/home/kk/.virtualenvs/blog-env/local/lib/python2.7/site-packages/django/db/models/manager.py", line 85, in manager_method
    return getattr(self.get_queryset(), name)(*args, **kwargs)
  File "/home/kk/.virtualenvs/blog-env/local/lib/python2.7/site-packages/django/db/models/query.py", line 392, in create
    obj = self.model(**kwargs)
  File "/home/kk/.virtualenvs/blog-env/local/lib/python2.7/site-packages/django/db/models/base.py", line 554, in __init__
    _setattr(self, field.name, rel_obj)
  File "/home/kk/.virtualenvs/blog-env/local/lib/python2.7/site-packages/django/db/models/fields/related_descriptors.py", line 216, in __set__
    self.field.remote_field.model._meta.object_name,
ValueError: Cannot assign "u'0'": "Comment.pid" must be a "Comment" instance.
[23/Mar/2018 21:40:00] "POST /comment HTTP/1.1" 500 16401
Internal Server Error: /comment
Traceback (most recent call last):
  File "/home/kk/.virtualenvs/blog-env/local/lib/python2.7/site-packages/django/core/handlers/exception.py", line 41, in inner
    response = get_response(request)
  File "/home/kk/.virtualenvs/blog-env/local/lib/python2.7/site-packages/django/core/handlers/base.py", line 187, in _get_response
    response = self.process_exception_by_middleware(e, request)
  File "/home/kk/.virtualenvs/blog-env/local/lib/python2.7/site-packages/django/core/handlers/base.py", line 185, in _get_response
    response = wrapped_callback(request, *callback_args, **callback_kwargs)
  File "/home/kk/.virtualenvs/blog-env/local/lib/python2.7/site-packages/django/views/decorators/csrf.py", line 58, in wrapped_view
    return view_func(*args, **kwargs)
  File "/home/kk/prac/blog/selfblog/views.py", line 299, in comment
    com = Comment.objects.create(content=txt, nickname='nobody', target=target, pid=pid)
  File "/home/kk/.virtualenvs/blog-env/local/lib/python2.7/site-packages/django/db/models/manager.py", line 85, in manager_method
    return getattr(self.get_queryset(), name)(*args, **kwargs)
  File "/home/kk/.virtualenvs/blog-env/local/lib/python2.7/site-packages/django/db/models/query.py", line 392, in create
    obj = self.model(**kwargs)
  File "/home/kk/.virtualenvs/blog-env/local/lib/python2.7/site-packages/django/db/models/base.py", line 554, in __init__
    _setattr(self, field.name, rel_obj)
  File "/home/kk/.virtualenvs/blog-env/local/lib/python2.7/site-packages/django/db/models/fields/related_descriptors.py", line 216, in __set__
    self.field.remote_field.model._meta.object_name,
ValueError: Cannot assign "u'0'": "Comment.pid" must be a "Comment" instance.
[23/Mar/2018 21:40:01] "POST /comment HTTP/1.1" 500 16401
Performing system checks...

System check identified no issues (0 silenced).
March 23, 2018 - 21:23:49
Django version 1.11.3, using settings 'blog.settings.product'
Starting development server at http://0:800/
Quit the server with CONTROL-C.
Unhandled exception in thread started by <function wrapper at 0x7f26e8e44aa0>
Traceback (most recent call last):
  File "/home/kk/.virtualenvs/blog-env/local/lib/python2.7/site-packages/django/utils/autoreload.py", line 227, in wrapper
    fn(*args, **kwargs)
  File "/home/kk/.virtualenvs/blog-env/local/lib/python2.7/site-packages/django/core/management/commands/runserver.py", line 117, in inner_run
    autoreload.raise_last_exception()
  File "/home/kk/.virtualenvs/blog-env/local/lib/python2.7/site-packages/django/utils/autoreload.py", line 250, in raise_last_exception
    six.reraise(*_exception)
  File "/home/kk/.virtualenvs/blog-env/local/lib/python2.7/site-packages/django/utils/autoreload.py", line 227, in wrapper
    fn(*args, **kwargs)
  File "/home/kk/.virtualenvs/blog-env/local/lib/python2.7/site-packages/django/__init__.py", line 27, in setup
    apps.populate(settings.INSTALLED_APPS)
  File "/home/kk/.virtualenvs/blog-env/local/lib/python2.7/site-packages/django/apps/registry.py", line 108, in populate
    app_config.import_models()
  File "/home/kk/.virtualenvs/blog-env/local/lib/python2.7/site-packages/django/apps/config.py", line 202, in import_models
    self.models_module = import_module(models_module_name)
  File "/usr/lib/python2.7/importlib/__init__.py", line 37, in import_module
    __import__(name)
  File "/home/kk/prac/blog/comment/models.py", line 9, in <module>
    class Comment(models.Model):
  File "/home/kk/prac/blog/comment/models.py", line 14, in Comment
    target = models.CharField(defatul='/', max_length=100, verbose_name="target")
  File "/home/kk/.virtualenvs/blog-env/local/lib/python2.7/site-packages/django/db/models/fields/__init__.py", line 1061, in __init__
    super(CharField, self).__init__(*args, **kwargs)
TypeError: __init__() got an unexpected keyword argument 'defatul'
