Error: That port is already in use.
[11/Mar/2018 20:18:24] "GET / HTTP/1.1" 200 13610
[11/Mar/2018 20:18:24] "GET /static/css/base.css HTTP/1.1" 304 0
[11/Mar/2018 20:18:24] "GET /static/img/header.jpg HTTP/1.1" 304 0
Performing system checks...

System check identified no issues (0 silenced).
March 11, 2018 - 20:18:22
Django version 1.11.3, using settings 'blog.settings.develop'
Starting development server at http://0.0.0.0:800/
Quit the server with CONTROL-C.
{u'notice': <SideBar: SideBar object>, u'recently_post': <SideBar: SideBar object>}
--------------------------------------------------------------------------------
path:  /
[{u'time': u'0.001', u'sql': u'SELECT COUNT(*) AS "__count" FROM "selfblog_post" WHERE "selfblog_post"."status" = 1'}, {u'time': u'0.000', u'sql': u'SELECT "selfblog_category"."id", "selfblog_category"."name", "selfblog_category"."status", "selfblog_category"."is_nav", "selfblog_category"."owner_id", "selfblog_category"."created_time" FROM "selfblog_category" WHERE "selfblog_category"."status" = 1'}, {u'time': u'0.000', u'sql': u'SELECT "config_sidebar"."id", "config_sidebar"."title", "config_sidebar"."display_type", "config_sidebar"."content", "config_sidebar"."owner_id", "config_sidebar"."status", "config_sidebar"."created_time" FROM "config_sidebar" WHERE "config_sidebar"."status" = 1 ORDER BY "config_sidebar"."display_type" ASC'}, {u'time': u'0.001', u'sql': u'SELECT "selfblog_post"."id", "selfblog_post"."title", "selfblog_post"."desc", "selfblog_post"."category_id", "selfblog_post"."content", "selfblog_post"."status", "selfblog_post"."owner_id", "selfblog_post"."weight", "selfblog_post"."created_time" FROM "selfblog_post" WHERE "selfblog_post"."status" = 1 ORDER BY "selfblog_post"."weight" DESC, "selfblog_post"."created_time" DESC LIMIT 6'}, {u'time': u'0.000', u'sql': u'SELECT "selfblog_tag"."id", "selfblog_tag"."name", "selfblog_tag"."status", "selfblog_tag"."owner_id", "selfblog_tag"."created_time" FROM "selfblog_tag" WHERE "selfblog_tag"."status" = 1'}, {u'time': u'0.000', u'sql': u'SELECT "selfblog_post"."id", "selfblog_post"."title", "selfblog_post"."desc", "selfblog_post"."category_id", "selfblog_post"."content", "selfblog_post"."status", "selfblog_post"."owner_id", "selfblog_post"."weight", "selfblog_post"."created_time" FROM "selfblog_post" WHERE "selfblog_post"."status" = 1 ORDER BY "selfblog_post"."created_time" DESC LIMIT 10'}, {u'time': u'0.000', u'sql': u'SELECT "config_link"."id", "config_link"."title", "config_link"."href", "config_link"."status", "config_link"."weight", "config_link"."owner_id", "config_link"."created_time" FROM "config_link" WHERE "config_link"."status" = 1 ORDER BY "config_link"."weight" ASC'}]
--------------------------------------------------------------------------------
Unhandled exception in thread started by <function wrapper at 0x7f27929331b8>
Performing system checks...

Traceback (most recent call last):
  File "/usr/local/lib/python2.7/dist-packages/django/utils/autoreload.py", line 227, in wrapper
    fn(*args, **kwargs)
  File "/usr/local/lib/python2.7/dist-packages/django/core/management/commands/runserver.py", line 125, in inner_run
    self.check(display_num_errors=True)
  File "/usr/local/lib/python2.7/dist-packages/django/core/management/base.py", line 359, in check
    include_deployment_checks=include_deployment_checks,
  File "/usr/local/lib/python2.7/dist-packages/django/core/management/base.py", line 346, in _run_checks
    return checks.run_checks(**kwargs)
  File "/usr/local/lib/python2.7/dist-packages/django/core/checks/registry.py", line 81, in run_checks
    new_errors = check(app_configs=app_configs)
  File "/usr/local/lib/python2.7/dist-packages/django/core/checks/urls.py", line 16, in check_url_config
    return check_resolver(resolver)
  File "/usr/local/lib/python2.7/dist-packages/django/core/checks/urls.py", line 26, in check_resolver
    return check_method()
  File "/usr/local/lib/python2.7/dist-packages/django/urls/resolvers.py", line 254, in check
    for pattern in self.url_patterns:
  File "/usr/local/lib/python2.7/dist-packages/django/utils/functional.py", line 35, in __get__
    res = instance.__dict__[self.name] = self.func(instance)
  File "/usr/local/lib/python2.7/dist-packages/django/urls/resolvers.py", line 405, in url_patterns
    patterns = getattr(self.urlconf_module, "urlpatterns", self.urlconf_module)
  File "/usr/local/lib/python2.7/dist-packages/django/utils/functional.py", line 35, in __get__
    res = instance.__dict__[self.name] = self.func(instance)
  File "/usr/local/lib/python2.7/dist-packages/django/urls/resolvers.py", line 398, in urlconf_module
    return import_module(self.urlconf_name)
  File "/usr/lib/python2.7/importlib/__init__.py", line 37, in import_module
    __import__(name)
  File "/root/prac/prac/blog/blog/urls.py", line 21, in <module>
    from selfblog.views import post_list, post_detail, TestView
  File "/root/prac/prac/blog/selfblog/views.py", line 9, in <module>
    from django.views.generic import ContextMixin, ListView, DetailView
ImportError: cannot import name ContextMixin
